Workbook

Sheet 套利产品
A1: 序号 | B1: 产品ID | C1: 产品名称 | D1: 类型 | E1: 统一策略类型 | F1: 是否套利策略 | G1: 策略判定来源 | H1: 火富牛策略路径 | I1: 当前净值 | J1: 净值日期 | K1: 净值来源 | L1: 成立日期 | M1: 成立以来收益 | N1: 今年以来收益 | O1: 成立以来年化 | P1: 成立以来最大回撤 | Q1: 成立以来夏普 | R1: 备案编号 | S1: 私募管理人 | T1: 历史净值行数 | U1: 历史起始 | V1: 历史截止 | W1: 末条复权净值 | X1: 跟踪来源 | Y1: 上海分公司策略分类 | Z1: 傲创二级策略 | AA1: 上海来源日期 | AB1: 傲创来源日期 | AC1: 指标来源 | AD1: 数据状态 | AE1: 来源URL | AF1: 是否上架
A2: 1 | B2: 8e641c904118560b | C2: 爱凡哲九号 | D2: 私募 | E2: 套利策略—期货套利 | F2: 是 | G2: 火富牛策略分类 | H2: 套利策略 /期货套利 | I2: 1.057 | J2: 46262 | K2: 火富牛产品详情页 | L2: 43710 | M2: 0.9919 | N2: 0.0907 | O2: 0.1419 | P2: 0.0256 | Q2: 3.6496 | R2: SJA112 | S2: 爱凡哲投资 | T2: 364 | U2: 43710 | V2: 46262 | W2: 1.9919444 | X2: 傲创提供名单 | Z2: 期货套利策略 | AB2: 46269 | AC2: 火富牛完整区间指标；历史净值复算 | AD2: 完整 | AE2: https://mp.fof99.com/fund/view/8e641c904118560b | AF2: 未确认
A3: 2 | B3: b03271229e00ba58 | C3: 滨风风云瑞丰1号 | D3: 私募 | E3: 管理期货—量化CTA | F3: 是 | G3: 火富牛策略分类；策略精选跟踪周报 | H3: 期货策略 /量化期货 /混合均衡 | I3: 2.2816 | J3: 46262 | K3: 火富牛产品详情页 | L3: 44897 | M3: 1.2816 | N3: 0.11417131 | O3: 0.3426989 | P3: 0.13061536 | Q3: 1.9499124 | R3: SXL267 | S3: 鹰潭滨风投资 | T3: 682 | U3: 44897 | V3: 46262 | W3: 2.2816 | X3: 策略精选跟踪周报 | Y3: 套利策略｜商品+股指套利 | AA3: 46262 | AC3: 火富牛成立以来指标；历史净值复核/复算 | AD3: 完整 | AE3: https://mp.fof99.com/fund/view/b03271229e00ba58 | AF3: 未确认
A4: 3 | B4: 9b20523c2bad1cdc | C4: 博牛转债策略2号 | D4: 私募 | E4: 套利策略—可转债套利 | F4: 是 | G4: 火富牛策略分类 | H4: 套利策略 /可转债套利 | I4: 1.2143 | J4: 46262 | K4: 火富牛产品详情页 | L4: 44788 | M4: 0.2153 | N4: -0.0099 | O4: 0.0535 | P4: 0.045 | Q4: 1.0017 | R4: SVY871 | S4: 广州博牛 | T4: 205 | U4: 44792 | V4: 46262 | W4: 1.2143 | X4: 傲创提供名单 | Z4: 期权套利策略 | AB4: 46269 | AC4: 火富牛成立以来指标 | AD4: 完整 | AE4: https://mp.fof99.com/fund/view/9b20523c2bad1cdc | AF4: 未确认
A5: 4 | B5: 783b8a029943d82b | C5: 博润小牛3号 | D5: 私募 | E5: 套利策略—基金套利 | F5: 是 | G5: 火富牛策略分类 | H5: 套利策略 /基金套利 /ETF套利 | I5: 1.0813 | J5: 46262 | K5: 火富牛产品详情页 | L5: 44624 | M5: 0.8262 | N5: 0.1377 | O5: 0.1841 | P5: 0.0257 | Q5: 2.3147 | R5: STV728 | S5: 北京博润银泰投资 | T5: 256 | U5: 44624 | V5: 46262 | W5: 1.8261898 | X5: 傲创提供名单 | Z5: 基金套利策略 | AB5: 46269 | AC5: 火富牛完整区间指标；历史净值复算 | AD5: 完整 | AE5: https://mp.fof99.com/fund/view/783b8a029943d82b | AF5: 未确认
A6: 5 | B6: 66f7dd55b7f90b97 | C6: 博润易量稳健1号 | D6: 私募 | E6: 套利策略—期货套利 | F6: 是 | G6: 火富牛策略分类 | H6: 套利策略 /期货套利 | I6: 1.0631 | J6: 46262 | K6: 火富牛产品详情页 | L6: 44895 | M6: 0.1692 | N6: 0.058 | O6: 0.0452 | P6: 0.0366 | Q6: 0.5618 | R6: SXL913 | S6: 北京博润银泰投资 | T6: 212 | U6: 44895 | V6: 46262 | W6: 1.169152 | X6: 上海分公司白名单 | Y6: 期货套利（混合套利）；期货套利（跨期套利）；量化期货（中高频&另类） | AA6: 46262 | AC6: 火富牛完整区间指标；历史净值复算 | AD6: 完整 | AE6: https://mp.fof99.com/fund/view/66f7dd55b7f90b97 | AF6: 未确认
A7: 6 | B7: 068bcb639f441262 | C7: 博弈树金选套利2号 | D7: 私募 | E7: 套利策略—期货套利 | F7: 是 | G7: 火富牛策略分类 | H7: 套利策略 /期货套利 | I7: 1.568 | J7: 46262 | K7: 火富牛产品详情页 | L7: 44867 | M7: 0.568 | N7: 0.166 | O7: 0.1486 | P7: 0.041 | Q7: 2.0619 | R7: SXR086 | S7: 广东丰煜 | T7: 349 | U7: 44867 | V7: 46262 | W7: 1.568 | X7: 傲创提供名单 | Z7: 期货套利策略 | AB7: 46269 | AC7: 火富牛完整区间指标；历史净值复算 | AD7: 完整 | AE7: https://mp.fof99.com/fund/view/068bcb639f441262 | AF7: 未确认
A8: 7 | B8: 11dff1146ece63b4 | C8: 常行7号 | D8: 私募 | E8: 套利策略—期货套利 | F8: 是 | G8: 火富牛策略分类；策略精选跟踪周报 | H8: 套利策略 /期货套利 /跨期套利；套利策略 /期货套利 /股指套利 | I8: 1.2709 | J8: 46262 | K8: 火富牛产品详情页 | L8: 44288 | M8: 0.396483 | N8: 0.046956091 | O8: 0.073311193 | P8: 0.011492093 | Q8: 3.1944242 | R8: SQH214 | S8: 江苏常行投资 | T8: 277 | U8: 44288 | V8: 46262 | W8: 1.396483 | X8: 策略精选跟踪周报 | Y8: 高频策略｜股指高频-跨期 | AA8: 46262 | AC8: 火富牛成立以来指标；历史净值复核/复算 | AD8: 完整 | AE8: https://mp.fof99.com/fund/view/11dff1146ece63b4 | AF8: 未确认
A9: 8 | B9: dfc323b7729ef01d | C9: 辰元稳健2号 | D9: 私募 | E9: 套利策略—混合套利 | F9: 是 | G9: 火富牛策略分类 | H9: 套利策略 /混合套利 | I9: 1.2726 | J9: 46262 | K9: 火富牛产品详情页 | L9: 44967 | M9: 0.2726 | N9: 0.0218 | O9: 0.0768 | P9: 0.0062 | Q9: 3.8037 | R9: SZJ724 | S9: 广东辰元 | T9: 183 | U9: 44967 | V9: 46262 | W9: 1.2726 | X9: 上海分公司白名单；傲创提供名单 | Y9: 主观期货（农产） | AA9: 46262 | AB9: 46274 | AC9: 火富牛完整区间指标；历史净值复算 | AD9: 完整 | AE9: https://mp.fof99.com/fund/view/dfc323b7729ef01d | AF9: 未确认
A10: 9 | B10: 3712ae883b81c7b6 | C10: 辰元优选稳健 | D10: 私募 | E10: 套利策略—混合套利 | F10: 是 | G10: 火富牛策略分类；策略精选跟踪周报 | H10: 套利策略 /混合套利 | I10: 1.2807 | J10: 46262 | K10: 火富牛产品详情页 | L10: 44966 | M10: 0.2807 | N10: 0.024068447 | O10: 0.07905517 | P10: 0.0042157858 | Q10: 3.951309 | R10: SZH690 | S10: 广东辰元 | T10: 185 | U10: 44966 | V10: 46262 | W10: 1.2807 | X10: 策略精选跟踪周报；傲创提供名单 | Y10: 套利策略｜ETF套利 | AA10: 46262 | AB10: 46274 | AC10: 火富牛成立以来指标；历史净值复核/复算 | AD10: 完整 | AE10: https://mp.fof99.com/fund/view/3712ae883b81c7b6 | AF10: 未确认
A11: 10 | B11: f56d280c5131a6c9 | C11: 晨翰11号 | D11: 私募 | E11: 套利策略—期货套利 | F11: 是 | G11: 火富牛策略分类 | H11: 套利策略 /期货套利 /跨品种套利 | I11: 1.1796 | J11: 46268 | K11: 火富牛产品详情页 | L11: 44722 | M11: 0.2902 | N11: 0.0355 | O11: 0.0685 | P11: 0.0356 | Q11: 1.2612 | R11: SVT598 | S11: 晋江晨翰 | T11: 1030 | U11: 44722 | V11: 46268 | W11: 1.2902465 | X11: 上海分公司白名单 | Y11: 主观期货（交易型） | AA11: 46262 | AC11: 火富牛完整区间指标；历史净值复算 | AD11: 完整 | AE11: https://mp.fof99.com/fund/view/f56d280c5131a6c9 | AF11: 未确认
A12: 11 | B12: 99bf55b582e27685 | C12: 晨翰6号 | D12: 私募 | E12: 套利策略—期货套利 | F12: 是 | G12: 火富牛策略分类 | H12: 套利策略 /期货套利 | I12: 1.1633 | J12: 46265 | K12: 火富牛产品详情页 | L12: 44575 | M12: 0.5046 | N12: 0.0734 | O12: 0.109 | P12: 0.0503 | Q12: 1.6952 | R12: STS460 | S12: 晋江晨翰 | T12: 263 | U12: 44575 | V12: 46265 | W12: 1.5045599 | X12: 上海分公司白名单 | Y12: 主观期货（交易型） | AA12: 46262 | AC12: 火富牛完整区间指标；历史净值复算 | AD12: 完整 | AE12: https://mp.fof99.com/fund/view/99bf55b582e27685 | AF12: 未确认
A13: 12 | B13: fbf1de225e3e65af | C13: 刀锋期权套利 | D13: 私募 | E13: 期权策略 | F13: 是 | G13: 火富牛策略分类 | H13: 期权策略 /场内期权 /定价卖波 | I13: 1.059 | J13: 46262 | K13: 火富牛产品详情页 | L13: 43627 | M13: 0.3238 | N13: 0.059 | O13: 0.1126 | P13: 0.1121 | Q13: 0.8646 | R13: SGR366 | S13: 深圳刀锋 | T13: 150 | U13: 45212 | V13: 46262 | W13: 1.2075471 | X13: 上海分公司白名单 | Y13: 商品卖波 | AA13: 46262 | AC13: 火富牛成立以来指标 | AD13: 完整 | AE13: https://mp.fof99.com/fund/view/fbf1de225e3e65af | AF13: 未确认
A14: 13 | B14: d7eeaf632af20fa7 | C14: 东方富银命运1号 | D14: 私募 | E14: 套利策略—可转债套利 | F14: 是 | G14: 火富牛策略分类 | H14: 套利策略 /可转债套利 | I14: 1.2518 | J14: 46262 | K14: 火富牛产品详情页 | L14: 43334 | M14: 0.7366 | N14: 0.0248 | O14: 0.0918 | P14: 0.0922 | Q14: 1.2442 | R14: SEG244 | S14: 深圳东方富银投资 | T14: 443 | U14: 43334 | V14: 46262 | W14: 1.736588 | X14: 傲创提供名单 | Z14: 可转债套利策略 | AB14: 46269 | AC14: 火富牛完整区间指标；历史净值复算 | AD14: 完整 | AE14: https://mp.fof99.com/fund/view/d7eeaf632af20fa7 | AF14: 未确认
A15: 14 | B15: baa4ff727568ddb3 | C15: 东源投资丰源5号 | D15: 私募 | E15: 套利策略—期权套利 | F15: 是 | G15: 火富牛策略分类 | H15: 套利策略 /期权套利 | I15: 1.0824 | J15: 46267 | K15: 产品详情页 | L15: 46017 | M15: 0.0839 | O15: 0.1326 | P15: 0.0043 | Q15: 4.2438 | R15: SBMG09 | S15: 天津东源投资 | T15: 151 | U15: 46036 | V15: 46267 | W15: 1.0824 | X15: 火富牛组合 | AC15: 火富牛产品详情页 | AD15: 完整 | AE15: https://mp.fof99.com/fund/view/baa4ff727568ddb3 | AF15: 未确认
A16: 15 | B16: dc199b33f4fce442 | C16: 东源投资乐源1号 | D16: 私募 | E16: 套利策略—期权套利 | F16: 是 | G16: 火富牛策略分类 | H16: 套利策略 /期权套利 | I16: 1.0855 | J16: 46267 | K16: 产品详情页 | L16: 46066 | M16: 0.0855 | N16: 0.0855 | O16: 0.1553 | P16: 0.0072 | Q16: 4.4259 | R16: SBRX68 | S16: 天津东源投资 | T16: 133 | U16: 46066 | V16: 46267 | W16: 1.0855 | X16: 火富牛组合；策略精选跟踪周报 | Y16: 期权策略｜金融期权套利为主 | AA16: 46262 | AC16: 火富牛产品详情页 | AD16: 完整 | AE16: https://mp.fof99.com/fund/view/dc199b33f4fce442 | AF16: 未确认
A17: 16 | B17: 572bc921ce9d2893 | C17: 放牛人5号 | D17: 私募 | E17: 套利策略—期货套利 | F17: 是 | G17: 火富牛策略分类 | H17: 套利策略 /期货套利 | I17: 1.0971 | J17: 46262 | K17: 火富牛产品详情页 | L17: 44729 | M17: 0.3343 | N17: 0.0682 | O17: 0.0796 | P17: 0.0033 | Q17: 3.4068 | R17: SVH487 | S17: 上海放牛人 | T17: 231 | U17: 44729 | V17: 46262 | W17: 1.3343076 | X17: 傲创提供名单 | Z17: 期货套利策略 | AB17: 46269 | AC17: 火富牛完整区间指标；历史净值复算 | AD17: 完整 | AE17: https://mp.fof99.com/fund/view/572bc921ce9d2893 | AF17: 未确认
A18: 17 | B18: bf37a6579525f8b3 | C18: 广联宏丰利1号 | D18: 私募 | E18: 套利策略—期货套利 | F18: 是 | G18: 火富牛策略分类 | H18: 套利策略 /期货套利 /商品套利 | I18: 2.004 | J18: 46268 | K18: 火富牛产品详情页 | L18: 45322 | M18: 1.004 | N18: 0.3317 | O18: 0.3874 | P18: 0.145 | Q18: 2.611 | R18: SAGN89 | S18: 海南广联宏 | T18: 627 | U18: 45322 | V18: 46268 | W18: 2.004 | X18: 傲创提供名单 | Z18: 期货套利策略 | AB18: 46269 | AC18: 火富牛完整区间指标；历史净值复算 | AD18: 完整 | AE18: https://mp.fof99.com/fund/view/bf37a6579525f8b3 | AF18: 未确认
A19: 18 | B19: c5b9a0c28942bf05 | C19: 广联宏稳健2号 | D19: 私募 | E19: 套利策略—期货套利 | F19: 是 | G19: 火富牛策略分类 | H19: 套利策略 /期货套利 /商品套利 | I19: 1.1011 | J19: 46268 | K19: 火富牛产品详情页 | L19: 45705 | M19: 0.3087 | N19: 0.1732 | O19: 0.2001 | P19: 0.0351 | Q19: 2.833 | R19: SATV20 | S19: 海南广联宏 | T19: 380 | U19: 45705 | V19: 46268 | W19: 1.3086574 | X19: 傲创提供名单 | Z19: 期货套利策略 | AB19: 46269 | AC19: 火富牛完整区间指标；历史净值复算 | AD19: 完整 | AE19: https://mp.fof99.com/fund/view/c5b9a0c28942bf05 | AF19: 未确认
A20: 19 | B20: e556f77ef201098a | C20: 杭州探融-锦鲤智能量化3号 | D20: 私募 | E20: 套利策略—可转债套利 | F20: 是 | G20: 火富牛策略分类 | H20: 套利策略 /可转债套利 | I20: 1.2817 | J20: 46262 | K20: 火富牛产品详情页 | L20: 44305 | M20: 0.2817 | N20: 0.0102 | O20: 0.0525 | P20: 0.0184 | Q20: 1.3007 | R20: SQC001 | S20: 杭州探融投资 | T20: 499 | U20: 44305 | V20: 46262 | W20: 1.2817 | X20: 傲创提供名单 | Z20: 期权套利策略 | AB20: 46269 | AC20: 火富牛完整区间指标；历史净值复算 | AD20: 完整 | AE20: https://mp.fof99.com/fund/view/e556f77ef201098a | AF20: 未确认
A21: 20 | B21: 5a95543cf10b3b66 | C21: 汇艾稳健3号 | D21: 私募 | E21: 套利策略—期货套利 | F21: 是 | G21: 火富牛策略分类 | H21: 套利策略 /期货套利 | I21: 2.018 | J21: 46262 | K21: 火富牛产品详情页 | L21: 42772 | M21: 1.696 | N21: 0.0621 | O21: 0.1774 | P21: 0.0516 | Q21: 2.4407 | R21: SR8584 | S21: 上海汇艾资管 | T21: 714 | U21: 42772 | V21: 46262 | W21: 2.6959568 | X21: 傲创提供名单 | Z21: 期货套利策略 | AB21: 46269 | AC21: 火富牛完整区间指标；历史净值复算 | AD21: 完整 | AE21: https://mp.fof99.com/fund/view/5a95543cf10b3b66 | AF21: 未确认
A22: 21 | B22: 3f5108a89aafc6d8 | C22: 惠隆金选套利1号 | D22: 私募 | E22: 套利策略—期货套利 | F22: 是 | G22: 火富牛策略分类 | H22: 套利策略 /期货套利 | I22: 1.133 | J22: 46262 | K22: 火富牛产品详情页 | L22: 44462 | M22: 0.9561 | N22: 0.0873 | O22: 0.1939 | P22: 0.0046 | Q22: 7.1254 | R22: SQG026 | S22: 北京惠隆资管 | T22: 285 | U22: 44462 | V22: 46262 | W22: 1.9560591 | X22: 傲创提供名单 | Z22: 期货套利策略 | AB22: 46269 | AC22: 火富牛完整区间指标；历史净值复算 | AD22: 完整 | AE22: https://mp.fof99.com/fund/view/3f5108a89aafc6d8 | AF22: 未确认
A23: 23 | B23: 441eaddd701f4a97 | C23: 佳泽信享5号A类 | D23: 私募 | E23: 套利策略—期货套利 | F23: 是 | G23: 火富牛策略分类 | H23: 套利策略 /期货套利 /股指套利 | I23: 1.1991 | J23: 46265 | K23: 火富牛产品详情页 | L23: 44936 | M23: 0.1991 | N23: 0.0612 | O23: 0.0547 | P23: 0.0244 | Q23: 1.2051 | R23: ZC395A | S23: 海南佳泽 | T23: 175 | U23: 44936 | V23: 46265 | W23: 1.1991 | X23: 傲创提供名单 | Z23: 期货套利策略 | AB23: 46269 | AC23: 火富牛完整区间指标；历史净值复算 | AD23: 完整 | AE23: https://mp.fof99.com/fund/view/441eaddd701f4a97 | AF23: 未确认
A24: 24 | B24: d8c5ba292c0e7653 | C24: 嘉和传承精研二期 | D24: 私募 | E24: 套利策略—期货套利 | F24: 是 | G24: 火富牛策略分类 | H24: 套利策略 /期货套利 /跨期套利；套利策略 /期货套利 /商品套利 | I24: 1.2185 | J24: 46265 | K24: 火富牛产品详情页 | L24: 44537 | M24: 0.5397 | N24: 0.0485 | O24: 0.114 | P24: 0.0894 | Q24: 1.3249 | R24: STD929 | S24: 上海嘉和传承 | T24: 268 | U24: 44537 | V24: 46265 | W24: 1.5396599 | X24: 上海分公司白名单 | Y24: 期货套利（混合套利）；期货套利（跨期套利） | AA24: 46262 | AC24: 火富牛完整区间指标；历史净值复算 | AD24: 完整 | AE24: https://mp.fof99.com/fund/view/d8c5ba292c0e7653 | AF24: 未确认
A25: 25 | B25: 735dc9bdc1713fc1 | C25: 阶石稳健1号 | D25: 私募 | E25: 套利策略—基金套利 | F25: 是 | G25: 火富牛策略分类 | H25: 套利策略 /基金套利 /ETF套利 | I25: 1.2007 | J25: 46206 | K25: 火富牛产品详情页 | L25: 45694 | M25: 0.2007 | N25: 0.1145 | O25: 0.1434 | P25: 0.0026 | Q25: 3.749 | R25: SATE65 | S25: 深圳阶石 | T25: 88 | U25: 45694 | V25: 46265 | W25: 1.3824 | X25: 傲创提供名单 | Z25: 基金套利策略 | AB25: 46269 | AC25: 火富牛成立以来指标 | AD25: 完整 | AE25: https://mp.fof99.com/fund/view/735dc9bdc1713fc1 | AF25: 未确认
A26: 26 | B26: a1580a40d8b17419 | C26: 阶石稳健7号 | D26: 私募 | E26: 套利策略—基金套利 | F26: 是 | G26: 火富牛策略分类；策略精选跟踪周报 | H26: 套利策略 /基金套利 /ETF套利 | I26: 1.1367 | J26: 46262 | K26: 火富牛产品详情页 | L26: 45749 | M26: 0.13658634 | N26: 0.091511427 | O26: 0.097371122 | P26: 0.0057289609 | Q26: 2.6204774 | R26: SAWS84 | S26: 深圳阶石 | T26: 76 | U26: 45750 | V26: 46262 | W26: 1.1367 | X26: 策略精选跟踪周报 | Y26: 套利策略｜ETF套利 | AA26: 46262 | AC26: 火富牛成立以来指标；历史净值复核/复算 | AD26: 完整 | AE26: https://mp.fof99.com/fund/view/a1580a40d8b17419 | AF26: 未确认
A27: 27 | B27: 4bda29597d3247b9 | C27: 阶石稳健9号 | D27: 私募 | E27: 套利策略—基金套利 | F27: 是 | G27: 火富牛策略分类 | H27: 套利策略 /基金套利 /ETF套利 | I27: 1.0252 | J27: 46265 | K27: 火富牛产品详情页 | L27: 45818 | M27: 0.1099 | N27: 0.0764 | O27: 0.0899 | P27: 0.0042 | Q27: 2.5823 | R27: SAZW60 | S27: 深圳阶石 | T27: 74 | U27: 45819 | V27: 46265 | W27: 1.1098815 | X27: 傲创提供名单 | Z27: 基金套利策略 | AB27: 46269 | AC27: 火富牛完整区间指标；历史净值复算 | AD27: 完整 | AE27: https://mp.fof99.com/fund/view/4bda29597d3247b9 | AF27: 未确认
A28: 28 | B28: a0e2d40b33d92ad4 | C28: 金锝牵星1号C类 | D28: 私募 | E28: 套利策略—期权套利 | F28: 是 | G28: 火富牛策略分类 | H28: 套利策略 /期权套利 | I28: 1.1126 | J28: 46265 | K28: 产品详情页 | L28: 45652 | M28: 0.1126 | N28: 0.0413 | O28: 0.067 | P28: 0.0678 | Q28: 0.5408 | R28: ASB89C | S28: 上海金锝资管 | T28: 95 | U28: 45652 | V28: 46265 | W28: 1.1126 | X28: 火富牛组合 | AC28: 火富牛产品详情页 | AD28: 完整 | AE28: https://mp.fof99.com/fund/view/a0e2d40b33d92ad4 | AF28: 未确认
A29: 29 | B29: 54b1f815aaee62da | C29: 九木套利9号A类 | D29: 私募 | E29: 套利策略—期货套利 | F29: 是 | G29: 火富牛策略分类 | H29: 套利策略 /期货套利 | I29: 1.0026 | J29: 46267 | K29: 组合持仓页回退 | L29: 46094 | M29: 0.0026 | N29: 0.0026 | O29: 0.0055 | P29: 0.0282 | Q29: -0.5116 | R29: BSA32A | S29: 深圳九木 | T29: 119 | U29: 46094 | V29: 46267 | W29: 1.0026 | X29: 火富牛组合 | AC29: 火富牛产品详情页 | AD29: 完整 | AE29: https://mp.fof99.com/fund/view/54b1f815aaee62da | AF29: 未确认
A30: 30 | B30: 206ccc429e7e2414 | C30: 九招真格量化套利一号 | D30: 私募 | E30: 套利策略—期货套利 | F30: 是 | G30: 火富牛策略分类 | H30: 套利策略 /期货套利 | I30: 1.0746 | J30: 46262 | K30: 火富牛产品详情页 | L30: 44271 | M30: 0.1336 | N30: 0.0844 | O30: 0.1366 | P30: 0.0035 | Q30: 5.4094 | R30: SQD546 | S30: 武汉九招 | T30: 311 | U30: 44271 | V30: 46265 | W30: 1.7993252 | X30: 上海分公司白名单；傲创提供名单；策略精选跟踪周报 | Y30: 量化期货（中高频&另类）；套利策略｜复合套利 | Z30: 期货套利策略 | AA30: 46262 | AB30: 46269 | AC30: 火富牛成立以来指标 | AD30: 完整 | AE30: https://mp.fof99.com/fund/view/206ccc429e7e2414 | AF30: 未确认
A31: 32 | B31: 62a3dc6ac3c3204d | C31: 聚亿具臻B类 | D31: 私募 | E31: 套利策略—期货套利 | F31: 是 | G31: 火富牛策略分类 | H31: 套利策略 /期货套利 | I31: 2.797 | J31: 46262 | K31: 火富牛产品详情页 | L31: 44061 | M31: 0.5591 | N31: 0.2531 | O31: 0.312 | P31: 0.0783 | Q31: 2.5084 | R31: LM995B | S31: 珠海聚亿基金 | T31: 102 | U31: 45608 | V31: 46262 | W31: 2.797 | X31: 傲创提供名单 | Z31: 期货套利策略 | AB31: 46269 | AC31: 火富牛完整区间指标；历史净值复算 | AD31: 完整 | AE31: https://mp.fof99.com/fund/view/62a3dc6ac3c3204d | AF31: 未确认
A32: 33 | B32: 8e3ad7d155f41bc3 | C32: 钧誉厚德量化对冲11号 | D32: 私募 | E32: 套利策略—期货套利 | F32: 是 | G32: 火富牛策略分类 | H32: 套利策略 /期货套利 /跨期套利；套利策略 /期货套利 /商品套利；套利策略 /期货套利 /高频 | I32: 1.5806 | J32: 46265 | K32: 火富牛产品详情页 | L32: 44323 | M32: 0.5806 | N32: 0.0986 | O32: 0.1091 | P32: 0.0083 | Q32: 5.8185 | R32: SQN453 | S32: 珠海钧誉资管 | T32: 933 | U32: 44323 | V32: 46265 | W32: 1.5806 | X32: 傲创提供名单 | Z32: 期货套利策略 | AB32: 46269 | AC32: 火富牛完整区间指标；历史净值复算 | AD32: 完整 | AE32: https://mp.fof99.com/fund/view/8e3ad7d155f41bc3 | AF32: 未确认
A33: 34 | B33: fd609fddab73af1e | C33: 澜胜稳赋套利1号 | D33: 私募 | E33: 套利策略—其他 | F33: 是 | G33: 火富牛策略分类；策略精选跟踪周报 | H33: 套利策略 | I33: 1.0782 | J33: 46268 | K33: 火富牛产品详情页 | L33: 46049 | M33: 0.0782 | N33: 0.0782 | O33: 0.13033333 | P33: 0.0078318628 | Q33: 3.2917686 | R33: SBPY84 | S33: 上海澜胜 | T33: 147 | U33: 46049 | V33: 46268 | W33: 1.0782 | X33: 策略精选跟踪周报 | Y33: 套利策略｜ETF套利（申赎） | AA33: 46262 | AC33: 火富牛成立以来指标；历史净值复核/复算 | AD33: 完整 | AE33: https://mp.fof99.com/fund/view/fd609fddab73af1e | AF33: 未确认
A34: 35 | B34: 672dc1ead9cd9d03 | C34: 量金灵瑞1号 | D34: 私募 | E34: 套利策略—期货套利 | F34: 是 | G34: 火富牛策略分类 | H34: 套利策略 /期货套利 | I34: 1.0205 | J34: 46267 | K34: 产品详情页 | L34: 45594 | M34: 0.0205 | N34: 0.0368 | O34: 0.0112 | P34: 0.1221 | Q34: -0.0842 | R34: SAPV10 | S34: 上海坤灵 | T34: 200 | U34: 45597 | V34: 46267 | W34: 1.0205 | X34: 火富牛组合 | AC34: 火富牛产品详情页 | AD34: 完整 | AE34: https://mp.fof99.com/fund/view/672dc1ead9cd9d03 | AF34: 未确认
A35: 36 | B35: 509478ab548cc2b3 | C35: 量客投资金选套利1号 | D35: 私募 | E35: 套利策略—期权套利 | F35: 是 | G35: 火富牛策略分类；策略精选跟踪周报 | H35: 套利策略 /期权套利 | I35: 1.0334 | J35: 46262 | K35: 火富牛产品详情页 | L35: 44196 | M35: 0.98226001 | N35: 0.044595443 | O35: 0.17353577 | P35: 0.0052485641 | Q35: 6.726678 | R35: SNH457 | S35: 上海量客 | T35: 290 | U35: 44196 | V35: 46262 | W35: 1.9824582 | X35: 策略精选跟踪周报；傲创提供名单 | Y35: 期权策略｜期权套利 | AA35: 46262 | AB35: 46274 | AC35: 火富牛成立以来指标；历史净值复核/复算 | AD35: 完整 | AE35: https://mp.fof99.com/fund/view/509478ab548cc2b3 | AF35: 未确认
A36: 37 | B36: 3ccbf07c4d4ac642 | C36: 龙帆恒盛稳固9号 | D36: 私募 | E36: 套利策略—期货套利 | F36: 是 | G36: 火富牛策略分类 | H36: 套利策略 /期货套利 /跨期套利；套利策略 /期货套利 /商品套利 | I36: 1.194 | J36: 46262 | K36: 火富牛产品详情页 | L36: 44489 | M36: 0.3902 | N36: 0.0658 | O36: 0.0804 | P36: 0.013 | Q36: 2.6102 | R36: SSX605 | S36: 厦门龙帆资管 | T36: 248 | U36: 44491 | V36: 46262 | W36: 1.3902334 | X36: 上海分公司白名单；傲创提供名单 | Y36: 期货套利（混合套利）；期货套利（跨期套利） | Z36: 期货套利策略 | AA36: 46262 | AB36: 46269 | AC36: 火富牛成立以来指标 | AD36: 完整 | AE36: https://mp.fof99.com/fund/view/3ccbf07c4d4ac642 | AF36: 未确认
A37: 38 | B37: beb13b86d2a4cfb2 | C37: 龙壹盛善时1号 | D37: 私募 | E37: 套利策略—期货套利 | F37: 是 | G37: 火富牛策略分类 | H37: 套利策略 /期货套利 | I37: 1.1373 | J37: 46267 | K37: 产品详情页 | L37: 45096 | M37: 0.0465 | O37: 0.1501 | P37: 0.0007 | Q37: 12.398 | R37: SB1261 | S37: 杭州龙壹盛 | T37: 80 | U37: 46154 | V37: 46267 | W37: 1.1373 | X37: 火富牛组合 | AC37: 火富牛产品详情页 | AD37: 完整 | AE37: https://mp.fof99.com/fund/view/beb13b86d2a4cfb2 | AF37: 未确认
A38: 39 | B38: 28d3372af2406528 | C38: 鸣熙资产-招享套利1号 | D38: 私募 | E38: 套利策略—期货套利 | F38: 是 | G38: 火富牛策略分类 | H38: 套利策略 /期货套利 | I38: 1.0568 | J38: 46262 | K38: 火富牛产品详情页 | L38: 43937 | M38: 0.8388 | N38: 0.0365 | O38: 0.1317 | P38: 0.0047 | Q38: 5.4991 | R38: SJZ381 | S38: 鸣熙资本 | T38: 337 | U38: 43937 | V38: 46262 | W38: 1.8387879 | X38: 傲创提供名单 | Z38: 期货套利策略 | AB38: 46269 | AC38: 火富牛完整区间指标；历史净值复算 | AD38: 完整 | AE38: https://mp.fof99.com/fund/view/28d3372af2406528 | AF38: 未确认
A39: 40 | B39: 9289c50ffc89f5de | C39: 铭杉量化稳健5号 | D39: 私募 | E39: 套利策略—期货套利 | F39: 是 | G39: 火富牛策略分类；策略精选跟踪周报 | H39: 套利策略 /期货套利 /跨期套利；套利策略 /期货套利 /股指套利；套利策略 /期货套利 /高频 | I39: 1.4103 | J39: 46262 | K39: 火富牛产品详情页 | L39: 44088 | M39: 0.410018 | N39: 0.021660388 | O39: 0.068966161 | P39: 0.025101273 | Q39: 2.6478431 | R39: SLT573 | S39: 上海铭杉投资 | T39: 305 | U39: 44092 | V39: 46262 | W39: 1.4103 | X39: 策略精选跟踪周报 | Y39: 高频策略｜股指高频-跨期 | AA39: 46262 | AC39: 火富牛成立以来指标；历史净值复核/复算 | AD39: 完整 | AE39: https://mp.fof99.com/fund/view/9289c50ffc89f5de | AF39: 未确认
A40: 41 | B40: f263e8836aad5b82 | C40: 摩旗ETF套利1号 | D40: 私募 | E40: 套利策略—基金套利 | F40: 是 | G40: 火富牛策略分类 | H40: 套利策略 /基金套利 /ETF套利 | I40: 1.5108 | J40: 45975 | K40: 火富牛产品详情页 | L40: 44571 | M40: 0.511 | N40: 0.0649 | O40: 0.1332 | P40: 0.0054 | Q40: 1.6446 | R40: STR466 | S40: 上海摩旗投资 | T40: 424 | U40: 44571 | V40: 46262 | W40: 1.6495 | X40: 傲创提供名单 | Z40: 基金套利策略 | AB40: 46269 | AC40: 火富牛成立以来指标；历史净值复算 | AD40: 完整 | AE40: https://mp.fof99.com/fund/view/f263e8836aad5b82 | AF40: 未确认
...

Sheet Sheet1-指标体系
A1: 私募基金指标体系
A2: 评价日 2026-09-10，指标截止 2026-09-04；沿用参考工作簿的权重和计算口径。
A3: 大类指标 | B3: 大类权重 | C3: 二级指标 | D3: 二级权重 | E3: 数据来源与方法 | F3: 时间口径 | G3: 综合权重 | I3: 计算参数 | J3: 值 | P3: 管理人规模区间 | Q3: 分值
A4: 管理人及产品 | B4: 0.15 | C4: 管理人规模 | D4: 0.4 | E4: 管理人公示规模区间分档：0-5亿60、5-10亿70、10-20亿80、20-100亿90、100亿以上100。 | F4: 最新公示 | G4: =B4*D4 -> 0.06 | I4: 产品规模标识阈值（万元） | J4: 1000 | P4: 0-5亿元 | Q4: 60
A5: 管理人及产品 | B5: =B4 -> 0.15 | C5: 产品规模 | D5: 0.3 | E5: 已精确匹配完整协会产品公示：低于1000万元提示得0；确认无该提示得100；未核实留空。 | F5: 最新公示 | G5: =B5*D5 -> 0.045 | I5: 近一年胜率观察数 | J5: 13 | P5: 5-10亿元 | Q5: 70
A6: 管理人及产品 | B6: =B4 -> 0.15 | C6: 成立年限 | D6: 0.3 | E6: 不足1年不入池；1年至不足3年70分；满3年100分。 | F6: 固定评价日 | G6: =B6*D6 -> 0.045 | I6: 近三年胜率观察数 | J6: 37 | P6: 10-20亿元 | Q6: 80
A7: 收益能力 | B7: 0.2 | C7: 年化收益 | D7: 0.7 | E7: 近1年及剔除近1年的早期年化收益分别横截面赋分，以60%/40%合成。 | F7: 近1年/早期 | G7: =B7*D7 -> 0.14 | I7: 早期胜率观察数 | J7: =J6-J5 -> 24 | P7: 20-50亿元 | Q7: 90
A8: 收益能力 | B8: =B7 -> 0.2 | C8: 月度胜率 | D8: 0.3 | E8: 近期胜率与按13/37期推算的早期胜率各乘100；早期不足6个月且缺值按模板得100。 | F8: 近1年/早期 | G8: =B8*D8 -> 0.06 | I8: 短期时间权重 | J8: 0.6 | P8: 50-100亿元 | Q8: 90
A9: 风险控制 | B9: 0.25 | C9: 最大回撤 | D9: 1 | E9: 取可用近1年与近3年最大回撤的较大值，低值优先横截面赋分。 | F9: 可用1/3年 | G9: =B9*D9 -> 0.25 | I9: 长期时间权重 | J9: 0.4 | P9: 20-100亿元 | Q9: 90
A10: 风险调整收益 | B10: 0.3 | C10: 卡玛比率 | D10: 1 | E10: 近1年卡玛与早期收益/可识别早期回撤分别横截面赋分，以60%/40%合成。 | F10: 近1年/早期 | G10: =B10*D10 -> 0.3 | I10: 趋势差距阈值 | J10: 0.2 | P10: 100亿元以上 | Q10: 100
A11: 业绩一致性/趋势 | B11: 0.1 | C11: 收益趋势 | D11: 1 | E11: 近期收益不低于比较基准得100；落后严格小于20个百分点得80；其余60。 | F11: 近1年对比 | G11: =B11*D11 -> 0.1 | I11: DD识别容差 | J11: 0.0001
I12: 评价日 | J12: 46275
I13: 指标截止日 | J13: 46269
A14: 计算与来源说明 | I14: 年限换算天数 | J14: 365.25
A15: 评价范围 | E15: 83条原跟踪记录全部保留。成立不足1年不入池；缺成立日期或备案号未匹配的记录不计算入池总分。 | I15: 入池最低年限 | J15: 1
A16: 横截面范围 | E16: 沿用模板：所有入池且该项有数值的产品一起排名，不按策略另分样本。平台一级、二级策略仅作汇总和筛选。 | I16: 长期评价年限 | J16: 3
A17: 排名算法 | E17: 高值优先：100×(低于本值数量＋同值数量÷2－0.5)÷(有效样本数－1)；回撤反向。仅1个样本得100。 | I17: 短存续年限分 | J17: 70
A18: 早期收益 | E18: 满3年：((1+近3年年化)^3/(1+近1年年化))^(1/2)-1；不足3年以成立以来年化与存续年限剔除近1年。 | I18: 满分 | J18: 100
A19: 月胜率假设 | E19: 按模板13期近期、37期三年观察数，早期24期。没有逐月胜负数据核实该观察数；超出0至100%的早期胜率不赋分。 | I19: 早期胜率免评月数 | J19: 6
A20: 早期胜率免评 | E20: 早期历史少于6个月且早期胜率缺失或不在0至100%时，模板给予100分。此项是假设，不是观测月胜率。 | I20: 一年月数 | J20: 12
A21: 回撤推算假设 | E21: 近1年回撤=ABS(近1年年化/近1年卡玛)。只有近3年回撤大于该值加容差0.0001时才视为可识别早期回撤。 | I21: 产品低规模分 | J21: 0
A22: 风险口径限制 | E22: 早期回撤识别依赖模板假设，未经净值路径验证；平台近3年卡玛原值保留，但模板长期卡玛采用早期收益/推断回撤。 | I22: 趋势中档分 | J22: 80
A23: 缺失处理 | E23: 缺值留空。各大类与总分均以可用叶子指标的有效权重归一；汇总直接链接明细，避免二次归一差异。 | I23: 趋势低档分 | J23: 60
A24: 总分解释 | E24: 有效权重不足100%为暂定分，可能因缺失项而偏高。严格总分仅有效权重100%时显示；总分不是投资建议。
A25: 管理人规模来源 | E25: 本次以2026-09-11协会管理人公示核验规模并更新查询核对表，历史平台来源仍在原文件可追溯。 | I25: 综合权重合计 | J25: =SUM(G4:G11) -> 1
A26: 产品规模标识 | E26: 协会完整产品公示精确匹配后才赋分。无低规模提示不证明实际规模达到1000万元，只表示未见该公示提示。 | I26: 时间权重合计 | J26: =SUM(J8:J9) -> 1
A27: 日期口径 | E27: 评价日固定为本表参数；指标按同一截止日期导出。成立日期、近1年与近3年窗口均取平台导出字段。
A28: 原始模板 | E28: 私募基金_指标赋分(1)(1).xlsx：sheet1-指标体系、sheet2-计算明细、sheet3-分类汇总、sheet4-原始数据。
A29: 数据来源 | E29: 火富牛 https://mp.fof99.com/fund/all；各产品详情和协会公示URL见Sheet5-查询核对。
A30: 原表保留 | E30: 套利产品原表保留原83条记录与32列。未匹配产品在原始数据页仅保留原表名称，其他平台字段留空并标记匹配状态。 | I30: 补数年化天数 | J30: 365
I31: 边界净值最大滞后天数 | J31: 14
I32: 重点排查差异（分） | J32: 5
I33: 协会核验日 | J33: 46276
I34: 规模分档边界（亿元） | J34: 5
A46: 本次补数与分组口径
A47: 补数来源 | E47: 傲创缺失数据.zip内26份净值表，文件名称与主表产品名称精确关联，备案号沿用已核验主表。净值文件自身不含备案号。
A48: 本版评价体系 | E48: 按照本次上传主表统一沿用现有权重及计算明细，不切换先前短历史参考模型。评价日仍为2026-09-10，绩效截止2026-09-04。
A49: 补数边界 | E49: 以83只基金表为基准，不补正两表差异值。压缩包逐项核算列示208项核算结果，独立复算差异不回写现有指标。
A50: 收益及回撤 | E50: 使用复权净值。年化收益=(末值/初值)^(365/实际间隔天数)-1，最大回撤由窗口内逐条净值及运行峰值计算，卡玛=年化收益/回撤。
A51: 时间对齐 | E51: 1年、3年目标起点为2025-09-04、2023-09-04，取不晚于边界的最近净值并记录实际日期，不插值。边界滞后超过14天不补算。
...

Sheet Sheet2-计算明细
A1: 私募基金指标计算明细
A2: 绿色为来源数据链接，黑色为计算。按模板逐项计算，缺失项从分子和有效权重中同时剔除。
A4: 大类指标 | B4: 大类权重 | C4: 二级指标 | D4: 综合权重 | F4: 评价日 | G4: ='Sheet1-指标体系'!$J$12 -> 46275
A5: ='Sheet1-指标体系'!A4 -> 管理人及产品 | B5: ='Sheet1-指标体系'!B4 -> 0.15 | C5: ='Sheet1-指标体系'!C4 -> 管理人规模 | D5: ='Sheet1-指标体系'!G4 -> 0.06 | F5: 指标截止 | G5: ='Sheet1-指标体系'!$J$13 -> 46269
A6: ='Sheet1-指标体系'!A5 -> 管理人及产品 | B6: ='Sheet1-指标体系'!B5 -> 0.15 | C6: ='Sheet1-指标体系'!C5 -> 产品规模 | D6: ='Sheet1-指标体系'!G5 -> 0.045
A7: ='Sheet1-指标体系'!A6 -> 管理人及产品 | B7: ='Sheet1-指标体系'!B6 -> 0.15 | C7: ='Sheet1-指标体系'!C6 -> 成立年限 | D7: ='Sheet1-指标体系'!G6 -> 0.045 | F7: 排名样本 | G7: 全体入池产品
A8: ='Sheet1-指标体系'!A7 -> 收益能力 | B8: ='Sheet1-指标体系'!B7 -> 0.2 | C8: ='Sheet1-指标体系'!C7 -> 年化收益 | D8: ='Sheet1-指标体系'!G7 -> 0.14 | F8: 缺失数据 | G8: 保留，显示暂定分
A9: ='Sheet1-指标体系'!A8 -> 收益能力 | B9: ='Sheet1-指标体系'!B8 -> 0.2 | C9: ='Sheet1-指标体系'!C8 -> 月度胜率 | D9: ='Sheet1-指标体系'!G8 -> 0.06 | F9: 全部记录 | G9: 83
A10: ='Sheet1-指标体系'!A9 -> 风险控制 | B10: ='Sheet1-指标体系'!B9 -> 0.25 | C10: ='Sheet1-指标体系'!C9 -> 最大回撤 | D10: ='Sheet1-指标体系'!G9 -> 0.25
A11: ='Sheet1-指标体系'!A10 -> 风险调整收益 | B11: ='Sheet1-指标体系'!B10 -> 0.3 | C11: ='Sheet1-指标体系'!C10 -> 卡玛比率 | D11: ='Sheet1-指标体系'!G10 -> 0.3
A12: ='Sheet1-指标体系'!A11 -> 业绩一致性/趋势 | B12: ='Sheet1-指标体系'!B11 -> 0.1 | C12: ='Sheet1-指标体系'!C11 -> 收益趋势 | D12: ='Sheet1-指标体系'!G11 -> 0.1
A16: 序号 | B16: 产品名称 | C16: 备案号 | D16: 管理人 | E16: 产品成立日期 | F16: 产品成立年限（年） | G16: 入池状态 | H16: 管理规模区间（亿元） | I16: 管理人规模分 | J16: 产品规模公示标识 | K16: 产品规模分 | L16: 成立年限分 | M16: R_1y | N16: R_3y | O16: R_incep（补录） | P16: R_early | Q16: R_1y排名分 | R16: R_early排名分 | S16: 年化收益分（可用折算） | T16: 近1年月胜率 | U16: 近3年月胜率 | V16: 早期月胜率 | W16: 近1年月胜率分 | X16: 早期月胜率分 | Y16: 月度胜率分（可用折算） | Z16: DD_1y | AA16: DD_3y | AB16: 统一最大回撤 | AC16: 最大回撤分 | AD16: 短期卡玛 | AE16: 可识别DD_long | AF16: 长期卡玛 | AG16: 短期卡玛分 | AH16: 长期卡玛分 | AI16: 卡玛比率分（可用折算） | AJ16: 趋势比较基准 | AK16: 收益趋势分 | AL16: 管理人及产品大类分 | AM16: 收益能力大类分 | AN16: 风险控制大类分 | AO16: 风险调整收益大类分 | AP16: 趋势大类分 | AQ16: 有效二级权重 | AR16: 加权总分（不补缺） | AS16: 可比总分（归一） | AT16: 唯一排名 | AU16: 数据缺口 | AV16: 严格总分 | AW16: 数据完整性 | AX16: 平台一级策略 | AY16: 平台二级策略 | AZ16: 原表策略参考 | BA16: 原表行号 | BB16: 匹配状态 | BC16: 来源URL | BD16: 指标截止日 | BE16: 管理人规模来源 | BF16: 规模日期 | BG16: 产品标识来源 | BH16: 标识日期 | BI16: 查询备案号线索 | BJ16: 汇总展示次序 | BK16: 近1年收益有效 | BL16: 早期收益有效 | BM16: 回撤有效 | BN16: 近期卡玛有效 | BO16: 早期卡玛有效 | BP16: 管理人规模贡献 | BQ16: 产品规模贡献 | BR16: 成立年限贡献 | BS16: 近1年收益排名贡献 | BT16: 早期收益排名贡献 | BU16: 近1年月胜率贡献 | BV16: 早期月胜率贡献 | BW16: 最大回撤排名贡献 | BX16: 近期卡玛排名贡献 | BY16: 早期卡玛排名贡献 | BZ16: 收益趋势贡献 | CA16: 管理人规模有效权重 | CB16: 产品规模有效权重 | CC16: 成立年限有效权重 | CD16: 近1年收益排名有效权重 | CE16: 早期收益排名有效权重 | CF16: 近1年月胜率有效权重 | CG16: 早期月胜率有效权重 | CH16: 最大回撤排名有效权重 | CI16: 近期卡玛排名有效权重 | CJ16: 早期卡玛排名有效权重 | CK16: 收益趋势有效权重
A17: ='Sheet5-查询核对'!A2-1 -> 1 | B17: =IF('Sheet4-原始数据'!A2="",'Sheet5-查询核对'!B2,'Sheet4-原始数据'!A2) -> 爱凡哲九号 | C17: =IF('Sheet4-原始数据'!B2="","",'Sheet4-原始数据'!B2) -> SJA112 | D17: =IF('Sheet4-原始数据'!E2="","",'Sheet4-原始数据'!E2) -> 爱凡哲投资 | E17: =IF('Sheet4-原始数据'!F2="","",'Sheet4-原始数据'!F2) -> 43710 | F17: =IF(ISNUMBER(E17),ROUND(('Sheet1-指标体系'!$J$12-E17)/'Sheet1-指标体系'!$J$14,4),"") -> 7.0226 | G17: =IF(C17="","未匹配",IF(NOT(ISNUMBER(F17)),"缺成立日期",IF(F17<'Sheet1-指标体系'!$J$15,"不入池","入池"))) -> 入池 | H17: =IF('Sheet5-查询核对'!K2="","",'Sheet5-查询核对'!K2) -> 20-50亿元 | I17: =IF(H17="","",IF(COUNTIF('Sheet1-指标体系'!$P$4:$P$10,H17)=0,"",INDEX('Sheet1-指标体系'!$Q$4:$Q$10,MATCH(H17,'Sheet1-指标体系'!$P$4:$P$10,0)))) -> 90 | J17: =IF(NOT(ISNUMBER('Sheet5-查询核对'!N2)),"",IF('Sheet5-查询核对'!N2=1,"低于"&'Sheet1-指标体系'!$J$4&"万元",IF('Sheet5-查询核对'!N2=0,"无低于"&'Sheet1-指标体系'!$J$4&"万元标识",""))) -> 无低于1000万元标识 | K17: =IF(NOT(ISNUMBER('Sheet5-查询核对'!N2)),"",IF('Sheet5-查询核对'!N2=1,'Sheet1-指标体系'!$J$21,IF('Sheet5-查询核对'!N2=0,'Sheet1-指标体系'!$J$18,""))) -> 100 | L17: =IF(NOT(ISNUMBER(F17)),"",IF(F17<'Sheet1-指标体系'!$J$15,"",IF(F17<'Sheet1-指标体系'!$J$16,'Sheet1-指标体系'!$J$17,'Sheet1-指标体系'!$J$18))) -> 100 | M17: =IF(ISNUMBER('Sheet4-原始数据'!G2),'Sheet4-原始数据'!G2,"") -> 0.1239 | N17: =IF(ISNUMBER('Sheet4-原始数据'!H2),'Sheet4-原始数据'!H2,"") -> 0.1185 | O17: =IF(ISNUMBER('Sheet5-查询核对'!Q2),'Sheet5-查询核对'!Q2,"") -> 0.103 | P17: =IF(G17<>"入池","",IF(F17>='Sheet1-指标体系'!$J$16,IF(AND(ISNUMBER(M17),ISNUMBER(N17)),IF(AND(1+M17>0,1+N17>=0),((1+N17)^'Sheet1-指标体系'!$J$16/(1+M17))^(1/('Sheet1-指标体系'!$J$16-1))-1,""),""),IF(AND(ISNUMBER(M17),ISNUMBER(O17)),IF(AND(F17>1,1+M17>0,1+O17>=0),((1+O17)^F17/(1+M17))^(1/(F17-1))-1,""),""))) -> 0.11580974 | Q17: =IF(BK17=1,IF(SUM($BK$17:$BK$99)<=1,100,ROUND(100*(COUNTIFS($BK$17:$BK$99,1,$M$17:$M$99,"<"&M17)+(COUNTIFS($BK$17:$BK$99,1,$M$17:$M$99,M17)-1)/2)/(SUM($BK$17:$BK$99)-1),2)),"") -> 72.22 | R17: =IF(BL17=1,IF(SUM($BL$17:$BL$99)<=1,100,ROUND(100*(COUNTIFS($BL$17:$BL$99,1,$P$17:$P$99,"<"&P17)+(COUNTIFS($BL$17:$BL$99,1,$P$17:$P$99,P17)-1)/2)/(SUM($BL$17:$BL$99)-1),2)),"") -> 77.27 | S17: =IF(ISNUMBER(Q17),IF(ISNUMBER(R17),ROUND(Q17*'Sheet1-指标体系'!$J$8+R17*'Sheet1-指标体系'!$J$9,2),Q17),"") -> 74.24 | T17: =IF(ISNUMBER('Sheet4-原始数据'!J2),'Sheet4-原始数据'!J2,"") -> 0.8462 | U17: =IF(ISNUMBER('Sheet4-原始数据'!I2),'Sheet4-原始数据'!I2,"") -> 0.8919 | V17: =IF(AND(ISNUMBER(T17),ISNUMBER(U17)),(U17*'Sheet1-指标体系'!$J$6-T17*'Sheet1-指标体系'!$J$5)/'Sheet1-指标体系'!$J$7,"") -> 0.91665417 | W17: =IF(ISNUMBER(T17),100*T17,"") -> 84.62 | X17: =IF(G17<>"入池","",IF(ISNUMBER(V17),IF(AND(V17>=0,V17<=1),V17*'Sheet1-指标体系'!$J$18,IF(MAX(0,(F17-'Sheet1-指标体系'!$J$15)*'Sheet1-指标体系'!$J$20)<'Sheet1-指标体系'!$J$19,'Sheet1-指标体系'!$J$18,"")),IF(MAX(0,(F17-'Sheet1-指标体系'!$J$15)*'Sheet1-指标体系'!$J$20)<'Sheet1-指标体系'!$J$19,'Sheet1-指标体系'!$J$18,""))) -> 91.665417 | Y17: =IF(ISNUMBER(W17),IF(ISNUMBER(X17),ROUND(W17*'Sheet1-指标体系'!$J$8+X17*'Sheet1-指标体系'!$J$9,2),W17),"") -> 87.44 | Z17: =IF(AND(ISNUMBER(M17),ISNUMBER(AD17)),IF(AD17<>0,ABS(M17/AD17),""),"") -> 0.0035831099 | AA17: =IF(ISNUMBER('Sheet4-原始数据'!K2),'Sheet4-原始数据'!K2,"") -> 0.0129 | AB17: =IF(AND(ISNUMBER(Z17),ISNUMBER(AA17)),MAX(Z17,AA17),IF(ISNUMBER(Z17),Z17,IF(ISNUMBER(AA17),AA17,""))) -> 0.0129 | AC17: =IF(BM17=1,IF(SUM($BM$17:$BM$99)<=1,100,ROUND(100*(COUNTIFS($BM$17:$BM$99,1,$AB$17:$AB$99,">"&AB17)+(COUNTIFS($BM$17:$BM$99,1,$AB$17:$AB$99,AB17)-1)/2)/(SUM($BM$17:$BM$99)-1),2)),"") -> 62.16 | AD17: =IF(ISNUMBER('Sheet4-原始数据'!M2),'Sheet4-原始数据'!M2,"") -> 34.5789 | AE17: =IF(AND(ISNUMBER(P17),ISNUMBER(AA17),ISNUMBER(Z17)),IF(AA17>Z17+'Sheet1-指标体系'!$J$11,AA17,""),"") -> 0.0129 | AF17: =IF(AND(ISNUMBER(P17),ISNUMBER(AE17)),IF(AE17<>0,P17/AE17,""),"") -> 8.977499 | AG17: =IF(BN17=1,IF(SUM($BN$17:$BN$99)<=1,100,ROUND(100*(COUNTIFS($BN$17:$BN$99,1,$AD$17:$AD$99,"<"&AD17)+(COUNTIFS($BN$17:$BN$99,1,$AD$17:$AD$99,AD17)-1)/2)/(SUM($BN$17:$BN$99)-1),2)),"") -> 88.73 | AH17: =IF(BO17=1,IF(SUM($BO$17:$BO$99)<=1,100,ROUND(100*(COUNTIFS($BO$17:$BO$99,1,$AF$17:$AF$99,"<"&AF17)+(COUNTIFS($BO$17:$BO$99,1,$AF$17:$AF$99,AF17)-1)/2)/(SUM($BO$17:$BO$99)-1),2)),"") -> 75 | AI17: =IF(ISNUMBER(AG17),IF(ISNUMBER(AH17),ROUND(AG17*'Sheet1-指标体系'!$J$8+AH17*'Sheet1-指标体系'!$J$9,2),AG17),"") -> 83.24 | AJ17: =IF(NOT(ISNUMBER(F17)),"",IF(F17>='Sheet1-指标体系'!$J$16,IF(ISNUMBER(N17),N17,""),IF(ISNUMBER(O17),O17,""))) -> 0.1185 | AK17: =IF(AND(G17="入池",ISNUMBER(M17),ISNUMBER(AJ17)),IF(M17>=AJ17,'Sheet1-指标体系'!$J$18,IF(AJ17-M17<'Sheet1-指标体系'!$J$10,'Sheet1-指标体系'!$J$22,'Sheet1-指标体系'!$J$23)),"") -> 100 | AL17: =IF((IF(ISNUMBER(I17),'Sheet1-指标体系'!$G$4,0)+IF(ISNUMBER(K17),'Sheet1-指标体系'!$G$5,0)+IF(ISNUMBER(L17),'Sheet1-指标体系'!$G$6,0))>0,ROUND((IF(ISNUMBER(I17),I17*'Sheet1-指标体系'!$G$4,0)+IF(ISNUMBER(K17),K17*'Sheet1-指标体系'!$G$5,0)+IF(ISNUMBER(L17),L17*'Sheet1-指标体系'!$G$6,0))/(IF(ISNUMBER(I17),'Sheet1-指标体系'!$G$4,0)+IF(ISNUMBER(K17),'Sheet1-指标体系'!$G$5,0)+IF(ISNUMBER(L17),'Sheet1-指标体系'!$G$6,0)),2),"") -> 96 | AM17: =IF(SUM(CD17:CG17)>0,ROUND(SUM(BS17:BV17)/SUM(CD17:CG17),2),"") -> 78.2 | AN17: =IF(SUM(CH17:CH17)>0,ROUND(SUM(BW17:BW17)/SUM(CH17:CH17),2),"") -> 62.16 | AO17: =IF(SUM(CI17:CJ17)>0,ROUND(SUM(BX17:BY17)/SUM(CI17:CJ17),2),"") -> 83.24 | AP17: =IF(SUM(CK17:CK17)>0,ROUND(SUM(BZ17:BZ17)/SUM(CK17:CK17),2),"") -> 100 | AQ17: =SUM(CA17:CK17) -> 1 | AR17: =IF(SUM(CA17:CK17)>0,SUM(BP17:BZ17),"") -> 80.55129 | AS17: =IF(SUM(CA17:CK17)>0,ROUND(SUM(BP17:BZ17)/SUM(CA17:CK17),2),"") -> 80.55 | AT17: =IF(OR(G17<>"入池",NOT(ISNUMBER(AS17))),"",COUNTIFS($G$17:$G$99,"入池",$AS$17:$AS$99,">"&AS17)+COUNTIFS($G$17:$G$99,"入池",$AS$17:$AS$99,AS17,$AQ$17:$AQ$99,">"&AQ17)+COUNTIFS($G$17:G17,"入池",$AS$17:AS17,AS17,$AQ$17:AQ17,AQ17)) -> 15 | AU17: =IF(NOT(ISNUMBER(I17)),"管理人规模；","")&IF(NOT(ISNUMBER(K17)),"产品规模标识；","")&IF(NOT(ISNUMBER(M17)),"近一年收益；","")&IF(NOT(ISNUMBER(T17)),"近一年胜率；","")&IF(NOT(ISNUMBER(N17)),"近三年收益；","")&IF(NOT(ISNUMBER(U17)),"近三年胜率；","")&IF(NOT(ISNUMBER(AA17)),"近三年回撤；","")&IF(NOT(ISNUMBER(AD17)),"近一年卡玛；","")&IF(ISNUMBER(F17),IF(AND(F17<'Sheet1-指标体系'!$J$16,NOT(ISNUMBER(O17))),"成立以来年化；",""),"成立日期；")&IF(ISNUMBER(V17),IF(OR(V17<0,V17>1),"胜率窗口口径不一致；",""),"")&IF(ISNUMBER(P17),IF(NOT(ISNUMBER(AE17)),"DD_long不可识别；",""),"") | AV17: =IF(ABS(SUM(CA17:CK17)-'Sheet1-指标体系'!$J$25)<0.0000000001,SUM(BP17:BZ17),"") -> 80.55129 | AW17: =IF(G17<>"入池",G17,IF(AQ17=0,"无有效评分数据",IF(ROUND(AQ17,10)=ROUND('Sheet1-指标体系'!$J$25,10),"完整赋分","暂定分／数据不完整"))) -> 完整赋分 | AX17: =IF('Sheet4-原始数据'!C2="","",'Sheet4-原始数据'!C2) -> 套利策略 | AY17: =IF('Sheet4-原始数据'!D2="","",'Sheet4-原始数据'!D2) -> 期货套利 | AZ17: =IF('Sheet5-查询核对'!S2="","",'Sheet5-查询核对'!S2) -> 套利策略—期货套利 | BA17: =IF('Sheet5-查询核对'!A2="","",'Sheet5-查询核对'!A2) -> 2 | BB17: =IF('Sheet5-查询核对'!F2="","",'Sheet5-查询核对'!F2) -> 备案号匹配 | BC17: =IF('Sheet5-查询核对'!I2="","",'Sheet5-查询核对'!I2) -> https://mp.fof99.com/fund/view/8e641c904118560b | BD17: =IF('Sheet5-查询核对'!H2="","",'Sheet5-查询核对'!H2) -> 46269 | BE17: =IF('Sheet5-查询核对'!L2="","",'Sheet5-查询核对'!L2) -> https://gs.amac.org.cn/amac-infodisc/res/pof/manager/1709181131101311.html | BF17: =IF('Sheet5-查询核对'!M2="","",'Sheet5-查询核对'!M2) -> 46276 | BG17: =IF('Sheet5-查询核对'!O2="","",'Sheet5-查询核对'!O2) -> https://gs.amac.org.cn/amac-infodisc/res/pof/fund/1909051919107161.html | BH17: =IF('Sheet5-查询核对'!P2="","",'Sheet5-查询核对'!P2) -> 46276 | BI17: =IF('Sheet5-查询核对'!D2="","",'Sheet5-查询核对'!D2) -> SJA112 | BJ17: =IF(ISNUMBER(AT17),AT17,COUNT($AT$17:$AT$99)+ROWS($AT$17:AT17)-COUNT($AT$17:AT17)) -> 15 | BK17: =IF(G17="入池",IF(ISNUMBER(M17),1,0),0) -> 1 | BL17: =IF(G17="入池",IF(ISNUMBER(P17),1,0),0) -> 1 | BM17: =IF(G17="入池",IF(ISNUMBER(AB17),1,0),0) -> 1 | BN17: =IF(G17="入池",IF(ISNUMBER(AD17),1,0),0) -> 1 | BO17: =IF(G17="入池",IF(ISNUMBER(AF17),1,0),0) -> 1 | BP17: =IF(G17="入池",IF(ISNUMBER(I17),I17*('Sheet1-指标体系'!$G$4),0),0) -> 5.4 | BQ17: =IF(G17="入池",IF(ISNUMBER(K17),K17*('Sheet1-指标体系'!$G$5),0),0) -> 4.5 | BR17: =IF(G17="入池",IF(ISNUMBER(L17),L17*('Sheet1-指标体系'!$G$6),0),0) -> 4.5 | BS17: =IF(G17="入池",IF(ISNUMBER(Q17),Q17*('Sheet1-指标体系'!$G$7*'Sheet1-指标体系'!$J$8),0),0) -> 6.06648 | BT17: =IF(G17="入池",IF(ISNUMBER(R17),R17*('Sheet1-指标体系'!$G$7*'Sheet1-指标体系'!$J$9),0),0) -> 4.32712 | BU17: =IF(G17="入池",IF(ISNUMBER(W17),W17*('Sheet1-指标体系'!$G$8*'Sheet1-指标体系'!$J$8),0),0) -> 3.04632 | BV17: =IF(G17="入池",IF(ISNUMBER(X17),X17*('Sheet1-指标体系'!$G$8*'Sheet1-指标体系'!$J$9),0),0) -> 2.19997 | BW17: =IF(G17="入池",IF(ISNUMBER(AC17),AC17*('Sheet1-指标体系'!$G$9),0),0) -> 15.54 | BX17: =IF(G17="入池",IF(ISNUMBER(AG17),AG17*('Sheet1-指标体系'!$G$10*'Sheet1-指标体系'!$J$8),0),0) -> 15.9714 | BY17: =IF(G17="入池",IF(ISNUMBER(AH17),AH17*('Sheet1-指标体系'!$G$10*'Sheet1-指标体系'!$J$9),0),0) -> 9 | BZ17: =IF(G17="入池",IF(ISNUMBER(AK17),AK17*('Sheet1-指标体系'!$G$11),0),0) -> 10 | CA17: =IF(G17="入池",IF(ISNUMBER(I17),'Sheet1-指标体系'!$G$4,0),0) -> 0.06 | CB17: =IF(G17="入池",IF(ISNUMBER(K17),'Sheet1-指标体系'!$G$5,0),0) -> 0.045 | CC17: =IF(G17="入池",IF(ISNUMBER(L17),'Sheet1-指标体系'!$G$6,0),0) -> 0.045 | CD17: =IF(G17="入池",IF(ISNUMBER(Q17),'Sheet1-指标体系'!$G$7*'Sheet1-指标体系'!$J$8,0),0) -> 0.084 | CE17: =IF(G17="入池",IF(ISNUMBER(R17),'Sheet1-指标体系'!$G$7*'Sheet1-指标体系'!$J$9,0),0) -> 0.056 | CF17: =IF(G17="入池",IF(ISNUMBER(W17),'Sheet1-指标体系'!$G$8*'Sheet1-指标体系'!$J$8,0),0) -> 0.036 | CG17: =IF(G17="入池",IF(ISNUMBER(X17),'Sheet1-指标体系'!$G$8*'Sheet1-指标体系'!$J$9,0),0) -> 0.024 | CH17: =IF(G17="入池",IF(ISNUMBER(AC17),'Sheet1-指标体系'!$G$9,0),0) -> 0.25 | CI17: =IF(G17="入池",IF(ISNUMBER(AG17),'Sheet1-指标体系'!$G$10*'Sheet1-指标体系'!$J$8,0),0) -> 0.18 | CJ17: =IF(G17="入池",IF(ISNUMBER(AH17),'Sheet1-指标体系'!$G$10*'Sheet1-指标体系'!$J$9,0),0) -> 0.12 | CK17: =IF(G17="入池",IF(ISNUMBER(AK17),'Sheet1-指标体系'!$G$11,0),0) -> 0.1
A18: ='Sheet5-查询核对'!A3-1 -> 2 | B18: =IF('Sheet4-原始数据'!A3="",'Sheet5-查询核对'!B3,'Sheet4-原始数据'!A3) -> 滨风风云瑞丰1号 | C18: =IF('Sheet4-原始数据'!B3="","",'Sheet4-原始数据'!B3) -> SXL267 | D18: =IF('Sheet4-原始数据'!E3="","",'Sheet4-原始数据'!E3) -> 鹰潭滨风投资 | E18: =IF('Sheet4-原始数据'!F3="","",'Sheet4-原始数据'!F3) -> 44897 | F18: =IF(ISNUMBER(E18),ROUND(('Sheet1-指标体系'!$J$12-E18)/'Sheet1-指标体系'!$J$14,4),"") -> 3.7728 | G18: =IF(C18="","未匹配",IF(NOT(ISNUMBER(F18)),"缺成立日期",IF(F18<'Sheet1-指标体系'!$J$15,"不入池","入池"))) -> 入池 | H18: =IF('Sheet5-查询核对'!K3="","",'Sheet5-查询核对'!K3) -> 5-10亿元 | I18: =IF(H18="","",IF(COUNTIF('Sheet1-指标体系'!$P$4:$P$10,H18)=0,"",INDEX('Sheet1-指标体系'!$Q$4:$Q$10,MATCH(H18,'Sheet1-指标体系'!$P$4:$P$10,0)))) -> 70 | J18: =IF(NOT(ISNUMBER('Sheet5-查询核对'!N3)),"",IF('Sheet5-查询核对'!N3=1,"低于"&'Sheet1-指标体系'!$J$4&"万元",IF('Sheet5-查询核对'!N3=0,"无低于"&'Sheet1-指标体系'!$J$4&"万元标识",""))) -> 无低于1000万元标识 | K18: =IF(NOT(ISNUMBER('Sheet5-查询核对'!N3)),"",IF('Sheet5-查询核对'!N3=1,'Sheet1-指标体系'!$J$21,IF('Sheet5-查询核对'!N3=0,'Sheet1-指标体系'!$J$18,""))) -> 100 | L18: =IF(NOT(ISNUMBER(F18)),"",IF(F18<'Sheet1-指标体系'!$J$15,"",IF(F18<'Sheet1-指标体系'!$J$16,'Sheet1-指标体系'!$J$17,'Sheet1-指标体系'!$J$18))) -> 100 | M18: =IF(ISNUMBER('Sheet4-原始数据'!G3),'Sheet4-原始数据'!G3,"") -> 0.45675608 | N18: =IF(ISNUMBER('Sheet4-原始数据'!H3),'Sheet4-原始数据'!H3,"") -> 0.24545794 | O18: =IF(ISNUMBER('Sheet5-查询核对'!Q3),'Sheet5-查询核对'!Q3,"") -> 0.2454158 | P18: =IF(G18<>"入池","",IF(F18>='Sheet1-指标体系'!$J$16,IF(AND(ISNUMBER(M18),ISNUMBER(N18)),IF(AND(1+M18>0,1+N18>=0),((1+N18)^'Sheet1-指标体系'!$J$16/(1+M18))^(1/('Sheet1-指标体系'!$J$16-1))-1,""),""),IF(AND(ISNUMBER(M18),ISNUMBER(O18)),IF(AND(F18>1,1+M18>0,1+O18>=0),((1+O18)^F18/(1+M18))^(1/(F18-1))-1,""),""))) -> 0.15159609 | Q18: =IF(BK18=1,IF(SUM($BK$17:$BK$99)<=1,100,ROUND(100*(COUNTIFS($BK$17:$BK$99,1,$M$17:$M$99,"<"&M18)+(COUNTIFS($BK$17:$BK$99,1,$M$17:$M$99,M18)-1)/2)/(SUM($BK$17:$BK$99)-1),2)),"") -> 100 | R18: =IF(BL18=1,IF(SUM($BL$17:$BL$99)<=1,100,ROUND(100*(COUNTIFS($BL$17:$BL$99,1,$P$17:$P$99,"<"&P18)+(COUNTIFS($BL$17:$BL$99,1,$P$17:$P$99,P18)-1)/2)/(SUM($BL$17:$BL$99)-1),2)),"") -> 87.88 | S18: =IF(ISNUMBER(Q18),IF(ISNUMBER(R18),ROUND(Q18*'Sheet1-指标体系'!$J$8+R18*'Sheet1-指标体系'!$J$9,2),Q18),"") -> 95.15 | T18: =IF(ISNUMBER('Sheet4-原始数据'!J3),'Sheet4-原始数据'!J3,"") -> 0.69230769 | U18: =IF(ISNUMBER('Sheet4-原始数据'!I3),'Sheet4-原始数据'!I3,"") -> 0.64864865 | V18: =IF(AND(ISNUMBER(T18),ISNUMBER(U18)),(U18*'Sheet1-指标体系'!$J$6-T18*'Sheet1-指标体系'!$J$5)/'Sheet1-指标体系'!$J$7,"") -> 0.625 | W18: =IF(ISNUMBER(T18),100*T18,"") -> 69.230769 | X18: =IF(G18<>"入池","",IF(ISNUMBER(V18),IF(AND(V18>=0,V18<=1),V18*'Sheet1-指标体系'!$J$18,IF(MAX(0,(F18-'Sheet1-指标体系'!$J$15)*'Sheet1-指标体系'!$J$20)<'Sheet1-指标体系'!$J$19,'Sheet1-指标体系'!$J$18,"")),IF(MAX(0,(F18-'Sheet1-指标体系'!$J$15)*'Sheet1-指标体系'!$J$20)<'Sheet1-指标体系'!$J$19,'Sheet1-指标体系'!$J$18,""))) -> 62.5 | Y18: =IF(ISNUMBER(W18),IF(ISNUMBER(X18),ROUND(W18*'Sheet1-指标体系'!$J$8+X18*'Sheet1-指标体系'!$J$9,2),W18),"") -> 66.54 | Z18: =IF(AND(ISNUMBER(M18),ISNUMBER(AD18)),IF(AD18<>0,ABS(M18/AD18),""),"") -> 0.13061536 | AA18: =IF(ISNUMBER('Sheet4-原始数据'!K3),'Sheet4-原始数据'!K3,"") -> 0.13061536 | AB18: =IF(AND(ISNUMBER(Z18),ISNUMBER(AA18)),MAX(Z18,AA18),IF(ISNUMBER(Z18),Z18,IF(ISNUMBER(AA18),AA18,""))) -> 0.13061536 | AC18: =IF(BM18=1,IF(SUM($BM$17:$BM$99)<=1,100,ROUND(100*(COUNTIFS($BM$17:$BM$99,1,$AB$17:$AB$99,">"&AB18)+(COUNTIFS($BM$17:$BM$99,1,$AB$17:$AB$99,AB18)-1)/2)/(SUM($BM$17:$BM$99)-1),2)),"") -> 4.05 | AD18: =IF(ISNUMBER('Sheet4-原始数据'!M3),'Sheet4-原始数据'!M3,"") -> 3.4969554 | AE18: =IF(AND(ISNUMBER(P18),ISNUMBER(AA18),ISNUMBER(Z18)),IF(AA18>Z18+'Sheet1-指标体系'!$J$11,AA18,""),"") | AF18: =IF(AND(ISNUMBER(P18),ISNUMBER(AE18)),IF(AE18<>0,P18/AE18,""),"") | AG18: =IF(BN18=1,IF(SUM($BN$17:$BN$99)<=1,100,ROUND(100*(COUNTIFS($BN$17:$BN$99,1,$AD$17:$AD$99,"<"&AD18)+(COUNTIFS($BN$17:$BN$99,1,$AD$17:$AD$99,AD18)-1)/2)/(SUM($BN$17:$BN$99)-1),2)),"") -> 29.58 | AH18: =IF(BO18=1,IF(SUM($BO$17:$BO$99)<=1,100,ROUND(100*(COUNTIFS($BO$17:$BO$99,1,$AF$17:$AF$99,"<"&AF18)+(COUNTIFS($BO$17:$BO$99,1,$AF$17:$AF$99,AF18)-1)/2)/(SUM($BO$17:$BO$99)-1),2)),"") | AI18: =IF(ISNUMBER(AG18),IF(ISNUMBER(AH18),ROUND(AG18*'Sheet1-指标体系'!$J$8+AH18*'Sheet1-指标体系'!$J$9,2),AG18),"") -> 29.58 | AJ18: =IF(NOT(ISNUMBER(F18)),"",IF(F18>='Sheet1-指标体系'!$J$16,IF(ISNUMBER(N18),N18,""),IF(ISNUMBER(O18),O18,""))) -> 0.24545794 | AK18: =IF(AND(G18="入池",ISNUMBER(M18),ISNUMBER(AJ18)),IF(M18>=AJ18,'Sheet1-指标体系'!$J$18,IF(AJ18-M18<'Sheet1-指标体系'!$J$10,'Sheet1-指标体系'!$J$22,'Sheet1-指标体系'!$J$23)),"") -> 100 | AL18: =IF((IF(ISNUMBER(I18),'Sheet1-指标体系'!$G$4,0)+IF(ISNUMBER(K18),'Sheet1-指标体系'!$G$5,0)+IF(ISNUMBER(L18),'Sheet1-指标体系'!$G$6,0))>0,ROUND((IF(ISNUMBER(I18),I18*'Sheet1-指标体系'!$G$4,0)+IF(ISNUMBER(K18),K18*'Sheet1-指标体系'!$G$5,0)+IF(ISNUMBER(L18),L18*'Sheet1-指标体系'!$G$6,0))/(IF(ISNUMBER(I18),'Sheet1-指标体系'!$G$4,0)+IF(ISNUMBER(K18),'Sheet1-指标体系'!$G$5,0)+IF(ISNUMBER(L18),'Sheet1-指标体系'!$G$6,0)),2),"") -> 88 | AM18: =IF(SUM(CD18:CG18)>0,ROUND(SUM(BS18:BV18)/SUM(CD18:CG18),2),"") -> 86.57 | AN18: =IF(SUM(CH18:CH18)>0,ROUND(SUM(BW18:BW18)/SUM(CH18:CH18),2),"") -> 4.05 | AO18: =IF(SUM(CI18:CJ18)>0,ROUND(SUM(BX18:BY18)/SUM(CI18:CJ18),2),"") -> 29.58 | AP18: =IF(SUM(CK18:CK18)>0,ROUND(SUM(BZ18:BZ18)/SUM(CK18:CK18),2),"") -> 100 | AQ18: =SUM(CA18:CK18) -> 0.88 | AR18: =IF(SUM(CA18:CK18)>0,SUM(BP18:BZ18),"") -> 46.850488 | AS18: =IF(SUM(CA18:CK18)>0,ROUND(SUM(BP18:BZ18)/SUM(CA18:CK18),2),"") -> 53.24 | AT18: =IF(OR(G18<>"入池",NOT(ISNUMBER(AS18))),"",COUNTIFS($G$17:$G$99,"入池",$AS$17:$AS$99,">"&AS18)+COUNTIFS($G$17:$G$99,"入池",$AS$17:$AS$99,AS18,$AQ$17:$AQ$99,">"&AQ18)+COUNTIFS($G$17:G18,"入池",$AS$17:AS18,AS18,$AQ$17:AQ18,AQ18)) -> 53 | AU18: =IF(NOT(ISNUMBER(I18)),"管理人规模；","")&IF(NOT(ISNUMBER(K18)),"产品规模标识；","")&IF(NOT(ISNUMBER(M18)),"近一年收益；","")&IF(NOT(ISNUMBER(T18)),"近一年胜率；","")&IF(NOT(ISNUMBER(N18)),"近三年收益；","")&IF(NOT(ISNUMBER(U18)),"近三年胜率；","")&IF(NOT(ISNUMBER(AA18)),"近三年回撤；","")&IF(NOT(ISNUMBER(AD18)),"近一年卡玛；","")&IF(ISNUMBER(F18),IF(AND(F18<'Sheet1-指标体系'!$J$16,NOT(ISNUMBER(O18))),"成立以来年化；",""),"成立日期；")&IF(ISNUMBER(V18),IF(OR(V18<0,V18>1),"胜率窗口口径不一致；",""),"")&IF(ISNUMBER(P18),IF(NOT(ISNUMBER(AE18)),"DD_long不可识别；",""),"") -> DD_long不可识别； | AV18: =IF(ABS(SUM(CA18:CK18)-'Sheet1-指标体系'!$J$25)<0.0000000001,SUM(BP18:BZ18),"") | AW18: =IF(G18<>"入池",G18,IF(AQ18=0,"无有效评分数据",IF(ROUND(AQ18,10)=ROUND('Sheet1-指标体系'!$J$25,10),"完整赋分","暂定分／数据不完整"))) -> 暂定分／数据不完整 | AX18: =IF('Sheet4-原始数据'!C3="","",'Sheet4-原始数据'!C3) -> 期货策略 | AY18: =IF('Sheet4-原始数据'!D3="","",'Sheet4-原始数据'!D3) -> 量化期货 | AZ18: =IF('Sheet5-查询核对'!S3="","",'Sheet5-查询核对'!S3) -> 管理期货—量化CTA | BA18: =IF('Sheet5-查询核对'!A3="","",'Sheet5-查询核对'!A3) -> 3 | BB18: =IF('Sheet5-查询核对'!F3="","",'Sheet5-查询核对'!F3) -> 备案号匹配 | BC18: =IF('Sheet5-查询核对'!I3="","",'Sheet5-查询核对'!I3) -> https://mp.fof99.com/fund/view/b03271229e00ba58 | BD18: =IF('Sheet5-查询核对'!H3="","",'Sheet5-查询核对'!H3) -> 46269 | BE18: =IF('Sheet5-查询核对'!L3="","",'Sheet5-查询核对'!L3) -> https://gs.amac.org.cn/amac-infodisc/res/pof/manager/1801301704109241.html | BF18: =IF('Sheet5-查询核对'!M3="","",'Sheet5-查询核对'!M3) -> 46276 | BG18: =IF('Sheet5-查询核对'!O3="","",'Sheet5-查询核对'!O3) -> https://gs.amac.org.cn/amac-infodisc/res/pof/fund/2212071732101603.html | BH18: =IF('Sheet5-查询核对'!P3="","",'Sheet5-查询核对'!P3) -> 46276 | BI18: =IF('Sheet5-查询核对'!D3="","",'Sheet5-查询核对'!D3) -> SXL267 | BJ18: =IF(ISNUMBER(AT18),AT18,COUNT($AT$17:$AT$99)+ROWS($AT$17:AT18)-COUNT($AT$17:AT18)) -> 53 | BK18: =IF(G18="入池",IF(ISNUMBER(M18),1,0),0) -> 1 | BL18: =IF(G18="入池",IF(ISNUMBER(P18),1,0),0) -> 1 | BM18: =IF(G18="入池",IF(ISNUMBER(AB18),1,0),0) -> 1 | BN18: =IF(G18="入池",IF(ISNUMBER(AD18),1,0),0) -> 1 | BO18: =IF(G18="入池",IF(ISNUMBER(AF18),1,0),0) -> 0 | BP18: =IF(G18="入池",IF(ISNUMBER(I18),I18*('Sheet1-指标体系'!$G$4),0),0) -> 4.2 | BQ18: =IF(G18="入池",IF(ISNUMBER(K18),K18*('Sheet1-指标体系'!$G$5),0),0) -> 4.5 | BR18: =IF(G18="入池",IF(ISNUMBER(L18),L18*('Sheet1-指标体系'!$G$6),0),0) -> 4.5 | BS18: =IF(G18="入池",IF(ISNUMBER(Q18),Q18*('Sheet1-指标体系'!$G$7*'Sheet1-指标体系'!$J$8),0),0) -> 8.4 | BT18: =IF(G18="入池",IF(ISNUMBER(R18),R18*('Sheet1-指标体系'!$G$7*'Sheet1-指标体系'!$J$9),0),0) -> 4.92128 | BU18: =IF(G18="入池",IF(ISNUMBER(W18),W18*('Sheet1-指标体系'!$G$8*'Sheet1-指标体系'!$J$8),0),0) -> 2.4923077 | BV18: =IF(G18="入池",IF(ISNUMBER(X18),X18*('Sheet1-指标体系'!$G$8*'Sheet1-指标体系'!$J$9),0),0) -> 1.5 | BW18: =IF(G18="入池",IF(ISNUMBER(AC18),AC18*('Sheet1-指标体系'!$G$9),0),0) -> 1.0125 | BX18: =IF(G18="入池",IF(ISNUMBER(AG18),AG18*('Sheet1-指标体系'!$G$10*'Sheet1-指标体系'!$J$8),0),0) -> 5.3244 | BY18: =IF(G18="入池",IF(ISNUMBER(AH18),AH18*('Sheet1-指标体系'!$G$10*'Sheet1-指标体系'!$J$9),0),0) -> 0 | BZ18: =IF(G18="入池",IF(ISNUMBER(AK18),AK18*('Sheet1-指标体系'!$G$11),0),0) -> 10 | CA18: =IF(G18="入池",IF(ISNUMBER(I18),'Sheet1-指标体系'!$G$4,0),0) -> 0.06 | CB18: =IF(G18="入池",IF(ISNUMBER(K18),'Sheet1-指标体系'!$G$5,0),0) -> 0.045 | CC18: =IF(G18="入池",IF(ISNUMBER(L18),'Sheet1-指标体系'!$G$6,0),0) -> 0.045 | CD18: =IF(G18="入池",IF(ISNUMBER(Q18),'Sheet1-指标体系'!$G$7*'Sheet1-指标体系'!$J$8,0),0) -> 0.084 | CE18: =IF(G18="入池",IF(ISNUMBER(R18),'Sheet1-指标体系'!$G$7*'Sheet1-指标体系'!$J$9,0),0) -> 0.056 | CF18: =IF(G18="入池",IF(ISNUMBER(W18),'Sheet1-指标体系'!$G$8*'Sheet1-指标体系'!$J$8,0),0) -> 0.036 | CG18: =IF(G18="入池",IF(ISNUMBER(X18),'Sheet1-指标体系'!$G$8*'Sheet1-指标体系'!$J$9,0),0) -> 0.024 | CH18: =IF(G18="入池",IF(ISNUMBER(AC18),'Sheet1-指标体系'!$G$9,0),0) -> 0.25 | CI18: =IF(G18="入池",IF(ISNUMBER(AG18),'Sheet1-指标体系'!$G$10*'Sheet1-指标体系'!$J$8,0),0) -> 0.18 | CJ18: =IF(G18="入池",IF(ISNUMBER(AH18),'Sheet1-指标体系'!$G$10*'Sheet1-指标体系'!$J$9,0),0) -> 0 | CK18: =IF(G18="入池",IF(ISNUMBER(AK18),'Sheet1-指标体系'!$G$11,0),0) -> 0.1
A19: ='Sheet5-查询核对'!A4-1 -> 3 | B19: =IF('Sheet4-原始数据'!A4="",'Sheet5-查询核对'!B4,'Sheet4-原始数据'!A4) -> 博牛转债策略2号 | C19: =IF('Sheet4-原始数据'!B4="","",'Sheet4-原始数据'!B4) -> SVY871 | D19: =IF('Sheet4-原始数据'!E4="","",'Sheet4-原始数据'!E4) -> 广州博牛 | E19: =IF('Sheet4-原始数据'!F4="","",'Sheet4-原始数据'!F4) -> 44788 | F19: =IF(ISNUMBER(E19),ROUND(('Sheet1-指标体系'!$J$12-E19)/'Sheet1-指标体系'!$J$14,4),"") -> 4.0712 | G19: =IF(C19="","未匹配",IF(NOT(ISNUMBER(F19)),"缺成立日期",IF(F19<'Sheet1-指标体系'!$J$15,"不入池","入池"))) -> 入池 | H19: =IF('Sheet5-查询核对'!K4="","",'Sheet5-查询核对'!K4) -> 5-10亿元 | I19: =IF(H19="","",IF(COUNTIF('Sheet1-指标体系'!$P$4:$P$10,H19)=0,"",INDEX('Sheet1-指标体系'!$Q$4:$Q$10,MATCH(H19,'Sheet1-指标体系'!$P$4:$P$10,0)))) -> 70 | J19: =IF(NOT(ISNUMBER('Sheet5-查询核对'!N4)),"",IF('Sheet5-查询核对'!N4=1,"低于"&'Sheet1-指标体系'!$J$4&"万元",IF('Sheet5-查询核对'!N4=0,"无低于"&'Sheet1-指标体系'!$J$4&"万元标识",""))) -> 无低于1000万元标识 | K19: =IF(NOT(ISNUMBER('Sheet5-查询核对'!N4)),"",IF('Sheet5-查询核对'!N4=1,'Sheet1-指标体系'!$J$21,IF('Sheet5-查询核对'!N4=0,'Sheet1-指标体系'!$J$18,""))) -> 100 | L19: =IF(NOT(ISNUMBER(F19)),"",IF(F19<'Sheet1-指标体系'!$J$15,"",IF(F19<'Sheet1-指标体系'!$J$16,'Sheet1-指标体系'!$J$17,'Sheet1-指标体系'!$J$18))) -> 100 | M19: =IF(ISNUMBER('Sheet4-原始数据'!G4),'Sheet4-原始数据'!G4,"") -> -0.0148 | N19: =IF(ISNUMBER('Sheet4-原始数据'!H4),'Sheet4-原始数据'!H4,"") -> 0.0427 | O19: =IF(ISNUMBER('Sheet5-查询核对'!Q4),'Sheet5-查询核对'!Q4,"") -> 0.0478 | P19: =IF(G19<>"入池","",IF(F19>='Sheet1-指标体系'!$J$16,IF(AND(ISNUMBER(M19),ISNUMBER(N19)),IF(AND(1+M19>0,1+N19>=0),((1+N19)^'Sheet1-指标体系'!$J$16/(1+M19))^(1/('Sheet1-指标体系'!$J$16-1))-1,""),""),IF(AND(ISNUMBER(M19),ISNUMBER(O19)),IF(AND(F19>1,1+M19>0,1+O19>=0),((1+O19)^F19/(1+M19))^(1/(F19-1))-1,""),""))) -> 0.072696488 | Q19: =IF(BK19=1,IF(SUM($BK$17:$BK$99)<=1,100,ROUND(100*(COUNTIFS($BK$17:$BK$99,1,$M$17:$M$99,"<"&M19)+(COUNTIFS($BK$17:$BK$99,1,$M$17:$M$99,M19)-1)/2)/(SUM($BK$17:$BK$99)-1),2)),"") -> 1.39 | R19: =IF(BL19=1,IF(SUM($BL$17:$BL$99)<=1,100,ROUND(100*(COUNTIFS($BL$17:$BL$99,1,$P$17:$P$99,"<"&P19)+(COUNTIFS($BL$17:$BL$99,1,$P$17:$P$99,P19)-1)/2)/(SUM($BL$17:$BL$99)-1),2)),"") -> 43.94 | S19: =IF(ISNUMBER(Q19),IF(ISNUMBER(R19),ROUND(Q19*'Sheet1-指标体系'!$J$8+R19*'Sheet1-指标体系'!$J$9,2),Q19),"") -> 18.41 | T19: =IF(ISNUMBER('Sheet4-原始数据'!J4),'Sheet4-原始数据'!J4,"") -> 0.3077 | U19: =IF(ISNUMBER('Sheet4-原始数据'!I4),'Sheet4-原始数据'!I4,"") -> 0.5946 | V19: =IF(AND(ISNUMBER(T19),ISNUMBER(U19)),(U19*'Sheet1-指标体系'!$J$6-T19*'Sheet1-指标体系'!$J$5)/'Sheet1-指标体系'!$J$7,"") -> 0.75000417 | W19: =IF(ISNUMBER(T19),100*T19,"") -> 30.77 | X19: =IF(G19<>"入池","",IF(ISNUMBER(V19),IF(AND(V19>=0,V19<=1),V19*'Sheet1-指标体系'!$J$18,IF(MAX(0,(F19-'Sheet1-指标体系'!$J$15)*'Sheet1-指标体系'!$J$20)<'Sheet1-指标体系'!$J$19,'Sheet1-指标体系'!$J$18,"")),IF(MAX(0,(F19-'Sheet1-指标体系'!$J$15)*'Sheet1-指标体系'!$J$20)<'Sheet1-指标体系'!$J$19,'Sheet1-指标体系'!$J$18,""))) -> 75.000417 | Y19: =IF(ISNUMBER(W19),IF(ISNUMBER(X19),ROUND(W19*'Sheet1-指标体系'!$J$8+X19*'Sheet1-指标体系'!$J$9,2),W19),"") -> 48.46 | Z19: =IF(AND(ISNUMBER(M19),ISNUMBER(AD19)),IF(AD19<>0,ABS(M19/AD19),""),"") -> 0.044875682 | AA19: =IF(ISNUMBER('Sheet4-原始数据'!K4),'Sheet4-原始数据'!K4,"") -> 0.045 | AB19: =IF(AND(ISNUMBER(Z19),ISNUMBER(AA19)),MAX(Z19,AA19),IF(ISNUMBER(Z19),Z19,IF(ISNUMBER(AA19),AA19,""))) -> 0.045 | AC19: =IF(BM19=1,IF(SUM($BM$17:$BM$99)<=1,100,ROUND(100*(COUNTIFS($BM$17:$BM$99,1,$AB$17:$AB$99,">"&AB19)+(COUNTIFS($BM$17:$BM$99,1,$AB$17:$AB$99,AB19)-1)/2)/(SUM($BM$17:$BM$99)-1),2)),"") -> 20.27 | AD19: =IF(ISNUMBER('Sheet4-原始数据'!M4),'Sheet4-原始数据'!M4,"") -> -0.3298 | AE19: =IF(AND(ISNUMBER(P19),ISNUMBER(AA19),ISNUMBER(Z19)),IF(AA19>Z19+'Sheet1-指标体系'!$J$11,AA19,""),"") -> 0.045 | AF19: =IF(AND(ISNUMBER(P19),ISNUMBER(AE19)),IF(AE19<>0,P19/AE19,""),"") -> 1.6154775 | AG19: =IF(BN19=1,IF(SUM($BN$17:$BN$99)<=1,100,ROUND(100*(COUNTIFS($BN$17:$BN$99,1,$AD$17:$AD$99,"<"&AD19)+(COUNTIFS($BN$17:$BN$99,1,$AD$17:$AD$99,AD19)-1)/2)/(SUM($BN$17:$BN$99)-1),2)),"") -> 1.41 | AH19: =IF(BO19=1,IF(SUM($BO$17:$BO$99)<=1,100,ROUND(100*(COUNTIFS($BO$17:$BO$99,1,$AF$17:$AF$99,"<"&AF19)+(COUNTIFS($BO$17:$BO$99,1,$AF$17:$AF$99,AF19)-1)/2)/(SUM($BO$17:$BO$99)-1),2)),"") -> 25 | AI19: =IF(ISNUMBER(AG19),IF(ISNUMBER(AH19),ROUND(AG19*'Sheet1-指标体系'!$J$8+AH19*'Sheet1-指标体系'!$J$9,2),AG19),"") -> 10.85 | AJ19: =IF(NOT(ISNUMBER(F19)),"",IF(F19>='Sheet1-指标体系'!$J$16,IF(ISNUMBER(N19),N19,""),IF(ISNUMBER(O19),O19,""))) -> 0.0427 | AK19: =IF(AND(G19="入池",ISNUMBER(M19),ISNUMBER(AJ19)),IF(M19>=AJ19,'Sheet1-指标体系'!$J$18,IF(AJ19-M19<'Sheet1-指标体系'!$J$10,'Sheet1-指标体系'!$J$22,'Sheet1-指标体系'!$J$23)),"") -> 80 | AL19: =IF((IF(ISNUMBER(I19),'Sheet1-指标体系'!$G$4,0)+IF(ISNUMBER(K19),'Sheet1-指标体系'!$G$5,0)+IF(ISNUMBER(L19),'Sheet1-指标体系'!$G$6,0))>0,ROUND((IF(ISNUMBER(I19),I19*'Sheet1-指标体系'!$G$4,0)+IF(ISNUMBER(K19),K19*'Sheet1-指标体系'!$G$5,0)+IF(ISNUMBER(L19),L19*'Sheet1-指标体系'!$G$6,0))/(IF(ISNUMBER(I19),'Sheet1-指标体系'!$G$4,0)+IF(ISNUMBER(K19),'Sheet1-指标体系'!$G$5,0)+IF(ISNUMBER(L19),'Sheet1-指标体系'!$G$6,0)),2),"") -> 88 | AM19: =IF(SUM(CD19:CG19)>0,ROUND(SUM(BS19:BV19)/SUM(CD19:CG19),2),"") -> 27.43 | AN19: =IF(SUM(CH19:CH19)>0,ROUND(SUM(BW19:BW19)/SUM(CH19:CH19),2),"") -> 20.27 | AO19: =IF(SUM(CI19:CJ19)>0,ROUND(SUM(BX19:BY19)/SUM(CI19:CJ19),2),"") -> 10.85 | AP19: =IF(SUM(CK19:CK19)>0,ROUND(SUM(BZ19:BZ19)/SUM(CK19:CK19),2),"") -> 80 | AQ19: =SUM(CA19:CK19) -> 1 | AR19: =IF(SUM(CA19:CK19)>0,SUM(BP19:BZ19),"") -> 35.00643 | AS19: =IF(SUM(CA19:CK19)>0,ROUND(SUM(BP19:BZ19)/SUM(CA19:CK19),2),"") -> 35.01 | AT19: =IF(OR(G19<>"入池",NOT(ISNUMBER(AS19))),"",COUNTIFS($G$17:$G$99,"入池",$AS$17:$AS$99,">"&AS19)+COUNTIFS($G$17:$G$99,"入池",$AS$17:$AS$99,AS19,$AQ$17:$AQ$99,">"&AQ19)+COUNTIFS($G$17:G19,"入池",$AS$17:AS19,AS19,$AQ$17:AQ19,AQ19)) -> 74 | AU19: =IF(NOT(ISNUMBER(I19)),"管理人规模；","")&IF(NOT(ISNUMBER(K19)),"产品规模标识；","")&IF(NOT(ISNUMBER(M19)),"近一年收益；","")&IF(NOT(ISNUMBER(T19)),"近一年胜率；","")&IF(NOT(ISNUMBER(N19)),"近三年收益；","")&IF(NOT(ISNUMBER(U19)),"近三年胜率；","")&IF(NOT(ISNUMBER(AA19)),"近三年回撤；","")&IF(NOT(ISNUMBER(AD19)),"近一年卡玛；","")&IF(ISNUMBER(F19),IF(AND(F19<'Sheet1-指标体系'!$J$16,NOT(ISNUMBER(O19))),"成立以来年化；",""),"成立日期；")&IF(ISNUMBER(V19),IF(OR(V19<0,V19>1),"胜率窗口口径不一致；",""),"")&IF(ISNUMBER(P19),IF(NOT(ISNUMBER(AE19)),"DD_long不可识别；",""),"") | AV19: =IF(ABS(SUM(CA19:CK19)-'Sheet1-指标体系'!$J$25)<0.0000000001,SUM(BP19:BZ19),"") -> 35.00643 | AW19: =IF(G19<>"入池",G19,IF(AQ19=0,"无有效评分数据",IF(ROUND(AQ19,10)=ROUND('Sheet1-指标体系'!$J$25,10),"完整赋分","暂定分／数据不完整"))) -> 完整赋分 | AX19: =IF('Sheet4-原始数据'!C4="","",'Sheet4-原始数据'!C4) -> 套利策略 | AY19: =IF('Sheet4-原始数据'!D4="","",'Sheet4-原始数据'!D4) -> 可转债套利 | AZ19: =IF('Sheet5-查询核对'!S4="","",'Sheet5-查询核对'!S4) -> 套利策略—可转债套利 | BA19: =IF('Sheet5-查询核对'!A4="","",'Sheet5-查询核对'!A4) -> 4 | BB19: =IF('Sheet5-查询核对'!F4="","",'Sheet5-查询核对'!F4) -> 备案号匹配 | BC19: =IF('Sheet5-查询核对'!I4="","",'Sheet5-查询核对'!I4) -> https://mp.fof99.com/fund/view/9b20523c2bad1cdc | BD19: =IF('Sheet5-查询核对'!H4="","",'Sheet5-查询核对'!H4) -> 46269 | BE19: =IF('Sheet5-查询核对'!L4="","",'Sheet5-查询核对'!L4) -> https://gs.amac.org.cn/amac-infodisc/res/pof/manager/1801020956105866.html | BF19: =IF('Sheet5-查询核对'!M4="","",'Sheet5-查询核对'!M4) -> 46276 | BG19: =IF('Sheet5-查询核对'!O4="","",'Sheet5-查询核对'!O4) -> https://gs.amac.org.cn/amac-infodisc/res/pof/fund/2208121907108282.html | BH19: =IF('Sheet5-查询核对'!P4="","",'Sheet5-查询核对'!P4) -> 46276 | BI19: =IF('Sheet5-查询核对'!D4="","",'Sheet5-查询核对'!D4) -> SVY871 | BJ19: =IF(ISNUMBER(AT19),AT19,COUNT($AT$17:$AT$99)+ROWS($AT$17:AT19)-COUNT($AT$17:AT19)) -> 74 | BK19: =IF(G19="入池",IF(ISNUMBER(M19),1,0),0) -> 1 | BL19: =IF(G19="入池",IF(ISNUMBER(P19),1,0),0) -> 1 | BM19: =IF(G19="入池",IF(ISNUMBER(AB19),1,0),0) -> 1 | BN19: =IF(G19="入池",IF(ISNUMBER(AD19),1,0),0) -> 1 | BO19: =IF(G19="入池",IF(ISNUMBER(AF19),1,0),0) -> 1 | BP19: =IF(G19="入池",IF(ISNUMBER(I19),I19*('Sheet1-指标体系'!$G$4),0),0) -> 4.2 | BQ19: =IF(G19="入池",IF(ISNUMBER(K19),K19*('Sheet1-指标体系'!$G$5),0),0) -> 4.5 | BR19: =IF(G19="入池",IF(ISNUMBER(L19),L19*('Sheet1-指标体系'!$G$6),0),0) -> 4.5 | BS19: =IF(G19="入池",IF(ISNUMBER(Q19),Q19*('Sheet1-指标体系'!$G$7*'Sheet1-指标体系'!$J$8),0),0) -> 0.11676 | BT19: =IF(G19="入池",IF(ISNUMBER(R19),R19*('Sheet1-指标体系'!$G$7*'Sheet1-指标体系'!$J$9),0),0) -> 2.46064 | BU19: =IF(G19="入池",IF(ISNUMBER(W19),W19*('Sheet1-指标体系'!$G$8*'Sheet1-指标体系'!$J$8),0),0) -> 1.10772 | BV19: =IF(G19="入池",IF(ISNUMBER(X19),X19*('Sheet1-指标体系'!$G$8*'Sheet1-指标体系'!$J$9),0),0) -> 1.80001 | BW19: =IF(G19="入池",IF(ISNUMBER(AC19),AC19*('Sheet1-指标体系'!$G$9),0),0) -> 5.0675 | BX19: =IF(G19="入池",IF(ISNUMBER(AG19),AG19*('Sheet1-指标体系'!$G$10*'Sheet1-指标体系'!$J$8),0),0) -> 0.2538 | BY19: =IF(G19="入池",IF(ISNUMBER(AH19),AH19*('Sheet1-指标体系'!$G$10*'Sheet1-指标体系'!$J$9),0),0) -> 3 | BZ19: =IF(G19="入池",IF(ISNUMBER(AK19),AK19*('Sheet1-指标体系'!$G$11),0),0) -> 8 | CA19: =IF(G19="入池",IF(ISNUMBER(I19),'Sheet1-指标体系'!$G$4,0),0) -> 0.06 | CB19: =IF(G19="入池",IF(ISNUMBER(K19),'Sheet1-指标体系'!$G$5,0),0) -> 0.045 | CC19: =IF(G19="入池",IF(ISNUMBER(L19),'Sheet1-指标体系'!$G$6,0),0) -> 0.045 | CD19: =IF(G19="入池",IF(ISNUMBER(Q19),'Sheet1-指标体系'!$G$7*'Sheet1-指标体系'!$J$8,0),0) -> 0.084 | CE19: =IF(G19="入池",IF(ISNUMBER(R19),'Sheet1-指标体系'!$G$7*'Sheet1-指标体系'!$J$9,0),0) -> 0.056 | CF19: =IF(G19="入池",IF(ISNUMBER(W19),'Sheet1-指标体系'!$G$8*'Sheet1-指标体系'!$J$8,0),0) -> 0.036 | CG19: =IF(G19="入池",IF(ISNUMBER(X19),'Sheet1-指标体系'!$G$8*'Sheet1-指标体系'!$J$9,0),0) -> 0.024 | CH19: =IF(G19="入池",IF(ISNUMBER(AC19),'Sheet1-指标体系'!$G$9,0),0) -> 0.25 | CI19: =IF(G19="入池",IF(ISNUMBER(AG19),'Sheet1-指标体系'!$G$10*'Sheet1-指标体系'!$J$8,0),0) -> 0.18 | CJ19: =IF(G19="入池",IF(ISNUMBER(AH19),'Sheet1-指标体系'!$G$10*'Sheet1-指标体系'!$J$9,0),0) -> 0.12 | CK19: =IF(G19="入池",IF(ISNUMBER(AK19),'Sheet1-指标体系'!$G$11,0),0) -> 0.1
