Workbook

Sheet sheet1-指标体系
A1: 二、优化后的完整赋分汇总表（字段一一对应）
A3: 大类指标 | B3: 权重 | C3: 二级指标 | D3: 二级权重 | E3: 数据来源/计算方法（重要） | F3: 时间口径权重 | G3: 综合权重 | I3: 计算参数 | J3: 值
A4: 管理人及产品 （不变） | B4: 0.15 | C4: 管理人规模 | D4: 0.4 | E4: 基金业协会管理人公示“管理规模区间”：0-5亿=60；5-10亿=70；10-20亿=80；20-100亿=90；100亿以上=100 | F4: 最新时点 | G4: =B4*D4 | I4: 产品规模标识阈值（万元） | J4: 1000
C5: 产品规模 | D5: 0.3 | E5: 基金业协会产品公示出现“存续规模低于1000万人民币”标识=0；未出现该标识=100 | F5: 最新时点 | G5: =$B$4*D5 | I5: 近一年胜率观察数 | J5: 13
C6: 成立年限 | D6: 0.3 | E6: 按产品成立日期计算：≥3年=100分；1~3年=70分；<1年不入池 | F6: 当前日期 | G6: =$B$4*D6 | I6: 近三年胜率观察数 | J6: 37
A7: 收益能力 （彻底消除重叠） | B7: 0.2 | C7: 年化收益 | D7: 0.7 | E7: 短期：直接用 R_1y 排名赋分 长期：用计算出的 R_early 排名赋分 | F7: 短期60%（近12月） 长期40%（早期区间） | G7: =B7*D7 | I7: 早期胜率观察数 | J7: =J6-J5
C8: 月度胜率 | D8: 0.3 | E8: 近12月胜率（60%）+早期历史胜率（40%） 若早期不足6个月，早期子项直接给满分 | F8: 同上 | G8: =$B$7*D8 | I8: 短期时间权重 | J8: 0.6
A9: 风险控制 （简化，不拆分） | B9: 0.25 | C9: 最大回撤 | D9: 1 | E9: 直接用 MAX(DD_1y, DD_3y) 作为统一风险敞口 | F9: 覆盖近3年（含近期） | G9: =B9*D9 | I9: 长期时间权重 | J9: 0.4
A10: 风险调整收益 （核心指标） | B10: 0.3 | C10: 卡玛比率 | D10: 1 | E10: 短期卡玛=R_1y/DD_1y（60%） 长期卡玛=R_early/DD_long（40%） | F10: 短期60% 长期40% | G10: =B10*D10 | I10: 趋势差距阈值 | J10: 0.2
A11: 业绩一致性/趋势 （新增，替代原有重复项） | B11: 0.1 | C11: 收益趋势 | D11: 1 | E11: 比较 R_1y 与 R_3y：近期不低于长期=100分；差距<20个百分点=80分；否则=60分。成立不足3年改用 R_incep。 | F11: — | G11: =B11*D11 | I11: DD识别容差 | J11: 0.0001
A14: 计算实现说明
A15: 1 | B15: 协会公示抓取日期为2026-09-07。管理人规模来源为基金业协会私募基金管理人公示，产品规模标识来源为基金业协会私募基金公示。
A16: 2 | B16: R_early：满3年时=((1+R_3y)^3/(1+R_1y))^(1/2)-1；不足3年且补录R_incep时，按存续期剔除最近1年后年化。
A17: 3 | B17: 早期月胜率按源数据精度默认使用37期总观察、13期近期观察，早期为24期；参数可在右侧修改。
A18: 4 | B18: DD_1y由ABS(R_1y/近一年卡玛)反推。仅当DD_3y明显大于DD_1y时，才能识别早期DD_long；其余记录留空。
A19: 5 | B19: 管理人规模按公示区间分档赋分；20-50亿元和50-100亿元均归入20-100亿元档，赋90分。
A20: 6 | B20: 产品成立年限由原始数据中的产品成立日期计算。未匹配到协会产品页或管理人页的规模项留空，缺失数据不按0分处理。
A23: 评分范围与数据口径 | B23: 本模板Sheet2的314只产品；按备案号匹配第二表；压缩包按各文件最新净值截至2026-09-11补算。第二表未提供统一业绩截止日。
A24: 协会信息 | B24: 管理规模、处罚/警示按协会公示核验；5亿元边界按公示区间分组。

Sheet sheet2-计算明细
A1: 私募基金指标计算明细
A2: H/J/AV:BD为基金业协会公示补录和追溯字段；O为待补录输入；绿字为原始数据或外部公示链接；黑字为计算。缺失项不按0分，综合分按有效权重归一。
A4: 大类指标 | B4: 大类权重 | C4: 二级指标 | D4: 二级权重 | E4: 综合权重 | F4: 计算
A5: ='sheet1-指标体系'!A4 | B5: ='sheet1-指标体系'!B4 | C5: ='sheet1-指标体系'!C4 | D5: ='sheet1-指标体系'!D4 | E5: =B5*D5 | F5: 大类权重×二级权重
A6: ='sheet1-指标体系'!A4 | B6: ='sheet1-指标体系'!B4 | C6: ='sheet1-指标体系'!C5 | D6: ='sheet1-指标体系'!D5 | E6: =B6*D6 | F6: 大类权重×二级权重
A7: ='sheet1-指标体系'!A4 | B7: ='sheet1-指标体系'!B4 | C7: ='sheet1-指标体系'!C6 | D7: ='sheet1-指标体系'!D6 | E7: =B7*D7 | F7: 大类权重×二级权重
A8: ='sheet1-指标体系'!A7 | B8: ='sheet1-指标体系'!B7 | C8: ='sheet1-指标体系'!C7 | D8: ='sheet1-指标体系'!D7 | E8: =B8*D8 | F8: 大类权重×二级权重
A9: ='sheet1-指标体系'!A7 | B9: ='sheet1-指标体系'!B7 | C9: ='sheet1-指标体系'!C8 | D9: ='sheet1-指标体系'!D8 | E9: =B9*D9 | F9: 大类权重×二级权重
A10: ='sheet1-指标体系'!A9 | B10: ='sheet1-指标体系'!B9 | C10: ='sheet1-指标体系'!C9 | D10: ='sheet1-指标体系'!D9 | E10: =B10*D10 | F10: 大类权重×二级权重
A11: ='sheet1-指标体系'!A10 | B11: ='sheet1-指标体系'!B10 | C11: ='sheet1-指标体系'!C10 | D11: ='sheet1-指标体系'!D10 | E11: =B11*D11 | F11: 大类权重×二级权重
A12: ='sheet1-指标体系'!A11 | B12: ='sheet1-指标体系'!B11 | C12: ='sheet1-指标体系'!C11 | D12: ='sheet1-指标体系'!D11 | E12: =B12*D12 | F12: 大类权重×二级权重
C13: 综合权重合计 | E13: =SUM(E5:E12)
A15: 基础信息 | H15: 管理人及产品 | M15: 年化收益 | T15: 月度胜率 | Z15: 最大回撤 | AD15: 卡玛比率 | AJ15: 收益趋势 | AL15: 大类辅助、总分与排序 | AV15: 基金业协会公示追溯
A16: 序号 | B16: 产品名称 | C16: 备案号 | D16: 管理人 | E16: 产品成立日期 | F16: 产品成立年限（年） | G16: 入池状态 | H16: 管理规模区间（亿元，协会） | I16: 管理人规模分 | J16: 产品规模公示标识 | K16: 产品规模分 | L16: 成立年限分 | M16: R_1y | N16: R_3y | O16: R_incep（补录） | P16: R_early | Q16: R_1y排名分 | R16: R_early排名分 | S16: 年化收益分（可用折算） | T16: 近1年月胜率 | U16: 近3年月胜率 | V16: 早期月胜率 | W16: 近1年月胜率分 | X16: 早期月胜率分 | Y16: 月度胜率分（可用折算） | Z16: DD_1y | AA16: DD_3y | AB16: 统一最大回撤 | AC16: 最大回撤分 | AD16: 短期卡玛 | AE16: 可识别DD_long | AF16: 长期卡玛 | AG16: 短期卡玛分 | AH16: 长期卡玛分 | AI16: 卡玛比率分（可用折算） | AJ16: 趋势比较基准 | AK16: 收益趋势分 | AL16: 管理人及产品大类分 | AM16: 收益能力大类分 | AN16: 风险控制大类分 | AO16: 风险调整收益大类分 | AP16: 趋势大类分 | AQ16: 有效二级权重 | AR16: 加权总分（不补缺） | AS16: 可比总分（归一） | AT16: 唯一排名 | AU16: 数据缺口 | AV16: 管理规模下限（亿元） | AW16: 协会管理人全称 | AX16: 管理人信息更新时间 | AY16: 管理人公示URL | AZ16: 协会产品名称 | BA16: 基金信息更新时间 | BB16: 产品标识季度 | BC16: 基金公示URL | BD16: AMAC匹配状态
A17: 1 | B17: 新视野智能量化2号 | C17: ='sheet4-原始数据'!B2 | D17: 杭州探融投资 | E17: 2017-01-09 | F17: 9.681 | G17: =IF(F17="","",IF(F17<1,"不入池","入池")) | H17: 0-5亿元 | I17: 60 | J17: 无低于1000万元标识 | K17: 100 | L17: 100 | M17: -0.0204 | N17: 0.0205 | P17: 0.04158598 | Q17: 11.11 | R17: 29.5 | S17: 18.47 | T17: 0.3846 | U17: 0.5405 | V17: 0.62494583 | W17: 38.46 | X17: 62.494583 | Y17: 48.07 | Z17: 0.055284553 | AA17: 0.0554 | AB17: 0.0554 | AC17: 41.11 | AD17: -0.369 | AE17: 0.0554 | AF17: 0.75064945 | AG17: 9.09 | AH17: 30.15 | AI17: 17.51 | AJ17: 0.0205 | AK17: 80 | AL17: 84 | AM17: 27.35 | AN17: 41.11 | AO17: 17.51 | AP17: 80 | AQ17: 1 | AR17: 41.60137 | AS17: 41.6 | AT17: 256 | AU17: =IF(I17="","管理人规模；","")&IF(J17="","产品规模标识；","")&IF(AND(F17<3,O17=""),"R_incep；","")&IF(N17="","近三年收益；","")&IF(U17="","近三年胜率；","")&IF(AND(V17<>"",OR(V17<0,V17>1)),"胜率窗口口径不一致；","")&IF(AA17="","近三年回撤；","")&IF(AD17="","短期卡玛；","")&IF(AND(P17<>"",AE17=""),"DD_long不可识别；","") | AV17: 41.60137 | AW17: 0-5亿元 | AX17: 2025-05-22 | AY17: 杭州探融投资管理有限公司 | AZ17: 2025-05-22 | BA17: https://gs.amac.org.cn/amac-infodisc/res/pof/manager/101000049159.html | BB17: 新视野智能量化私募基金2号 | BC17: 2026-05-12 | BD17: 已匹配 | BE17: https://gs.amac.org.cn/amac-infodisc/res/pof/fund/351000611236.html | BF17: 已核验
A18: 2 | B18: 探融新视野智能量化1号 | C18: ='sheet4-原始数据'!B3 | D18: 杭州探融投资 | E18: 2016-09-22 | F18: 9.9795 | G18: =IF(F18="","",IF(F18<1,"不入池","入池")) | H18: 0-5亿元 | I18: 60 | J18: 无低于1000万元标识 | K18: 100 | L18: 100 | M18: -0.0048 | N18: 0.0123 | P18: 0.020959869 | Q18: 15.28 | R18: 10 | S18: 13.17 | T18: 0.3846 | U18: 0.5676 | V18: 0.666725 | W18: 38.46 | X18: 66.6725 | Y18: 49.75 | Z18: 0.025263158 | AA18: 0.0251 | AB18: 0.025263158 | AC18: 66.2 | AD18: -0.19 | AG18: 11.89 | AI18: 11.89 | AJ18: 0.0123 | AK18: 80 | AL18: 84 | AM18: 24.14 | AN18: 66.2 | AO18: 11.89 | AP18: 80 | AQ18: 0.88 | AR18: 44.11842 | AS18: 50.13 | AT18: 222 | AU18: =IF(I18="","管理人规模；","")&IF(J18="","产品规模标识；","")&IF(AND(F18<3,O18=""),"R_incep；","")&IF(N18="","近三年收益；","")&IF(U18="","近三年胜率；","")&IF(AND(V18<>"",OR(V18<0,V18>1)),"胜率窗口口径不一致；","")&IF(AA18="","近三年回撤；","")&IF(AD18="","短期卡玛；","")&IF(AND(P18<>"",AE18=""),"DD_long不可识别；","") | AW18: 0-5亿元 | AX18: 2025-05-22 | AY18: 杭州探融投资管理有限公司 | AZ18: 2025-05-22 | BA18: https://gs.amac.org.cn/amac-infodisc/res/pof/manager/101000049159.html | BB18: 探融新视野智能量化私募证券投资基金1号 | BC18: 2026-05-25 | BD18: 已匹配 | BE18: https://gs.amac.org.cn/amac-infodisc/res/pof/fund/351000500099.html | BF18: 已核验
A19: 3 | B19: 辉毅4号 | C19: ='sheet4-原始数据'!B4 | D19: 上海申毅投资 | E19: 2016-09-14 | F19: 10.0014 | G19: =IF(F19="","",IF(F19<1,"不入池","入池")) | H19: 100亿元以上 | I19: 100 | J19: 无低于1000万元标识 | K19: 100 | L19: 100 | M19: -0.0025 | N19: 0.0488 | P19: 0.075431036 | Q19: 16.49 | R19: 61 | S19: 34.29 | T19: 0.4615 | U19: 0.7568 | V19: 0.91675417 | W19: 46.15 | X19: 91.675417 | Y19: 64.36 | Z19: 0.024366472 | AA19: 0.0246 | AB19: 0.0246 | AC19: 68.12 | AD19: -0.1026 | AE19: 0.0246 | AF19: 3.0663023 | AG19: 14.69 | AH19: 76.47 | AI19: 39.4 | AJ19: 0.0488 | AK19: 80 | AL19: 100 | AM19: 43.31 | AN19: 68.12 | AO19: 39.4 | AP19: 80 | AQ19: 1 | AR19: 60.51337 | AS19: 60.51 | AT19: 165 | AU19: =IF(I19="","管理人规模；","")&IF(J19="","产品规模标识；","")&IF(AND(F19<3,O19=""),"R_incep；","")&IF(N19="","近三年收益；","")&IF(U19="","近三年胜率；","")&IF(AND(V19<>"",OR(V19<0,V19>1)),"胜率窗口口径不一致；","")&IF(AA19="","近三年回撤；","")&IF(AD19="","短期卡玛；","")&IF(AND(P19<>"",AE19=""),"DD_long不可识别；","") | AV19: 60.51337 | AW19: 100亿元以上 | AX19: 2026-04-28 | AY19: 上海申毅投资股份有限公司 | AZ19: 2026-04-28 | BA19: https://gs.amac.org.cn/amac-infodisc/res/pof/manager/101000000870.html | BB19: 辉毅4号 | BC19: 2025-04-02 | BD19: 已匹配 | BE19: https://gs.amac.org.cn/amac-infodisc/res/pof/fund/351000509057.html | BF19: 已核验
A20: 4 | B20: 平凡悟鑫 | C20: ='sheet4-原始数据'!B5 | D20: 北京平凡 | E20: 2016-04-19 | F20: 10.4066 | G20: =IF(F20="","",IF(F20<1,"不入池","入池")) | H20: 50-100亿元 | I20: 90 | J20: 无低于1000万元标识 | K20: 100 | L20: 100 | M20: 0.0607 | N20: 0.0649 | P20: 0.067006232 | Q20: 51.39 | R20: 54 | S20: 52.43 | T20: 0.9231 | U20: 0.8919 | V20: 0.875 | W20: 92.31 | X20: 87.5 | Y20: 90.39 | Z20: 0.0097124662 | AA20: 0.0097 | AB20: 0.0097124662 | AC20: 86.06 | AD20: 6.2497 | AG20: 71.33 | AI20: 71.33 | AJ20: 0.0649 | AK20: 80 | AL20: 96 | AM20: 63.82 | AN20: 86.06 | AO20: 71.33 | AP20: 80 | AQ20: 0.88 | AR20: 69.51832 | AS20: 79 | AT20: 69 | AU20: =IF(I20="","管理人规模；","")&IF(J20="","产品规模标识；","")&IF(AND(F20<3,O20=""),"R_incep；","")&IF(N20="","近三年收益；","")&IF(U20="","近三年胜率；","")&IF(AND(V20<>"",OR(V20<0,V20>1)),"胜率窗口口径不一致；","")&IF(AA20="","近三年回撤；","")&IF(AD20="","短期卡玛；","")&IF(AND(P20<>"",AE20=""),"DD_long不可识别；","") | AW20: 50-100亿元 | AX20: 2026-08-05 | AY20: 北京平凡私募基金管理有限公司 | AZ20: 2026-08-05 | BA20: https://gs.amac.org.cn/amac-infodisc/res/pof/manager/101000030286.html | BB20: 平凡悟鑫证券投资基金 | BC20: 2026-05-27 | BD20: 已匹配 | BE20: https://gs.amac.org.cn/amac-infodisc/res/pof/fund/351000410825.html | BF20: 已核验
A21: 5 | B21: 致同稳盈对冲 | C21: ='sheet4-原始数据'!B6 | D21: 上海致同投资 | E21: 2017-05-02 | F21: 9.3717 | G21: =IF(F21="","",IF(F21<1,"不入池","入池")) | H21: 20-50亿元 | I21: 90 | J21: 无低于1000万元标识 | K21: 100 | L21: 100 | M21: 0.0405 | N21: 0.0489 | P21: 0.053125396 | Q21: 39.93 | R21: 39.5 | S21: 39.76 | T21: 0.7692 | U21: 0.7838 | V21: 0.79170833 | W21: 76.92 | X21: 79.170833 | Y21: 77.82 | Z21: 0.013372515 | AA21: 0.0134 | AB21: 0.0134 | AC21: 80.49 | AD21: 3.0286 | AG21: 54.9 | AI21: 54.9 | AJ21: 0.0489 | AK21: 80 | AL21: 96 | AM21: 51.18 | AN21: 80.49 | AO21: 54.9 | AP21: 80 | AQ21: 0.88 | AR21: 62.63984 | AS21: 71.18 | AT21: 110 | AU21: =IF(I21="","管理人规模；","")&IF(J21="","产品规模标识；","")&IF(AND(F21<3,O21=""),"R_incep；","")&IF(N21="","近三年收益；","")&IF(U21="","近三年胜率；","")&IF(AND(V21<>"",OR(V21<0,V21>1)),"胜率窗口口径不一致；","")&IF(AA21="","近三年回撤；","")&IF(AD21="","短期卡玛；","")&IF(AND(P21<>"",AE21=""),"DD_long不可识别；","") | AW21: 20-50亿元 | AX21: 2026-03-16 | AY21: 上海致同投资管理有限公司 | AZ21: 2026-03-16 | BA21: https://gs.amac.org.cn/amac-infodisc/res/pof/manager/101000004339.html | BB21: 致同稳盈对冲私募基金 | BC21: 2026-07-06 | BD21: 已匹配 | BE21: https://gs.amac.org.cn/amac-infodisc/res/pof/fund/1705051025108658.html | BF21: 已核验
A22: 6 | B22: 哈福尊享一号 | C22: ='sheet4-原始数据'!B7 | D22: 哈福基金 | E22: 2017-05-10 | F22: 9.3498 | G22: =IF(F22="","",IF(F22<1,"不入池","入池")) | H22: 0-5亿元 | I22: 60 | J22: 无低于1000万元标识 | K22: 100 | L22: 100 | M22: 0.0289 | N22: 0.0225 | P22: 0.019314944 | Q22: 29.51 | R22: 9 | S22: 21.31 | T22: 0.6923 | U22: 0.7297 | V22: 0.74995833 | W22: 69.23 | X22: 74.995833 | Y22: 71.54 | Z22: 0.028402948 | AA22: 0.0658 | AB22: 0.0658 | AC22: 36.93 | AD22: 1.0175 | AE22: 0.0658 | AF22: 0.29354018 | AG22: 34.62 | AH22: 13.24 | AI22: 26.07 | AJ22: 0.0225 | AK22: 100 | AL22: 84 | AM22: 36.38 | AN22: 36.93 | AO22: 26.07 | AP22: 100 | AQ22: 1 | AR22: 46.92792 | AS22: 46.93 | AT22: 236 | AU22: =IF(I22="","管理人规模；","")&IF(J22="","产品规模标识；","")&IF(AND(F22<3,O22=""),"R_incep；","")&IF(N22="","近三年收益；","")&IF(U22="","近三年胜率；","")&IF(AND(V22<>"",OR(V22<0,V22>1)),"胜率窗口口径不一致；","")&IF(AA22="","近三年回撤；","")&IF(AD22="","短期卡玛；","")&IF(AND(P22<>"",AE22=""),"DD_long不可识别；","") | AV22: 46.92792 | AW22: 0-5亿元 | AX22: 2026-06-05 | AY22: 广东哈福私募证券投资基金管理有限公司 | AZ22: 2026-06-05 | BA22: https://gs.amac.org.cn/amac-infodisc/res/pof/manager/101000010078.html | BB22: 哈福尊享一号私募证券投资基金 | BC22: 2024-10-29 | BD22: 已匹配 | BE22: https://gs.amac.org.cn/amac-infodisc/res/pof/fund/1705180919103330.html | BF22: 已核验
A23: 7 | B23: 远澜翠柏1号 | C23: ='sheet4-原始数据'!B8 | D23: 上海远澜 | E23: 2017-05-12 | F23: 9.3443 | G23: =IF(F23="","",IF(F23<1,"不入池","入池")) | H23: 100亿元以上 | I23: 100 | J23: 无低于1000万元标识 | K23: 100 | L23: 100 | M23: 0.0546 | N23: 0.0457 | P23: 0.041278206 | Q23: 47.22 | R23: 29 | S23: 39.93 | T23: 0.4615 | U23: 0.5135 | V23: 0.54166667 | W23: 46.15 | X23: 54.166667 | Y23: 49.36 | Z23: 0.15388952 | AA23: 0.154 | AB23: 0.154 | AC23: 15.33 | AD23: 0.3548 | AE23: 0.154 | AF23: 0.2680403 | AG23: 22.73 | AH23: 12.5 | AI23: 18.64 | AJ23: 0.0457 | AK23: 100 | AL23: 100 | AM23: 42.76 | AN23: 15.33 | AO23: 18.64 | AP23: 100 | AQ23: 1 | AR23: 42.97578 | AS23: 42.98 | AT23: 253 | AU23: =IF(I23="","管理人规模；","")&IF(J23="","产品规模标识；","")&IF(AND(F23<3,O23=""),"R_incep；","")&IF(N23="","近三年收益；","")&IF(U23="","近三年胜率；","")&IF(AND(V23<>"",OR(V23<0,V23>1)),"胜率窗口口径不一致；","")&IF(AA23="","近三年回撤；","")&IF(AD23="","短期卡玛；","")&IF(AND(P23<>"",AE23=""),"DD_long不可识别；","") | AV23: 42.97578 | AW23: 100亿元以上 | AX23: 2026-05-08 | AY23: 上海远澜私募基金管理有限公司 | AZ23: 2026-05-08 | BA23: https://gs.amac.org.cn/amac-infodisc/res/pof/manager/101000022626.html | BB23: 远澜翠柏1号私募证券投资基金 | BC23: 2024-11-07 | BD23: 已匹配 | BE23: https://gs.amac.org.cn/amac-infodisc/res/pof/fund/1706161700107643.html | BF23: 已核验
A24: 8 | B24: 擎丰1号 | C24: ='sheet4-原始数据'!B9 | D24: 上海擎丰 | E24: 2018-06-06 | F24: 8.2765 | G24: =IF(F24="","",IF(F24<1,"不入池","入池")) | H24: 0-5亿元 | I24: 60 | J24: 无低于1000万元标识 | K24: 100 | L24: 100 | M24: 0.0786 | N24: 0.0506 | P24: 0.036873767 | Q24: 64.93 | R24: 22.5 | S24: 47.96 | T24: 0.9231 | U24: 0.8378 | V24: 0.79159583 | W24: 92.31 | X24: 79.159583 | Y24: 87.05 | Z24: 0.0069003055 | AA24: 0.0069 | AB24: 0.0069003055 | AC24: 89.9 | AD24: 11.3908 | AG24: 84.27 | AI24: 84.27 | AJ24: 0.0506 | AK24: 100 | AL24: 84 | AM24: 59.69 | AN24: 89.9 | AO24: 84.27 | AP24: 100 | AQ24: 0.88 | AR24: 72.18071 | AS24: 82.02 | AT24: 51 | AU24: =IF(I24="","管理人规模；","")&IF(J24="","产品规模标识；","")&IF(AND(F24<3,O24=""),"R_incep；","")&IF(N24="","近三年收益；","")&IF(U24="","近三年胜率；","")&IF(AND(V24<>"",OR(V24<0,V24>1)),"胜率窗口口径不一致；","")&IF(AA24="","近三年回撤；","")&IF(AD24="","短期卡玛；","")&IF(AND(P24<>"",AE24=""),"DD_long不可识别；","") | AW24: 0-5亿元 | AX24: 2026-08-06 | AY24: 上海擎丰私募基金管理有限公司 | AZ24: 2026-08-06 | BA24: https://gs.amac.org.cn/amac-infodisc/res/pof/manager/1707071820104466.html | BB24: 擎丰1号私募投资基金 | BC24: 2023-01-16 | BD24: 已匹配 | BE24: https://gs.amac.org.cn/amac-infodisc/res/pof/fund/1806141444102951.html | BF24: 已核验
A25: 9 | B25: 新时代智能量化3号 | C25: ='sheet4-原始数据'!B10 | D25: 杭州探融投资 | E25: 2018-10-29 | F25: 7.8795 | G25: =IF(F25="","",IF(F25<1,"不入池","入池")) | H25: 0-5亿元 | I25: 60 | J25: 无低于1000万元标识 | K25: 100 | L25: 100 | M25: 0.012 | N25: 0.0312 | P25: 0.040936172 | Q25: 21.53 | R25: 28.5 | S25: 24.32 | T25: 0.4615 | U25: 0.5676 | V25: 0.62507083 | W25: 46.15 | X25: 62.507083 | Y25: 52.69 | Z25: 0.032994226 | AA25: 0.033 | AB25: 0.033 | AC25: 56.79 | AD25: 0.3637 | AG25: 23.43 | AI25: 23.43 | AJ25: 0.0312 | AK25: 80 | AL25: 84 | AM25: 32.83 | AN25: 56.79 | AO25: 23.43 | AP25: 80 | AQ25: 0.88 | AR25: 45.58099 | AS25: 51.8 | AT25: 212 | AU25: =IF(I25="","管理人规模；","")&IF(J25="","产品规模标识；","")&IF(AND(F25<3,O25=""),"R_incep；","")&IF(N25="","近三年收益；","")&IF(U25="","近三年胜率；","")&IF(AND(V25<>"",OR(V25<0,V25>1)),"胜率窗口口径不一致；","")&IF(AA25="","近三年回撤；","")&IF(AD25="","短期卡玛；","")&IF(AND(P25<>"",AE25=""),"DD_long不可识别；","") | AW25: 0-5亿元 | AX25: 2025-05-22 | AY25: 杭州探融投资管理有限公司 | AZ25: 2025-05-22 | BA25: https://gs.amac.org.cn/amac-infodisc/res/pof/manager/101000049159.html | BB25: 新时代智能量化3号私募投资基金 | BC25: 2026-05-12 | BD25: 已匹配 | BE25: https://gs.amac.org.cn/amac-infodisc/res/pof/fund/1811011729102590.html | BF25: 已核验
A26: 10 | B26: 悬铃C号2期 | C26: ='sheet4-原始数据'!B11 | D26: 上海悬铃 | E26: 2019-04-24 | F26: 7.3949 | G26: =IF(F26="","",IF(F26<1,"不入池","入池")) | H26: 20-50亿元 | I26: 90 | J26: 无低于1000万元标识 | K26: 100 | L26: 100 | M26: -0.0865 | N26: 0.0183 | P26: 0.075125939 | Q26: 5.21 | R26: 60 | S26: 27.13 | T26: 0.3077 | U26: 0.5676 | V26: 0.70837917 | W26: 30.77 | X26: 70.837917 | Y26: 46.8 | Z26: 0.087861859 | AA26: 0.1306 | AB26: 0.1306 | AC26: 19.16 | AD26: -0.9845 | AE26: 0.1306 | AF26: 0.5752369 | AG26: 0 | AH26: 20.59 | AI26: 8.24 | AJ26: 0.0183 | AK26: 80 | AL26: 96 | AM26: 33.03 | AN26: 19.16 | AO26: 8.24 | AP26: 80 | AQ26: 1 | AR26: 36.26627 | AS26: 36.27 | AT26: 281 | AU26: =IF(I26="","管理人规模；","")&IF(J26="","产品规模标识；","")&IF(AND(F26<3,O26=""),"R_incep；","")&IF(N26="","近三年收益；","")&IF(U26="","近三年胜率；","")&IF(AND(V26<>"",OR(V26<0,V26>1)),"胜率窗口口径不一致；","")&IF(AA26="","近三年回撤；","")&IF(AD26="","短期卡玛；","")&IF(AND(P26<>"",AE26=""),"DD_long不可识别；","") | AV26: 36.26627 | AW26: 20-50亿元 | AX26: 2026-07-13 | AY26: 上海悬铃私募基金管理有限公司 | AZ26: 2026-07-13 | BA26: https://gs.amac.org.cn/amac-infodisc/res/pof/manager/1701161209103763.html | BB26: 悬铃C号2期私募证券投资基金 | BC26: 2025-03-12 | BD26: 已匹配 | BE26: https://gs.amac.org.cn/amac-infodisc/res/pof/fund/1904291722104146.html | BF26: 已核验
A27: 11 | B27: 爱凡哲九号 | C27: ='sheet4-原始数据'!B12 | D27: 爱凡哲投资 | E27: 2019-09-02 | F27: 7.0363 | G27: =IF(F27="","",IF(F27<1,"不入池","入池")) | H27: 20-50亿元 | I27: 90 | J27: 无低于1000万元标识 | K27: 100 | L27: 100 | M27: 0.1158 | N27: 0.1178 | P27: 0.11880134 | Q27: 81.6 | R27: 79.5 | S27: 80.76 | T27: 0.8462 | U27: 0.8919 | V27: 0.91665417 | W27: 84.62 | X27: 91.665417 | Y27: 87.44 | Z27: 0.0035857832 | AA27: 0.0129 | AB27: 0.0129 | AC27: 82.23 | AD27: 32.2942 | AE27: 0.0129 | AF27: 9.2094065 | AG27: 94.76 | AH27: 90.44 | AI27: 93.03 | AJ27: 0.1178 | AK27: 80 | AL27: 96 | AM27: 82.76 | AN27: 82.23 | AO27: 93.03 | AP27: 80 | AQ27: 1 | AR27: 87.41979 | AS27: 87.42 | AT27: 20 | AU27: =IF(I27="","管理人规模；","")&IF(J27="","产品规模标识；","")&IF(AND(F27<3,O27=""),"R_incep；","")&IF(N27="","近三年收益；","")&IF(U27="","近三年胜率；","")&IF(AND(V27<>"",OR(V27<0,V27>1)),"胜率窗口口径不一致；","")&IF(AA27="","近三年回撤；","")&IF(AD27="","短期卡玛；","")&IF(AND(P27<>"",AE27=""),"DD_long不可识别；","") | AV27: 87.41979 | AW27: 20-50亿元 | AX27: 2025-04-30 | AY27: 爱凡哲投资管理有限公司 | AZ27: 2025-04-30 | BA27: https://gs.amac.org.cn/amac-infodisc/res/pof/manager/1709181131101311.html | BB27: 爱凡哲九号私募证券投资基金 | BC27: 2026-08-06 | BD27: 已匹配 | BE27: https://gs.amac.org.cn/amac-infodisc/res/pof/fund/1909051919107161.html | BF27: 已核验
A28: 12 | B28: 恒如套利三号 | C28: ='sheet4-原始数据'!B13 | D28: 上海恒如投资 | E28: 2019-09-19 | F28: 6.9897 | G28: =IF(F28="","",IF(F28<1,"不入池","入池")) | H28: 5-10亿元 | I28: 70 | J28: 无低于1000万元标识 | K28: 100 | L28: 100 | M28: 0.0213 | N28: 0.057 | P28: 0.075315275 | Q28: 24.65 | R28: 60.5 | S28: 38.99 | T28: 0.6154 | U28: 0.7297 | V28: 0.7916125 | W28: 61.54 | X28: 79.16125 | Y28: 68.59 | Z28: 0.0079353252 | AA28: 0.015 | AB28: 0.015 | AC28: 78.05 | AD28: 2.6842 | AE28: 0.015 | AF28: 5.0210183 | AG28: 52.8 | AH28: 86.03 | AI28: 66.09 | AJ28: 0.057 | AK28: 80 | AL28: 88 | AM28: 47.87 | AN28: 78.05 | AO28: 66.09 | AP28: 80 | AQ28: 1 | AR28: 70.11401 | AS28: 70.11 | AT28: 119 | AU28: =IF(I28="","管理人规模；","")&IF(J28="","产品规模标识；","")&IF(AND(F28<3,O28=""),"R_incep；","")&IF(N28="","近三年收益；","")&IF(U28="","近三年胜率；","")&IF(AND(V28<>"",OR(V28<0,V28>1)),"胜率窗口口径不一致；","")&IF(AA28="","近三年回撤；","")&IF(AD28="","短期卡玛；","")&IF(AND(P28<>"",AE28=""),"DD_long不可识别；","") | AV28: 70.11401 | AW28: 5-10亿元 | AX28: 2026-05-28 | AY28: 上海恒如投资管理有限公司 | AZ28: 2026-05-28 | BA28: https://gs.amac.org.cn/amac-infodisc/res/pof/manager/101000001221.html | BB28: 恒如套利三号私募证券投资基金 | BC28: 2024-11-21 | BD28: 已匹配 | BE28: https://gs.amac.org.cn/amac-infodisc/res/pof/fund/1910121042102347.html | BF28: 已核验
A29: 13 | B29: 鹿秀驯鹿二号 | C29: ='sheet4-原始数据'!B14 | D29: 青岛鹿秀投资 | E29: 2019-10-17 | F29: 6.9131 | G29: =IF(F29="","",IF(F29<1,"不入池","入池")) | H29: 50-100亿元 | I29: 90 | J29: 低于1000万元 | K29: 0 | L29: 100 | M29: 0.0399 | N29: 0.0246 | P29: 0.017034624 | Q29: 38.19 | R29: 7.5 | S29: 25.91 | T29: 0.9231 | U29: 0.8108 | V29: 0.74997083 | W29: 92.31 | X29: 74.997083 | Y29: 85.38 | Z29: 0.00021691856 | AA29: 0.0463 | AB29: 0.0463 | AC29: 46.69 | AD29: 183.94 | AE29: 0.0463 | AF29: 0.36791844 | AG29: 100 | AH29: 16.18 | AI29: 66.47 | AJ29: 0.0246 | AK29: 100 | AL29: 66 | AM29: 43.76 | AN29: 46.69 | AO29: 66.47 | AP29: 100 | AQ29: 1 | AR29: 60.26515 | AS29: 60.27 | AT29: 167 | AU29: =IF(I29="","管理人规模；","")&IF(J29="","产品规模标识；","")&IF(AND(F29<3,O29=""),"R_incep；","")&IF(N29="","近三年收益；","")&IF(U29="","近三年胜率；","")&IF(AND(V29<>"",OR(V29<0,V29>1)),"胜率窗口口径不一致；","")&IF(AA29="","近三年回撤；","")&IF(AD29="","短期卡玛；","")&IF(AND(P29<>"",AE29=""),"DD_long不可识别；","") | AV29: 60.26515 | AW29: 50-100亿元 | AX29: 2025-01-10 | AY29: 青岛鹿秀投资管理有限公司 | AZ29: 2025-01-10 | BA29: https://gs.amac.org.cn/amac-infodisc/res/pof/manager/1612231708101923.html | BB29: 鹿秀驯鹿二号私募证券投资基金 | BC29: 2026-07-15 | BD29: 已匹配 | BE29: https://gs.amac.org.cn/amac-infodisc/res/pof/fund/1910231722102267.html | BF29: 已核验
A30: 14 | B30: 本利达利磐一号 | C30: ='sheet4-原始数据'!B15 | D30: 深圳本利达资管 | E30: 2019-11-01 | F30: 6.872 | G30: =IF(F30="","",IF(F30<1,"不入池","入池")) | H30: 0-5亿元 | I30: 60 | J30: 无低于1000万元标识 | K30: 100 | L30: 100 | M30: 0.11 | N30: 0.1208 | P30: 0.12623934 | Q30: 80.21 | R30: 82 | S30: 80.93 | T30: 0.7692 | U30: 0.6757 | V30: 0.62505417 | W30: 76.92 | X30: 62.505417 | Y30: 71.15 | Z30: 0.11350738 | AA30: 0.1144 | AB30: 0.1144 | AC30: 24.04 | AD30: 0.9691 | AE30: 0.1144 | AF30: 1.1034907 | AG30: 33.92 | AH30: 44.85 | AI30: 38.29 | AJ30: 0.1208 | AK30: 80 | AL30: 84 | AM30: 77.99 | AN30: 24.04 | AO30: 38.29 | AP30: 80 | AQ30: 1 | AR30: 53.69649 | AS30: 53.7 | AT30: 203 | AU30: =IF(I30="","管理人规模；","")&IF(J30="","产品规模标识；","")&IF(AND(F30<3,O30=""),"R_incep；","")&IF(N30="","近三年收益；","")&IF(U30="","近三年胜率；","")&IF(AND(V30<>"",OR(V30<0,V30>1)),"胜率窗口口径不一致；","")&IF(AA30="","近三年回撤；","")&IF(AD30="","短期卡玛；","")&IF(AND(P30<>"",AE30=""),"DD_long不可识别；","") | AV30: 53.69649 | AW30: 0-5亿元 | AX30: 2026-06-16 | AY30: 深圳市本利达资产管理有限公司 | AZ30: 2026-06-16 | BA30: https://gs.amac.org.cn/amac-infodisc/res/pof/manager/101000028552.html | BB30: 本利达利磐一号私募证券投资基金 | BC30: 2025-04-01 | BD30: 已匹配 | BE30: https://gs.amac.org.cn/amac-infodisc/res/pof/fund/1911061732126237.html | BF30: 已核验
A31: 15 | B31: 和熙新月1号 | C31: ='sheet4-原始数据'!B16 | D31: 浙江和熙资管 | E31: 2019-11-14 | F31: 6.8364 | G31: =IF(F31="","",IF(F31<1,"不入池","入池")) | H31: 5-10亿元 | I31: 70 | J31: 无低于1000万元标识 | K31: 100 | L31: 100 | M31: -0.0029 | N31: 0.0207 | P31: 0.032708648 | Q31: 15.63 | R31: 18.5 | S31: 16.78 | T31: 0.4615 | U31: 0.4865 | V31: 0.50004167 | W31: 46.15 | X31: 50.004167 | Y31: 47.69 | Z31: 0.086053412 | AA31: 0.0853 | AB31: 0.086053412 | AC31: 30.31 | AD31: -0.0337 | AG31: 16.43 | AI31: 16.43 | AJ31: 0.0207 | AK31: 80 | AL31: 88 | AM31: 26.05 | AN31: 30.31 | AO31: 16.43 | AP31: 80 | AQ31: 0.88 | AR31: 36.94532 | AS31: 41.98 | AT31: 254 | AU31: =IF(I31="","管理人规模；","")&IF(J31="","产品规模标识；","")&IF(AND(F31<3,O31=""),"R_incep；","")&IF(N31="","近三年收益；","")&IF(U31="","近三年胜率；","")&IF(AND(V31<>"",OR(V31<0,V31>1)),"胜率窗口口径不一致；","")&IF(AA31="","近三年回撤；","")&IF(AD31="","短期卡玛；","")&IF(AND(P31<>"",AE31=""),"DD_long不可识别；","") | AW31: 5-10亿元 | AX31: 2026-02-10 | AY31: 浙江和熙资产管理有限公司 | AZ31: 2026-02-10 | BA31: https://gs.amac.org.cn/amac-infodisc/res/pof/manager/101000072213.html | BB31: 和熙新月1号私募证券投资基金 | BC31: 2025-03-20 | BD31: 已匹配 | BE31: https://gs.amac.org.cn/amac-infodisc/res/pof/fund/1911201726147441.html | BF31: 已核验
A32: 16 | B32: 鹿秀统计套利1号 | C32: ='sheet4-原始数据'!B17 | D32: 青岛鹿秀投资 | E32: 2019-12-02 | F32: 6.7871 | G32: =IF(F32="","",IF(F32<1,"不入池","入池")) | H32: 50-100亿元 | I32: 90 | J32: 无低于1000万元标识 | K32: 100 | L32: 100 | M32: 0.0304 | N32: 0.0355 | P32: 0.038059458 | Q32: 30.73 | R32: 24.25 | S32: 28.14 | T32: 1 | U32: 0.9189 | V32: 0.87497083 | W32: 100 | X32: 87.497083 | Y32: 95 | Z32: 0.00079323247 | AA32: 0.0009 | AB32: 0.0009 | AC32: 99.65 | AD32: 38.3242 | AE32: 0.0009 | AF32: 42.288287 | AG32: 96.15 | AH32: 100 | AI32: 97.69 | AJ32: 0.0355 | AK32: 80 | AL32: 96 | AM32: 48.2 | AN32: 99.65 | AO32: 97.69 | AP32: 80 | AQ32: 1 | AR32: 86.25875 | AS32: 86.26 | AT32: 25 | AU32: =IF(I32="","管理人规模；","")&IF(J32="","产品规模标识；","")&IF(AND(F32<3,O32=""),"R_incep；","")&IF(N32="","近三年收益；","")&IF(U32="","近三年胜率；","")&IF(AND(V32<>"",OR(V32<0,V32>1)),"胜率窗口口径不一致；","")&IF(AA32="","近三年回撤；","")&IF(AD32="","短期卡玛；","")&IF(AND(P32<>"",AE32=""),"DD_long不可识别；","") | AV32: 86.25875 | AW32: 50-100亿元 | AX32: 2025-01-10 | AY32: 青岛鹿秀投资管理有限公司 | AZ32: 2025-01-10 | BA32: https://gs.amac.org.cn/amac-infodisc/res/pof/manager/1612231708101923.html | BB32: 鹿秀统计套利1号私募证券基金 | BC32: 2026-07-14 | BD32: 已匹配 | BE32: https://gs.amac.org.cn/amac-infodisc/res/pof/fund/1912061240100295.html | BF32: 已核验
A33: 17 | B33: 唐龙量化对冲99号 | C33: ='sheet4-原始数据'!B18 | D33: 福建平潭唐龙资管 | E33: 2020-02-24 | F33: 6.5572 | G33: =IF(F33="","",IF(F33<1,"不入池","入池")) | H33: 5-10亿元 | I33: 70 | J33: 无低于1000万元标识 | K33: 100 | L33: 100 | M33: 0.0177 | N33: 0.0434 | P33: 0.056492361 | Q33: 23.26 | R33: 45 | S33: 31.96 | T33: 0.6154 | U33: 0.6757 | V33: 0.7083625 | W33: 61.54 | X33: 70.83625 | Y33: 65.26 | Z33: 0.0033091535 | AA33: 0.1407 | AB33: 0.1407 | AC33: 16.38 | AD33: 5.3488 | AE33: 0.1407 | AF33: 0.40150932 | AG33: 67.13 | AH33: 16.91 | AI33: 47.04 | AJ33: 0.0434 | AK33: 80 | AL33: 88 | AM33: 41.95 | AN33: 16.38 | AO33: 47.04 | AP33: 80 | AQ33: 1 | AR33: 47.79695 | AS33: 47.8 | AT33: 232 | AU33: =IF(I33="","管理人规模；","")&IF(J33="","产品规模标识；","")&IF(AND(F33<3,O33=""),"R_incep；","")&IF(N33="","近三年收益；","")&IF(U33="","近三年胜率；","")&IF(AND(V33<>"",OR(V33<0,V33>1)),"胜率窗口口径不一致；","")&IF(AA33="","近三年回撤；","")&IF(AD33="","短期卡玛；","")&IF(AND(P33<>"",AE33=""),"DD_long不可识别；","") | AV33: 47.79695 | AW33: 5-10亿元 | AX33: 2026-03-31 | AY33: 福建平潭唐龙资产管理有限公司 | AZ33: 2026-03-31 | BA33: https://gs.amac.org.cn/amac-infodisc/res/pof/manager/1708091719102142.html | BB33: 唐龙量化对冲99号私募证券投资基金 | BC33: 2023-11-29 | BD33: 已匹配 | BE33: https://gs.amac.org.cn/amac-infodisc/res/pof/fund/2002251051107073.html | BF33: 已核验
A34: 18 | B34: 凡德量化八号 | C34: ='sheet4-原始数据'!B19 | D34: 广东凡德投资 | E34: 2020-03-02 | F34: 6.538 | G34: =IF(F34="","",IF(F34<1,"不入池","入池")) | H34: 5-10亿元 | I34: 70 | J34: 无低于1000万元标识 | K34: 100 | L34: 100 | M34: -0.0136 | N34: 0.0421 | P34: 0.071118603 | Q34: 13.72 | R34: 57.5 | S34: 31.23 | T34: 0.5385 | U34: 0.5676 | V34: 0.5833625 | W34: 53.85 | X34: 58.33625 | Y34: 55.64 | Z34: 0.122633 | AA34: 0.1226 | AB34: 0.122633 | AC34: 20.21 | AD34: -0.1109 | AG34: 14.34 | AI34: 14.34 | AJ34: 0.0421 | AK34: 80 | AL34: 88 | AM34: 38.56 | AN34: 20.21 | AO34: 14.34 | AP34: 80 | AQ34: 0.88 | AR34: 36.54485 | AS34: 41.53 | AT34: 257 | AU34: =IF(I34="","管理人规模；","")&IF(J34="","产品规模标识；","")&IF(AND(F34<3,O34=""),"R_incep；","")&IF(N34="","近三年收益；","")&IF(U34="","近三年胜率；","")&IF(AND(V34<>"",OR(V34<0,V34>1)),"胜率窗口口径不一致；","")&IF(AA34="","近三年回撤；","")&IF(AD34="","短期卡玛；","")&IF(AND(P34<>"",AE34=""),"DD_long不可识别；","") | AW34: 5-10亿元 | AX34: 2026-04-15 | AY34: 广东凡德投资有限公司 | AZ34: 2026-04-15 | BA34: https://gs.amac.org.cn/amac-infodisc/res/pof/manager/101000000695.html | BB34: 凡德量化八号私募证券投资基金 | BC34: 2025-03-27 | BD34: 已匹配 | BE34: https://gs.amac.org.cn/amac-infodisc/res/pof/fund/2003030835104240.html | BF34: 已核验
A35: 19 | B35: 百奕传家一号 | C35: ='sheet4-原始数据'!B20 | D35: 上海百奕投资 | E35: 2020-03-23 | F35: 6.4805 | G35: =IF(F35="","",IF(F35<1,"不入池","入池")) | H35: 0-5亿元 | I35: 60 | J35: 无低于1000万元标识 | K35: 100 | L35: 100 | M35: 0.1386 | N35: 0.0598 | P35: 0.022469314 | Q35: 86.11 | R35: 11.5 | S35: 56.27 | T35: 0.5385 | U35: 0.6216 | V35: 0.6666125 | W35: 53.85 | X35: 66.66125 | Y35: 58.97 | Z35: 0.040054331 | AA35: 0.1117 | AB35: 0.1117 | AC35: 24.74 | AD35: 3.4603 | AE35: 0.1117 | AF35: 0.20115769 | AG35: 59.09 | AH35: 11.03 | AI35: 39.87 | AJ35: 0.0598 | AK35: 100 | AL35: 84 | AM35: 57.08 | AN35: 24.74 | AO35: 39.87 | AP35: 100 | AQ35: 1 | AR35: 52.16051 | AS35: 52.16 | AT35: 211 | AU35: =IF(I35="","管理人规模；","")&IF(J35="","产品规模标识；","")&IF(AND(F35<3,O35=""),"R_incep；","")&IF(N35="","近三年收益；","")&IF(U35="","近三年胜率；","")&IF(AND(V35<>"",OR(V35<0,V35>1)),"胜率窗口口径不一致；","")&IF(AA35="","近三年回撤；","")&IF(AD35="","短期卡玛；","")&IF(AND(P35<>"",AE35=""),"DD_long不可识别；","") | AV35: 52.16051 | AW35: 0-5亿元 | AX35: 2026-07-24 | AY35: 上海百奕投资管理中心（有限合伙） | AZ35: 2026-07-24 | BA35: https://gs.amac.org.cn/amac-infodisc/res/pof/manager/101000019935.html | BB35: 百奕传家一号私募证券投资基金 | BC35: 2025-04-24 | BD35: 已匹配 | BE35: https://gs.amac.org.cn/amac-infodisc/res/pof/fund/2003301654103531.html | BF35: 已核验
A36: 20 | B36: 蒙森斯道特恒星三号 | C36: ='sheet4-原始数据'!B21 | D36: 上海蒙森投资 | E36: 2020-04-03 | F36: 6.4504 | G36: =IF(F36="","",IF(F36<1,"不入池","入池")) | H36: 0-5亿元 | I36: 60 | J36: 无低于1000万元标识 | K36: 100 | L36: 100 | M36: 0.0715 | N36: 0.0706 | P36: 0.070150284 | Q36: 59.72 | R36: 57 | S36: 58.63 | T36: 0.3077 | U36: 0.4865 | V36: 0.58335 | W36: 30.77 | X36: 58.335 | Y36: 41.8 | Z36: 0.033411215 | AA36: 0.0797 | AB36: 0.0797 | AC36: 33.1 | AD36: 2.14 | AE36: 0.0797 | AF36: 0.88017922 | AG36: 49.65 | AH36: 37.5 | AI36: 44.79 | AJ36: 0.0706 | AK36: 100 | AL36: 84 | AM36: 53.58 | AN36: 33.1 | AO36: 44.79 | AP36: 100 | AQ36: 1 | AR36: 55.02824 | AS36: 55.03 | AT36: 194 | AU36: =IF(I36="","管理人规模；","")&IF(J36="","产品规模标识；","")&IF(AND(F36<3,O36=""),"R_incep；","")&IF(N36="","近三年收益；","")&IF(U36="","近三年胜率；","")&IF(AND(V36<>"",OR(V36<0,V36>1)),"胜率窗口口径不一致；","")&IF(AA36="","近三年回撤；","")&IF(AD36="","短期卡玛；","")&IF(AND(P36<>"",AE36=""),"DD_long不可识别；","") | AV36: 55.02824 | AW36: 0-5亿元 | AX36: 2026-03-30 | AY36: 蒙森（上海）投资管理有限公司 | AZ36: 2026-03-30 | BA36: https://gs.amac.org.cn/amac-infodisc/res/pof/manager/101000010726.html | BB36: 蒙森斯道特恒星三号私募证券投资基金 | BC36: 2025-05-07 | BD36: 已匹配 | BE36: https://gs.amac.org.cn/amac-infodisc/res/pof/fund/2004141727126733.html | BF36: 已核验
A37: 21 | B37: 银瓴运通对冲套利致远3号 | C37: ='sheet4-原始数据'!B22 | D37: 广西银瓴资产 | E37: 2020-06-16 | F37: 6.2478 | G37: =IF(F37="","",IF(F37<1,"不入池","入池")) | H37: 0-5亿元 | I37: 60 | J37: 低于1000万元 | K37: 0 | L37: 100 | M37: -0.0415 | N37: 0.0004 | P37: 0.022031934 | Q37: 9.03 | R37: 11 | S37: 9.82 | T37: 0.6154 | U37: 0.5405 | V37: 0.49992917 | W37: 61.54 | X37: 49.992917 | Y37: 56.92 | Z37: 0.10295212 | AA37: 0.113 | AB37: 0.113 | AC37: 24.39 | AD37: -0.4031 | AE37: 0.113 | AF37: 0.19497287 | AG37: 7.34 | AH37: 10.29 | AI37: 8.52 | AJ37: 0.0004 | AK37: 80 | AL37: 54 | AM37: 23.95 | AN37: 24.39 | AO37: 8.52 | AP37: 80 | AQ37: 1 | AR37: 29.54329 | AS37: 29.54 | AT37: 296 | AU37: =IF(I37="","管理人规模；","")&IF(J37="","产品规模标识；","")&IF(AND(F37<3,O37=""),"R_incep；","")&IF(N37="","近三年收益；","")&IF(U37="","近三年胜率；","")&IF(AND(V37<>"",OR(V37<0,V37>1)),"胜率窗口口径不一致；","")&IF(AA37="","近三年回撤；","")&IF(AD37="","短期卡玛；","")&IF(AND(P37<>"",AE37=""),"DD_long不可识别；","") | AV37: 29.54329 | AW37: 0-5亿元 | AX37: 2026-07-09 | AY37: 广西银瓴资产管理有限公司 | AZ37: 2026-07-09 | BA37: https://gs.amac.org.cn/amac-infodisc/res/pof/manager/101000035485.html | BB37: 银瓴运通对冲套利致远3号私募证券投资基金 | BC37: 2024-12-04 | BD37: 已匹配 | BE37: https://gs.amac.org.cn/amac-infodisc/res/pof/fund/2006181800104261.html | BF37: 已核验
A38: 22 | B38: 银瓴运通对冲套利进取2号 | C38: ='sheet4-原始数据'!B23 | D38: 广西银瓴资产 | E38: 2020-06-16 | F38: 6.2478 | G38: =IF(F38="","",IF(F38<1,"不入池","入池")) | H38: 0-5亿元 | I38: 60 | J38: 无低于1000万元标识 | K38: 100 | L38: 100 | M38: -0.015 | N38: -0.0118 | P38: -0.010196104 | Q38: 13.19 | R38: 4 | S38: 9.51 | T38: 0.3846 | U38: 0.4324 | V38: 0.45829167 | W38: 38.46 | X38: 45.829167 | Y38: 41.41 | Z38: 0.076142132 | AA38: 0.1738 | AB38: 0.1738 | AC38: 13.59 | AD38: -0.197 | AE38: 0.1738 | AF38: -0.058665729 | AG38: 11.19 | AH38: 5.88 | AI38: 9.07 | AJ38: -0.0118 | AK38: 80 | AL38: 84 | AM38: 19.08 | AN38: 13.59 | AO38: 9.07 | AP38: 80 | AQ38: 1 | AR38: 30.53372 | AS38: 30.53 | AT38: 294 | AU38: =IF(I38="","管理人规模；","")&IF(J38="","产品规模标识；","")&IF(AND(F38<3,O38=""),"R_incep；","")&IF(N38="","近三年收益；","")&IF(U38="","近三年胜率；","")&IF(AND(V38<>"",OR(V38<0,V38>1)),"胜率窗口口径不一致；","")&IF(AA38="","近三年回撤；","")&IF(AD38="","短期卡玛；","")&IF(AND(P38<>"",AE38=""),"DD_long不可识别；","") | AV38: 30.53372 | AW38: 0-5亿元 | AX38: 2026-07-09 | AY38: 广西银瓴资产管理有限公司 | AZ38: 2026-07-09 | BA38: https://gs.amac.org.cn/amac-infodisc/res/pof/manager/101000035485.html | BB38: 银瓴运通对冲套利进取2号私募证券投资基金 | BC38: 2024-12-04 | BD38: 已匹配 | BE38: https://gs.amac.org.cn/amac-infodisc/res/pof/fund/2006192211107635.html | BF38: 已核验
A39: 23 | B39: 铭杉量化稳健5号 | C39: ='sheet4-原始数据'!B24 | D39: 上海铭杉投资 | E39: 2020-09-14 | F39: 6.0014 | G39: =IF(F39="","",IF(F39<1,"不入池","入池")) | H39: 0-5亿元 | I39: 60 | J39: 低于1000万元 | K39: 0 | L39: 100 | M39: 0.0563 | N39: 0.0578 | P39: 0.058550799 | Q39: 48.09 | R39: 48 | S39: 48.05 | T39: 0.7692 | U39: 0.8649 | V39: 0.9167375 | W39: 76.92 | X39: 91.67375 | Y39: 82.82 | Z39: 0.02510367 | AA39: 0.0251 | AB39: 0.02510367 | AC39: 66.55 | AD39: 2.2427 | AG39: 50 | AI39: 50 | AJ39: 0.0578 | AK39: 80 | AL39: 54 | AM39: 58.48 | AN39: 66.55 | AO39: 50 | AP39: 80 | AQ39: 0.88 | AR39: 53.43435 | AS39: 60.72 | AT39: 162 | AU39: =IF(I39="","管理人规模；","")&IF(J39="","产品规模标识；","")&IF(AND(F39<3,O39=""),"R_incep；","")&IF(N39="","近三年收益；","")&IF(U39="","近三年胜率；","")&IF(AND(V39<>"",OR(V39<0,V39>1)),"胜率窗口口径不一致；","")&IF(AA39="","近三年回撤；","")&IF(AD39="","短期卡玛；","")&IF(AND(P39<>"",AE39=""),"DD_long不可识别；","") | AW39: 0-5亿元 | AX39: 2025-05-20 | AY39: 上海铭杉投资管理有限公司 | AZ39: 2025-05-20 | BA39: https://gs.amac.org.cn/amac-infodisc/res/pof/manager/1708301158107602.html | BB39: 铭杉量化稳健5号私募证券投资基金 | BC39: 2026-07-08 | BD39: 已匹配 | BE39: https://gs.amac.org.cn/amac-infodisc/res/pof/fund/2009171717131963.html | BF39: 已核验
A40: 24 | B40: 数为道策套利一号 | C40: ='sheet4-原始数据'!B25 | D40: 福州数为 | E40: 2020-10-19 | F40: 5.9055 | G40: =IF(F40="","",IF(F40<1,"不入池","入池")) | H40: 0-5亿元 | I40: 60 | J40: 低于1000万元 | K40: 0 | L40: 100 | M40: -0.3489 | N40: -0.1122 | P40: 0.03668989 | Q40: 0.35 | R40: 22 | S40: 9.01 | T40: 0.2308 | U40: 0.4054 | V40: 0.499975 | W40: 23.08 | X40: 49.9975 | Y40: 33.85 | Z40: 0.37018568 | AA40: 0.3702 | AB40: 0.3702 | AC40: 1.05 | AD40: -0.9425 | AG40: 0.7 | AI40: 0.7 | AJ40: -0.1122 | AK40: 60 | AL40: 54 | AM40: 16.46 | AN40: 1.05 | AO40: 0.7 | AP40: 60 | AQ40: 0.88 | AR40: 17.78072 | AS40: 20.21 | AT40: 314 | AU40: =IF(I40="","管理人规模；","")&IF(J40="","产品规模标识；","")&IF(AND(F40<3,O40=""),"R_incep；","")&IF(N40="","近三年收益；","")&IF(U40="","近三年胜率；","")&IF(AND(V40<>"",OR(V40<0,V40>1)),"胜率窗口口径不一致；","")&IF(AA40="","近三年回撤；","")&IF(AD40="","短期卡玛；","")&IF(AND(P40<>"",AE40=""),"DD_long不可识别；","") | AW40: 0-5亿元 | AX40: 2025-07-31 | AY40: 福州数为私募基金管理有限公司 | AZ40: 2025-07-31 | BA40: https://gs.amac.org.cn/amac-infodisc/res/pof/manager/1705081548107725.html | BB40: 数为道策套利一号私募证券投资基金 | BC40: 2025-07-07 | BD40: 已匹配 | BE40: https://gs.amac.org.cn/amac-infodisc/res/pof/fund/2010271707103406.html | BF40: 已核验
A41: 25 | B41: 犇牛稳进3号 | C41: ='sheet4-原始数据'!B26 | D41: 上海犇牛 | E41: 2020-11-09 | F41: 5.848 | G41: =IF(F41="","",IF(F41<1,"不入池","入池")) | H41: 10-20亿元 | I41: 80 | J41: 无低于1000万元标识 | K41: 100 | L41: 100 | M41: 0.0374 | N41: 0.0455 | P41: 0.049573686 | Q41: 34.03 | R41: 37 | S41: 35.22 | T41: 0.7692 | U41: 0.5946 | V41: 0.500025 | W41: 76.92 | X41: 50.0025 | Y41: 66.15 | Z41: 0.0084277892 | AA41: 0.0265 | AB41: 0.0265 | AC41: 63.41 | AD41: 4.4377 | AE41: 0.0265 | AF41: 1.8707051 | AG41: 64.34 | AH41: 63.97 | AI41: 64.19 | AJ41: 0.0455 | AK41: 80 | AL41: 92 | AM41: 44.5 | AN41: 63.41 | AO41: 64.19 | AP41: 80 | AQ41: 1 | AR41: 65.8098 | AS41: 65.81 | AT41: 142 | AU41: =IF(I41="","管理人规模；","")&IF(J41="","产品规模标识；","")&IF(AND(F41<3,O41=""),"R_incep；","")&IF(N41="","近三年收益；","")&IF(U41="","近三年胜率；","")&IF(AND(V41<>"",OR(V41<0,V41>1)),"胜率窗口口径不一致；","")&IF(AA41="","近三年回撤；","")&IF(AD41="","短期卡玛；","")&IF(AND(P41<>"",AE41=""),"DD_long不可识别；","") | AV41: 65.8098 | AW41: 10-20亿元 | AX41: 2026-07-08 | AY41: 上海犇牛私募基金管理有限公司 | AZ41: 2026-07-08 | BA41: https://gs.amac.org.cn/amac-infodisc/res/pof/manager/101000013203.html | BB41: 犇牛稳进3号私募证券投资基金 | BC41: 2025-05-12 | BD41: 已匹配 | BE41: https://gs.amac.org.cn/amac-infodisc/res/pof/fund/2011121710129780.html | BF41: 已核验
A42: 26 | B42: 致同云峰A | C42: ='sheet4-原始数据'!B27 | D42: 上海致同投资 | E42: 2020-11-10 | F42: 5.8453 | G42: =IF(F42="","",IF(F42<1,"不入池","入池")) | H42: 20-50亿元 | I42: 90 | J42: 无低于1000万元标识 | K42: 100 | L42: 100 | M42: 0.0408 | N42: 0.0422 | P42: 0.042900706 | Q42: 40.63 | R42: 31 | S42: 36.78 | T42: 0.6923 | U42: 0.7297 | V42: 0.74995833 | W42: 69.23 | X42: 74.995833 | Y42: 71.54 | Z42: 0.014522674 | AA42: 0.0145 | AB42: 0.014522674 | AC42: 79.09 | AD42: 2.8094 | AG42: 53.5 | AI42: 53.5 | AJ42: 0.0422 | AK42: 80 | AL42: 96 | AM42: 47.21 | AN42: 79.09 | AO42: 53.5 | AP42: 80 | AQ42: 0.88 | AR42: 61.2436 | AS42: 69.6 | AT42: 123 | AU42: =IF(I42="","管理人规模；","")&IF(J42="","产品规模标识；","")&IF(AND(F42<3,O42=""),"R_incep；","")&IF(N42="","近三年收益；","")&IF(U42="","近三年胜率；","")&IF(AND(V42<>"",OR(V42<0,V42>1)),"胜率窗口口径不一致；","")&IF(AA42="","近三年回撤；","")&IF(AD42="","短期卡玛；","")&IF(AND(P42<>"",AE42=""),"DD_long不可识别；","") | AW42: 20-50亿元 | AX42: 2026-03-16 | AY42: 上海致同投资管理有限公司 | AZ42: 2026-03-16 | BA42: https://gs.amac.org.cn/amac-infodisc/res/pof/manager/101000004339.html | BB42: 致同云峰A私募证券投资基金 | BC42: 2025-05-27 | BD42: 已匹配 | BE42: https://gs.amac.org.cn/amac-infodisc/res/pof/fund/2011161541105858.html | BF42: 已核验
...

Sheet sheet3-分类汇总
A1: 私募基金大类指标赋分与排名
A2: 本版评分范围为模板Sheet2的314只产品；数据截至2026-09-11；协会规模按公示区间分组，5亿元边界已注明。
A4: 基本信息 | F4: 二级指标得分 | N4: 大类指标得分 | S4: 总分、完整度与追溯
A5: 排名 | B5: 产品名称 | C5: 备案号 | D5: 管理人 | E5: 入池状态 | F5: 管理人规模分 | G5: 产品规模分 | H5: 成立年限分 | I5: 年化收益分（可用折算） | J5: 月度胜率分（可用折算） | K5: 最大回撤分 | L5: 卡玛比率分（可用折算） | M5: 收益趋势分 | N5: 管理人及产品 | O5: 收益能力 | P5: 风险控制 | Q5: 风险调整收益 | R5: 业绩一致性/趋势 | S5: 有效权重 | T5: 加权总分（不补缺） | U5: 可比总分 | V5: 严格总分 | W5: 数据缺口 | X5: 明细相对行
A6: 1 | B6: =IF($X6="","",INDEX('sheet2-计算明细'!$B$17:$B$330,$X6)) | C6: =IF($X6="","",INDEX('sheet2-计算明细'!$C$17:$C$330,$X6)) | D6: =IF($X6="","",INDEX('sheet2-计算明细'!$D$17:$D$330,$X6)) | E6: =IF($X6="","",INDEX('sheet2-计算明细'!$G$17:$G$330,$X6)) | F6: =IF($X6="","",INDEX('sheet2-计算明细'!$I$17:$I$330,$X6)) | G6: =IF($X6="","",INDEX('sheet2-计算明细'!$K$17:$K$330,$X6)) | H6: =IF($X6="","",INDEX('sheet2-计算明细'!$L$17:$L$330,$X6)) | I6: =IF($X6="","",INDEX('sheet2-计算明细'!$S$17:$S$330,$X6)) | J6: =IF($X6="","",INDEX('sheet2-计算明细'!$Y$17:$Y$330,$X6)) | K6: =IF($X6="","",INDEX('sheet2-计算明细'!$AC$17:$AC$330,$X6)) | L6: =IF($X6="","",INDEX('sheet2-计算明细'!$AI$17:$AI$330,$X6)) | M6: =IF($X6="","",INDEX('sheet2-计算明细'!$AK$17:$AK$330,$X6)) | N6: =IF(COUNT(F6:H6)=0,"",ROUND((IF(ISNUMBER(F6),F6*40%,0)+IF(ISNUMBER(G6),G6*30%,0)+IF(ISNUMBER(H6),H6*30%,0))/(IF(ISNUMBER(F6),40%,0)+IF(ISNUMBER(G6),30%,0)+IF(ISNUMBER(H6),30%,0)),2)) | O6: =IF(COUNT(I6:J6)=0,"",ROUND((IF(ISNUMBER(I6),I6*70%,0)+IF(ISNUMBER(J6),J6*30%,0))/(IF(ISNUMBER(I6),70%,0)+IF(ISNUMBER(J6),30%,0)),2)) | P6: =K6 | Q6: =L6 | R6: =M6 | S6: =IF($X6="","",INDEX('sheet2-计算明细'!$AQ$17:$AQ$330,$X6)) | T6: =IF($X6="","",INDEX('sheet2-计算明细'!$AR$17:$AR$330,$X6)) | U6: =IF(S6=0,"",ROUND(T6/S6,2)) | V6: =IF(S6=100%,T6,"") | W6: =IF($X6="","",INDEX('sheet2-计算明细'!$AU$17:$AU$330,$X6)) | X6: =IF($A6>COUNT('sheet2-计算明细'!$AT$17:$AT$330),"",MATCH($A6,'sheet2-计算明细'!$AT$17:$AT$330,0))
A7: 2 | B7: =IF($X7="","",INDEX('sheet2-计算明细'!$B$17:$B$330,$X7)) | C7: =IF($X7="","",INDEX('sheet2-计算明细'!$C$17:$C$330,$X7)) | D7: =IF($X7="","",INDEX('sheet2-计算明细'!$D$17:$D$330,$X7)) | E7: =IF($X7="","",INDEX('sheet2-计算明细'!$G$17:$G$330,$X7)) | F7: =IF($X7="","",INDEX('sheet2-计算明细'!$I$17:$I$330,$X7)) | G7: =IF($X7="","",INDEX('sheet2-计算明细'!$K$17:$K$330,$X7)) | H7: =IF($X7="","",INDEX('sheet2-计算明细'!$L$17:$L$330,$X7)) | I7: =IF($X7="","",INDEX('sheet2-计算明细'!$S$17:$S$330,$X7)) | J7: =IF($X7="","",INDEX('sheet2-计算明细'!$Y$17:$Y$330,$X7)) | K7: =IF($X7="","",INDEX('sheet2-计算明细'!$AC$17:$AC$330,$X7)) | L7: =IF($X7="","",INDEX('sheet2-计算明细'!$AI$17:$AI$330,$X7)) | M7: =IF($X7="","",INDEX('sheet2-计算明细'!$AK$17:$AK$330,$X7)) | N7: =IF(COUNT(F7:H7)=0,"",ROUND((IF(ISNUMBER(F7),F7*40%,0)+IF(ISNUMBER(G7),G7*30%,0)+IF(ISNUMBER(H7),H7*30%,0))/(IF(ISNUMBER(F7),40%,0)+IF(ISNUMBER(G7),30%,0)+IF(ISNUMBER(H7),30%,0)),2)) | O7: =IF(COUNT(I7:J7)=0,"",ROUND((IF(ISNUMBER(I7),I7*70%,0)+IF(ISNUMBER(J7),J7*30%,0))/(IF(ISNUMBER(I7),70%,0)+IF(ISNUMBER(J7),30%,0)),2)) | P7: =K7 | Q7: =L7 | R7: =M7 | S7: =IF($X7="","",INDEX('sheet2-计算明细'!$AQ$17:$AQ$330,$X7)) | T7: =IF($X7="","",INDEX('sheet2-计算明细'!$AR$17:$AR$330,$X7)) | U7: =IF(S7=0,"",ROUND(T7/S7,2)) | V7: =IF(S7=100%,T7,"") | W7: =IF($X7="","",INDEX('sheet2-计算明细'!$AU$17:$AU$330,$X7)) | X7: =IF($A7>COUNT('sheet2-计算明细'!$AT$17:$AT$330),"",MATCH($A7,'sheet2-计算明细'!$AT$17:$AT$330,0))
A8: 3 | B8: =IF($X8="","",INDEX('sheet2-计算明细'!$B$17:$B$330,$X8)) | C8: =IF($X8="","",INDEX('sheet2-计算明细'!$C$17:$C$330,$X8)) | D8: =IF($X8="","",INDEX('sheet2-计算明细'!$D$17:$D$330,$X8)) | E8: =IF($X8="","",INDEX('sheet2-计算明细'!$G$17:$G$330,$X8)) | F8: =IF($X8="","",INDEX('sheet2-计算明细'!$I$17:$I$330,$X8)) | G8: =IF($X8="","",INDEX('sheet2-计算明细'!$K$17:$K$330,$X8)) | H8: =IF($X8="","",INDEX('sheet2-计算明细'!$L$17:$L$330,$X8)) | I8: =IF($X8="","",INDEX('sheet2-计算明细'!$S$17:$S$330,$X8)) | J8: =IF($X8="","",INDEX('sheet2-计算明细'!$Y$17:$Y$330,$X8)) | K8: =IF($X8="","",INDEX('sheet2-计算明细'!$AC$17:$AC$330,$X8)) | L8: =IF($X8="","",INDEX('sheet2-计算明细'!$AI$17:$AI$330,$X8)) | M8: =IF($X8="","",INDEX('sheet2-计算明细'!$AK$17:$AK$330,$X8)) | N8: =IF(COUNT(F8:H8)=0,"",ROUND((IF(ISNUMBER(F8),F8*40%,0)+IF(ISNUMBER(G8),G8*30%,0)+IF(ISNUMBER(H8),H8*30%,0))/(IF(ISNUMBER(F8),40%,0)+IF(ISNUMBER(G8),30%,0)+IF(ISNUMBER(H8),30%,0)),2)) | O8: =IF(COUNT(I8:J8)=0,"",ROUND((IF(ISNUMBER(I8),I8*70%,0)+IF(ISNUMBER(J8),J8*30%,0))/(IF(ISNUMBER(I8),70%,0)+IF(ISNUMBER(J8),30%,0)),2)) | P8: =K8 | Q8: =L8 | R8: =M8 | S8: =IF($X8="","",INDEX('sheet2-计算明细'!$AQ$17:$AQ$330,$X8)) | T8: =IF($X8="","",INDEX('sheet2-计算明细'!$AR$17:$AR$330,$X8)) | U8: =IF(S8=0,"",ROUND(T8/S8,2)) | V8: =IF(S8=100%,T8,"") | W8: =IF($X8="","",INDEX('sheet2-计算明细'!$AU$17:$AU$330,$X8)) | X8: =IF($A8>COUNT('sheet2-计算明细'!$AT$17:$AT$330),"",MATCH($A8,'sheet2-计算明细'!$AT$17:$AT$330,0))
A9: 4 | B9: =IF($X9="","",INDEX('sheet2-计算明细'!$B$17:$B$330,$X9)) | C9: =IF($X9="","",INDEX('sheet2-计算明细'!$C$17:$C$330,$X9)) | D9: =IF($X9="","",INDEX('sheet2-计算明细'!$D$17:$D$330,$X9)) | E9: =IF($X9="","",INDEX('sheet2-计算明细'!$G$17:$G$330,$X9)) | F9: =IF($X9="","",INDEX('sheet2-计算明细'!$I$17:$I$330,$X9)) | G9: =IF($X9="","",INDEX('sheet2-计算明细'!$K$17:$K$330,$X9)) | H9: =IF($X9="","",INDEX('sheet2-计算明细'!$L$17:$L$330,$X9)) | I9: =IF($X9="","",INDEX('sheet2-计算明细'!$S$17:$S$330,$X9)) | J9: =IF($X9="","",INDEX('sheet2-计算明细'!$Y$17:$Y$330,$X9)) | K9: =IF($X9="","",INDEX('sheet2-计算明细'!$AC$17:$AC$330,$X9)) | L9: =IF($X9="","",INDEX('sheet2-计算明细'!$AI$17:$AI$330,$X9)) | M9: =IF($X9="","",INDEX('sheet2-计算明细'!$AK$17:$AK$330,$X9)) | N9: =IF(COUNT(F9:H9)=0,"",ROUND((IF(ISNUMBER(F9),F9*40%,0)+IF(ISNUMBER(G9),G9*30%,0)+IF(ISNUMBER(H9),H9*30%,0))/(IF(ISNUMBER(F9),40%,0)+IF(ISNUMBER(G9),30%,0)+IF(ISNUMBER(H9),30%,0)),2)) | O9: =IF(COUNT(I9:J9)=0,"",ROUND((IF(ISNUMBER(I9),I9*70%,0)+IF(ISNUMBER(J9),J9*30%,0))/(IF(ISNUMBER(I9),70%,0)+IF(ISNUMBER(J9),30%,0)),2)) | P9: =K9 | Q9: =L9 | R9: =M9 | S9: =IF($X9="","",INDEX('sheet2-计算明细'!$AQ$17:$AQ$330,$X9)) | T9: =IF($X9="","",INDEX('sheet2-计算明细'!$AR$17:$AR$330,$X9)) | U9: =IF(S9=0,"",ROUND(T9/S9,2)) | V9: =IF(S9=100%,T9,"") | W9: =IF($X9="","",INDEX('sheet2-计算明细'!$AU$17:$AU$330,$X9)) | X9: =IF($A9>COUNT('sheet2-计算明细'!$AT$17:$AT$330),"",MATCH($A9,'sheet2-计算明细'!$AT$17:$AT$330,0))
A10: 5 | B10: =IF($X10="","",INDEX('sheet2-计算明细'!$B$17:$B$330,$X10)) | C10: =IF($X10="","",INDEX('sheet2-计算明细'!$C$17:$C$330,$X10)) | D10: =IF($X10="","",INDEX('sheet2-计算明细'!$D$17:$D$330,$X10)) | E10: =IF($X10="","",INDEX('sheet2-计算明细'!$G$17:$G$330,$X10)) | F10: =IF($X10="","",INDEX('sheet2-计算明细'!$I$17:$I$330,$X10)) | G10: =IF($X10="","",INDEX('sheet2-计算明细'!$K$17:$K$330,$X10)) | H10: =IF($X10="","",INDEX('sheet2-计算明细'!$L$17:$L$330,$X10)) | I10: =IF($X10="","",INDEX('sheet2-计算明细'!$S$17:$S$330,$X10)) | J10: =IF($X10="","",INDEX('sheet2-计算明细'!$Y$17:$Y$330,$X10)) | K10: =IF($X10="","",INDEX('sheet2-计算明细'!$AC$17:$AC$330,$X10)) | L10: =IF($X10="","",INDEX('sheet2-计算明细'!$AI$17:$AI$330,$X10)) | M10: =IF($X10="","",INDEX('sheet2-计算明细'!$AK$17:$AK$330,$X10)) | N10: =IF(COUNT(F10:H10)=0,"",ROUND((IF(ISNUMBER(F10),F10*40%,0)+IF(ISNUMBER(G10),G10*30%,0)+IF(ISNUMBER(H10),H10*30%,0))/(IF(ISNUMBER(F10),40%,0)+IF(ISNUMBER(G10),30%,0)+IF(ISNUMBER(H10),30%,0)),2)) | O10: =IF(COUNT(I10:J10)=0,"",ROUND((IF(ISNUMBER(I10),I10*70%,0)+IF(ISNUMBER(J10),J10*30%,0))/(IF(ISNUMBER(I10),70%,0)+IF(ISNUMBER(J10),30%,0)),2)) | P10: =K10 | Q10: =L10 | R10: =M10 | S10: =IF($X10="","",INDEX('sheet2-计算明细'!$AQ$17:$AQ$330,$X10)) | T10: =IF($X10="","",INDEX('sheet2-计算明细'!$AR$17:$AR$330,$X10)) | U10: =IF(S10=0,"",ROUND(T10/S10,2)) | V10: =IF(S10=100%,T10,"") | W10: =IF($X10="","",INDEX('sheet2-计算明细'!$AU$17:$AU$330,$X10)) | X10: =IF($A10>COUNT('sheet2-计算明细'!$AT$17:$AT$330),"",MATCH($A10,'sheet2-计算明细'!$AT$17:$AT$330,0))
A11: 6 | B11: =IF($X11="","",INDEX('sheet2-计算明细'!$B$17:$B$330,$X11)) | C11: =IF($X11="","",INDEX('sheet2-计算明细'!$C$17:$C$330,$X11)) | D11: =IF($X11="","",INDEX('sheet2-计算明细'!$D$17:$D$330,$X11)) | E11: =IF($X11="","",INDEX('sheet2-计算明细'!$G$17:$G$330,$X11)) | F11: =IF($X11="","",INDEX('sheet2-计算明细'!$I$17:$I$330,$X11)) | G11: =IF($X11="","",INDEX('sheet2-计算明细'!$K$17:$K$330,$X11)) | H11: =IF($X11="","",INDEX('sheet2-计算明细'!$L$17:$L$330,$X11)) | I11: =IF($X11="","",INDEX('sheet2-计算明细'!$S$17:$S$330,$X11)) | J11: =IF($X11="","",INDEX('sheet2-计算明细'!$Y$17:$Y$330,$X11)) | K11: =IF($X11="","",INDEX('sheet2-计算明细'!$AC$17:$AC$330,$X11)) | L11: =IF($X11="","",INDEX('sheet2-计算明细'!$AI$17:$AI$330,$X11)) | M11: =IF($X11="","",INDEX('sheet2-计算明细'!$AK$17:$AK$330,$X11)) | N11: =IF(COUNT(F11:H11)=0,"",ROUND((IF(ISNUMBER(F11),F11*40%,0)+IF(ISNUMBER(G11),G11*30%,0)+IF(ISNUMBER(H11),H11*30%,0))/(IF(ISNUMBER(F11),40%,0)+IF(ISNUMBER(G11),30%,0)+IF(ISNUMBER(H11),30%,0)),2)) | O11: =IF(COUNT(I11:J11)=0,"",ROUND((IF(ISNUMBER(I11),I11*70%,0)+IF(ISNUMBER(J11),J11*30%,0))/(IF(ISNUMBER(I11),70%,0)+IF(ISNUMBER(J11),30%,0)),2)) | P11: =K11 | Q11: =L11 | R11: =M11 | S11: =IF($X11="","",INDEX('sheet2-计算明细'!$AQ$17:$AQ$330,$X11)) | T11: =IF($X11="","",INDEX('sheet2-计算明细'!$AR$17:$AR$330,$X11)) | U11: =IF(S11=0,"",ROUND(T11/S11,2)) | V11: =IF(S11=100%,T11,"") | W11: =IF($X11="","",INDEX('sheet2-计算明细'!$AU$17:$AU$330,$X11)) | X11: =IF($A11>COUNT('sheet2-计算明细'!$AT$17:$AT$330),"",MATCH($A11,'sheet2-计算明细'!$AT$17:$AT$330,0))
A12: 7 | B12: =IF($X12="","",INDEX('sheet2-计算明细'!$B$17:$B$330,$X12)) | C12: =IF($X12="","",INDEX('sheet2-计算明细'!$C$17:$C$330,$X12)) | D12: =IF($X12="","",INDEX('sheet2-计算明细'!$D$17:$D$330,$X12)) | E12: =IF($X12="","",INDEX('sheet2-计算明细'!$G$17:$G$330,$X12)) | F12: =IF($X12="","",INDEX('sheet2-计算明细'!$I$17:$I$330,$X12)) | G12: =IF($X12="","",INDEX('sheet2-计算明细'!$K$17:$K$330,$X12)) | H12: =IF($X12="","",INDEX('sheet2-计算明细'!$L$17:$L$330,$X12)) | I12: =IF($X12="","",INDEX('sheet2-计算明细'!$S$17:$S$330,$X12)) | J12: =IF($X12="","",INDEX('sheet2-计算明细'!$Y$17:$Y$330,$X12)) | K12: =IF($X12="","",INDEX('sheet2-计算明细'!$AC$17:$AC$330,$X12)) | L12: =IF($X12="","",INDEX('sheet2-计算明细'!$AI$17:$AI$330,$X12)) | M12: =IF($X12="","",INDEX('sheet2-计算明细'!$AK$17:$AK$330,$X12)) | N12: =IF(COUNT(F12:H12)=0,"",ROUND((IF(ISNUMBER(F12),F12*40%,0)+IF(ISNUMBER(G12),G12*30%,0)+IF(ISNUMBER(H12),H12*30%,0))/(IF(ISNUMBER(F12),40%,0)+IF(ISNUMBER(G12),30%,0)+IF(ISNUMBER(H12),30%,0)),2)) | O12: =IF(COUNT(I12:J12)=0,"",ROUND((IF(ISNUMBER(I12),I12*70%,0)+IF(ISNUMBER(J12),J12*30%,0))/(IF(ISNUMBER(I12),70%,0)+IF(ISNUMBER(J12),30%,0)),2)) | P12: =K12 | Q12: =L12 | R12: =M12 | S12: =IF($X12="","",INDEX('sheet2-计算明细'!$AQ$17:$AQ$330,$X12)) | T12: =IF($X12="","",INDEX('sheet2-计算明细'!$AR$17:$AR$330,$X12)) | U12: =IF(S12=0,"",ROUND(T12/S12,2)) | V12: =IF(S12=100%,T12,"") | W12: =IF($X12="","",INDEX('sheet2-计算明细'!$AU$17:$AU$330,$X12)) | X12: =IF($A12>COUNT('sheet2-计算明细'!$AT$17:$AT$330),"",MATCH($A12,'sheet2-计算明细'!$AT$17:$AT$330,0))
A13: 8 | B13: =IF($X13="","",INDEX('sheet2-计算明细'!$B$17:$B$330,$X13)) | C13: =IF($X13="","",INDEX('sheet2-计算明细'!$C$17:$C$330,$X13)) | D13: =IF($X13="","",INDEX('sheet2-计算明细'!$D$17:$D$330,$X13)) | E13: =IF($X13="","",INDEX('sheet2-计算明细'!$G$17:$G$330,$X13)) | F13: =IF($X13="","",INDEX('sheet2-计算明细'!$I$17:$I$330,$X13)) | G13: =IF($X13="","",INDEX('sheet2-计算明细'!$K$17:$K$330,$X13)) | H13: =IF($X13="","",INDEX('sheet2-计算明细'!$L$17:$L$330,$X13)) | I13: =IF($X13="","",INDEX('sheet2-计算明细'!$S$17:$S$330,$X13)) | J13: =IF($X13="","",INDEX('sheet2-计算明细'!$Y$17:$Y$330,$X13)) | K13: =IF($X13="","",INDEX('sheet2-计算明细'!$AC$17:$AC$330,$X13)) | L13: =IF($X13="","",INDEX('sheet2-计算明细'!$AI$17:$AI$330,$X13)) | M13: =IF($X13="","",INDEX('sheet2-计算明细'!$AK$17:$AK$330,$X13)) | N13: =IF(COUNT(F13:H13)=0,"",ROUND((IF(ISNUMBER(F13),F13*40%,0)+IF(ISNUMBER(G13),G13*30%,0)+IF(ISNUMBER(H13),H13*30%,0))/(IF(ISNUMBER(F13),40%,0)+IF(ISNUMBER(G13),30%,0)+IF(ISNUMBER(H13),30%,0)),2)) | O13: =IF(COUNT(I13:J13)=0,"",ROUND((IF(ISNUMBER(I13),I13*70%,0)+IF(ISNUMBER(J13),J13*30%,0))/(IF(ISNUMBER(I13),70%,0)+IF(ISNUMBER(J13),30%,0)),2)) | P13: =K13 | Q13: =L13 | R13: =M13 | S13: =IF($X13="","",INDEX('sheet2-计算明细'!$AQ$17:$AQ$330,$X13)) | T13: =IF($X13="","",INDEX('sheet2-计算明细'!$AR$17:$AR$330,$X13)) | U13: =IF(S13=0,"",ROUND(T13/S13,2)) | V13: =IF(S13=100%,T13,"") | W13: =IF($X13="","",INDEX('sheet2-计算明细'!$AU$17:$AU$330,$X13)) | X13: =IF($A13>COUNT('sheet2-计算明细'!$AT$17:$AT$330),"",MATCH($A13,'sheet2-计算明细'!$AT$17:$AT$330,0))
A14: 9 | B14: =IF($X14="","",INDEX('sheet2-计算明细'!$B$17:$B$330,$X14)) | C14: =IF($X14="","",INDEX('sheet2-计算明细'!$C$17:$C$330,$X14)) | D14: =IF($X14="","",INDEX('sheet2-计算明细'!$D$17:$D$330,$X14)) | E14: =IF($X14="","",INDEX('sheet2-计算明细'!$G$17:$G$330,$X14)) | F14: =IF($X14="","",INDEX('sheet2-计算明细'!$I$17:$I$330,$X14)) | G14: =IF($X14="","",INDEX('sheet2-计算明细'!$K$17:$K$330,$X14)) | H14: =IF($X14="","",INDEX('sheet2-计算明细'!$L$17:$L$330,$X14)) | I14: =IF($X14="","",INDEX('sheet2-计算明细'!$S$17:$S$330,$X14)) | J14: =IF($X14="","",INDEX('sheet2-计算明细'!$Y$17:$Y$330,$X14)) | K14: =IF($X14="","",INDEX('sheet2-计算明细'!$AC$17:$AC$330,$X14)) | L14: =IF($X14="","",INDEX('sheet2-计算明细'!$AI$17:$AI$330,$X14)) | M14: =IF($X14="","",INDEX('sheet2-计算明细'!$AK$17:$AK$330,$X14)) | N14: =IF(COUNT(F14:H14)=0,"",ROUND((IF(ISNUMBER(F14),F14*40%,0)+IF(ISNUMBER(G14),G14*30%,0)+IF(ISNUMBER(H14),H14*30%,0))/(IF(ISNUMBER(F14),40%,0)+IF(ISNUMBER(G14),30%,0)+IF(ISNUMBER(H14),30%,0)),2)) | O14: =IF(COUNT(I14:J14)=0,"",ROUND((IF(ISNUMBER(I14),I14*70%,0)+IF(ISNUMBER(J14),J14*30%,0))/(IF(ISNUMBER(I14),70%,0)+IF(ISNUMBER(J14),30%,0)),2)) | P14: =K14 | Q14: =L14 | R14: =M14 | S14: =IF($X14="","",INDEX('sheet2-计算明细'!$AQ$17:$AQ$330,$X14)) | T14: =IF($X14="","",INDEX('sheet2-计算明细'!$AR$17:$AR$330,$X14)) | U14: =IF(S14=0,"",ROUND(T14/S14,2)) | V14: =IF(S14=100%,T14,"") | W14: =IF($X14="","",INDEX('sheet2-计算明细'!$AU$17:$AU$330,$X14)) | X14: =IF($A14>COUNT('sheet2-计算明细'!$AT$17:$AT$330),"",MATCH($A14,'sheet2-计算明细'!$AT$17:$AT$330,0))
A15: 10 | B15: =IF($X15="","",INDEX('sheet2-计算明细'!$B$17:$B$330,$X15)) | C15: =IF($X15="","",INDEX('sheet2-计算明细'!$C$17:$C$330,$X15)) | D15: =IF($X15="","",INDEX('sheet2-计算明细'!$D$17:$D$330,$X15)) | E15: =IF($X15="","",INDEX('sheet2-计算明细'!$G$17:$G$330,$X15)) | F15: =IF($X15="","",INDEX('sheet2-计算明细'!$I$17:$I$330,$X15)) | G15: =IF($X15="","",INDEX('sheet2-计算明细'!$K$17:$K$330,$X15)) | H15: =IF($X15="","",INDEX('sheet2-计算明细'!$L$17:$L$330,$X15)) | I15: =IF($X15="","",INDEX('sheet2-计算明细'!$S$17:$S$330,$X15)) | J15: =IF($X15="","",INDEX('sheet2-计算明细'!$Y$17:$Y$330,$X15)) | K15: =IF($X15="","",INDEX('sheet2-计算明细'!$AC$17:$AC$330,$X15)) | L15: =IF($X15="","",INDEX('sheet2-计算明细'!$AI$17:$AI$330,$X15)) | M15: =IF($X15="","",INDEX('sheet2-计算明细'!$AK$17:$AK$330,$X15)) | N15: =IF(COUNT(F15:H15)=0,"",ROUND((IF(ISNUMBER(F15),F15*40%,0)+IF(ISNUMBER(G15),G15*30%,0)+IF(ISNUMBER(H15),H15*30%,0))/(IF(ISNUMBER(F15),40%,0)+IF(ISNUMBER(G15),30%,0)+IF(ISNUMBER(H15),30%,0)),2)) | O15: =IF(COUNT(I15:J15)=0,"",ROUND((IF(ISNUMBER(I15),I15*70%,0)+IF(ISNUMBER(J15),J15*30%,0))/(IF(ISNUMBER(I15),70%,0)+IF(ISNUMBER(J15),30%,0)),2)) | P15: =K15 | Q15: =L15 | R15: =M15 | S15: =IF($X15="","",INDEX('sheet2-计算明细'!$AQ$17:$AQ$330,$X15)) | T15: =IF($X15="","",INDEX('sheet2-计算明细'!$AR$17:$AR$330,$X15)) | U15: =IF(S15=0,"",ROUND(T15/S15,2)) | V15: =IF(S15=100%,T15,"") | W15: =IF($X15="","",INDEX('sheet2-计算明细'!$AU$17:$AU$330,$X15)) | X15: =IF($A15>COUNT('sheet2-计算明细'!$AT$17:$AT$330),"",MATCH($A15,'sheet2-计算明细'!$AT$17:$AT$330,0))
A16: 11 | B16: =IF($X16="","",INDEX('sheet2-计算明细'!$B$17:$B$330,$X16)) | C16: =IF($X16="","",INDEX('sheet2-计算明细'!$C$17:$C$330,$X16)) | D16: =IF($X16="","",INDEX('sheet2-计算明细'!$D$17:$D$330,$X16)) | E16: =IF($X16="","",INDEX('sheet2-计算明细'!$G$17:$G$330,$X16)) | F16: =IF($X16="","",INDEX('sheet2-计算明细'!$I$17:$I$330,$X16)) | G16: =IF($X16="","",INDEX('sheet2-计算明细'!$K$17:$K$330,$X16)) | H16: =IF($X16="","",INDEX('sheet2-计算明细'!$L$17:$L$330,$X16)) | I16: =IF($X16="","",INDEX('sheet2-计算明细'!$S$17:$S$330,$X16)) | J16: =IF($X16="","",INDEX('sheet2-计算明细'!$Y$17:$Y$330,$X16)) | K16: =IF($X16="","",INDEX('sheet2-计算明细'!$AC$17:$AC$330,$X16)) | L16: =IF($X16="","",INDEX('sheet2-计算明细'!$AI$17:$AI$330,$X16)) | M16: =IF($X16="","",INDEX('sheet2-计算明细'!$AK$17:$AK$330,$X16)) | N16: =IF(COUNT(F16:H16)=0,"",ROUND((IF(ISNUMBER(F16),F16*40%,0)+IF(ISNUMBER(G16),G16*30%,0)+IF(ISNUMBER(H16),H16*30%,0))/(IF(ISNUMBER(F16),40%,0)+IF(ISNUMBER(G16),30%,0)+IF(ISNUMBER(H16),30%,0)),2)) | O16: =IF(COUNT(I16:J16)=0,"",ROUND((IF(ISNUMBER(I16),I16*70%,0)+IF(ISNUMBER(J16),J16*30%,0))/(IF(ISNUMBER(I16),70%,0)+IF(ISNUMBER(J16),30%,0)),2)) | P16: =K16 | Q16: =L16 | R16: =M16 | S16: =IF($X16="","",INDEX('sheet2-计算明细'!$AQ$17:$AQ$330,$X16)) | T16: =IF($X16="","",INDEX('sheet2-计算明细'!$AR$17:$AR$330,$X16)) | U16: =IF(S16=0,"",ROUND(T16/S16,2)) | V16: =IF(S16=100%,T16,"") | W16: =IF($X16="","",INDEX('sheet2-计算明细'!$AU$17:$AU$330,$X16)) | X16: =IF($A16>COUNT('sheet2-计算明细'!$AT$17:$AT$330),"",MATCH($A16,'sheet2-计算明细'!$AT$17:$AT$330,0))
A17: 12 | B17: =IF($X17="","",INDEX('sheet2-计算明细'!$B$17:$B$330,$X17)) | C17: =IF($X17="","",INDEX('sheet2-计算明细'!$C$17:$C$330,$X17)) | D17: =IF($X17="","",INDEX('sheet2-计算明细'!$D$17:$D$330,$X17)) | E17: =IF($X17="","",INDEX('sheet2-计算明细'!$G$17:$G$330,$X17)) | F17: =IF($X17="","",INDEX('sheet2-计算明细'!$I$17:$I$330,$X17)) | G17: =IF($X17="","",INDEX('sheet2-计算明细'!$K$17:$K$330,$X17)) | H17: =IF($X17="","",INDEX('sheet2-计算明细'!$L$17:$L$330,$X17)) | I17: =IF($X17="","",INDEX('sheet2-计算明细'!$S$17:$S$330,$X17)) | J17: =IF($X17="","",INDEX('sheet2-计算明细'!$Y$17:$Y$330,$X17)) | K17: =IF($X17="","",INDEX('sheet2-计算明细'!$AC$17:$AC$330,$X17)) | L17: =IF($X17="","",INDEX('sheet2-计算明细'!$AI$17:$AI$330,$X17)) | M17: =IF($X17="","",INDEX('sheet2-计算明细'!$AK$17:$AK$330,$X17)) | N17: =IF(COUNT(F17:H17)=0,"",ROUND((IF(ISNUMBER(F17),F17*40%,0)+IF(ISNUMBER(G17),G17*30%,0)+IF(ISNUMBER(H17),H17*30%,0))/(IF(ISNUMBER(F17),40%,0)+IF(ISNUMBER(G17),30%,0)+IF(ISNUMBER(H17),30%,0)),2)) | O17: =IF(COUNT(I17:J17)=0,"",ROUND((IF(ISNUMBER(I17),I17*70%,0)+IF(ISNUMBER(J17),J17*30%,0))/(IF(ISNUMBER(I17),70%,0)+IF(ISNUMBER(J17),30%,0)),2)) | P17: =K17 | Q17: =L17 | R17: =M17 | S17: =IF($X17="","",INDEX('sheet2-计算明细'!$AQ$17:$AQ$330,$X17)) | T17: =IF($X17="","",INDEX('sheet2-计算明细'!$AR$17:$AR$330,$X17)) | U17: =IF(S17=0,"",ROUND(T17/S17,2)) | V17: =IF(S17=100%,T17,"") | W17: =IF($X17="","",INDEX('sheet2-计算明细'!$AU$17:$AU$330,$X17)) | X17: =IF($A17>COUNT('sheet2-计算明细'!$AT$17:$AT$330),"",MATCH($A17,'sheet2-计算明细'!$AT$17:$AT$330,0))
... A319: 314 | B319: =IF($X319="","",INDEX('sheet2-计算明细'!$B$17:$B$330,$X319)) | C319: =IF($X319="","",INDEX('sheet2-计算明细'!$C$17:$C$330,$X319)) | D319: =IF($X319="","",INDEX('sheet2-计算明细'!$D$17:$D$330,$X319)) | E319: =IF($X319="","",INDEX('sheet2-计算明细'!$G$17:$G$330,$X319)) | F319: =IF($X319="","",INDEX('sheet2-计算明细'!$I$17:$I$330,$X319)) | G319: =IF($X319="","",INDEX('sheet2-计算明细'!$K$17:$K$330,$X319)) | H319: =IF($X319="","",INDEX('sheet2-计算明细'!$L$17:$L$330,$X319)) | I319: =IF($X319="","",INDEX('sheet2-计算明细'!$S$17:$S$330,$X319)) | J319: =IF($X319="","",INDEX('sheet2-计算明细'!$Y$17:$Y$330,$X319)) | K319: =IF($X319="","",INDEX('sheet2-计算明细'!$AC$17:$AC$330,$X319)) | L319: =IF($X319="","",INDEX('sheet2-计算明细'!$AI$17:$AI$330,$X319)) | M319: =IF($X319="","",INDEX('sheet2-计算明细'!$AK$17:$AK$330,$X319)) | N319: =IF(COUNT(F319:H319)=0,"",ROUND((IF(ISNUMBER(F319),F319*40%,0)+IF(ISNUMBER(G319),G319*30%,0)+IF(ISNUMBER(H319),H319*30%,0))/(IF(ISNUMBER(F319),40%,0)+IF(ISNUMBER(G319),30%,0)+IF(ISNUMBER(H319),30%,0)),2)) | O319: =IF(COUNT(I319:J319)=0,"",ROUND((IF(ISNUMBER(I319),I319*70%,0)+IF(ISNUMBER(J319),J319*30%,0))/(IF(ISNUMBER(I319),70%,0)+IF(ISNUMBER(J319),30%,0)),2)) | P319: =K319 | Q319: =L319 | R319: =M319 | S319: =IF($X319="","",INDEX('sheet2-计算明细'!$AQ$17:$AQ$330,$X319)) | T319: =IF($X319="","",INDEX('sheet2-计算明细'!$AR$17:$AR$330,$X319)) | U319: =IF(S319=0,"",ROUND(T319/S319,2)) | V319: =IF(S319=100%,T319,"") | W319: =IF($X319="","",INDEX('sheet2-计算明细'!$AU$17:$AU$330,$X319)) | X319: =IF($A319>COUNT('sheet2-计算明细'!$AT$17:$AT$330),"",MATCH($A319,'sheet2-计算明细'!$AT$17:$AT$330,0))

Sheet sheet4-原始数据
A1: 产品名称 | B1: 备案号 | C1: 一级策略 | D1: 二级策略 | E1: 管理人 | F1: 成立日期 | G1: 近一年年化收益 | H1: 近三年年化收益 | I1: 近三年月胜率 | J1: 近一年月胜率 | K1: 近三年最大回撤 | L1: 近三年卡玛比率 | M1: 近一年卡玛比率 | N1: 基准指数
A2: 新视野智能量化2号 | B2: SR2759 | C2: 套利策略 | D2: 可转债套利 | E2: 杭州探融投资 | F2: 2017-01-09 | G2: -2.0400% | H2: 2.0500% | I2: 54.0500% | J2: 38.4600% | K2: 5.5400% | L2: 0.37 | M2: -0.369 | N2: 沪深300 | O2: 2026-08-31 | P2: 2026-09-15
A3: 探融新视野智能量化1号 | B3: SL8089 | C3: 套利策略 | D3: 可转债套利 | E3: 杭州探融投资 | F3: 2016-09-22 | G3: -0.4800% | H3: 1.2300% | I3: 56.7600% | J3: 38.4600% | K3: 2.5100% | L3: 0.4906 | M3: -0.19 | N3: 沪深300 | O3: 2026-08-31 | P3: 2026-09-15
A4: 辉毅4号 | B4: SM4445 | C4: 套利策略 | D4: 期权套利 | E4: 上海申毅投资 | F4: 2016-09-14 | G4: -0.2500% | H4: 4.8800% | I4: 75.6800% | J4: 46.1500% | K4: 2.4600% | L4: 1.9851 | M4: -0.1026 | N4: 沪深300 | O4: 2026-08-31 | P4: 2026-09-15
A5: 平凡悟鑫 | B5: SJ2870 | C5: 套利策略 | D5: 基金套利 | E5: 北京平凡 | F5: 2016-04-19 | G5: 6.0700% | H5: 6.4900% | I5: 89.1900% | J5: 92.3100% | K5: 0.9700% | L5: 6.6754 | M5: 6.2497 | N5: 沪深300 | O5: 2026-08-31 | P5: 2026-09-15
A6: 致同稳盈对冲 | B6: SS8645 | C6: 套利策略 | D6: 期货套利 | E6: 上海致同投资 | F6: 2017-05-02 | G6: 4.0500% | H6: 4.8900% | I6: 78.3800% | J6: 76.9200% | K6: 1.3400% | L6: 3.6582 | M6: 3.0286 | N6: 沪深300 | O6: 2026-08-31 | P6: 2026-09-15
A7: 哈福尊享一号 | B7: ST3922 | C7: 套利策略 | D7: 混合套利 | E7: 哈福基金 | F7: 2017-05-10 | G7: 2.8900% | H7: 2.2500% | I7: 72.9700% | J7: 69.2300% | K7: 6.5800% | L7: 0.3413 | M7: 1.0175 | N7: 南华商品指数 | O7: 2026-08-31 | P7: 2026-09-15
A8: 远澜翠柏1号 | B8: SS9088 | C8: 套利策略 | D8: 期货套利 | E8: 上海远澜 | F8: 2017-05-12 | G8: 5.4600% | H8: 4.5700% | I8: 51.3500% | J8: 46.1500% | K8: 15.4000% | L8: 0.297 | M8: 0.3548 | N8: 沪深300 | O8: 2026-08-31 | P8: 2026-09-15
A9: 擎丰1号 | B9: SCS637 | C9: 套利策略 | D9: - | E9: 上海擎丰 | F9: 2018-06-06 | G9: 7.8600% | H9: 5.0600% | I9: 83.7800% | J9: 92.3100% | K9: 0.6900% | L9: 7.3302 | M9: 11.3908 | N9: 沪深300 | O9: 2026-08-31 | P9: 2026-09-15
A10: 新时代智能量化3号 | B10: SEM001 | C10: 套利策略 | D10: 可转债套利 | E10: 杭州探融投资 | F10: 2018-10-29 | G10: 1.2000% | H10: 3.1200% | I10: 56.7600% | J10: 46.1500% | K10: 3.3000% | L10: 0.9453 | M10: 0.3637 | N10: 沪深300 | O10: 2026-08-31 | P10: 2026-09-15
A11: 悬铃C号2期 | B11: SGH303 | C11: 套利策略 | D11: 可转债套利 | E11: 上海悬铃 | F11: 2019-04-24 | G11: -8.6500% | H11: 1.8300% | I11: 56.7600% | J11: 30.7700% | K11: 13.0600% | L11: 0.14 | M11: -0.9845 | N11: 沪深300 | O11: 2026-08-31 | P11: 2026-09-15
A12: 爱凡哲九号 | B12: SJA112 | C12: 套利策略 | D12: 期货套利 | E12: 爱凡哲投资 | F12: 2019-09-02 | G12: 11.5800% | H12: 11.7800% | I12: 89.1900% | J12: 84.6200% | K12: 1.2900% | L12: 9.1289 | M12: 32.2942 | N12: 沪深300 | O12: 2026-08-31 | P12: 2026-09-15
A13: 恒如套利三号 | B13: SGQ731 | C13: 套利策略 | D13: 期货套利 | E13: 上海恒如投资 | F13: 2019-09-19 | G13: 2.1300% | H13: 5.7000% | I13: 72.9700% | J13: 61.5400% | K13: 1.5000% | L13: 3.8103 | M13: 2.6842 | N13: 沪深300 | O13: 2026-08-31 | P13: 2026-09-15
... A61: 慕途稳健2号 | B61: SXW938 | C61: 套利策略 | D61: 期权套利 | E61: 慕途基金 | F61: 2022-12-13 | G61: 7.6300% | H61: 7.6000% | I61: 97.3000% | J61: 92.3100% | K61: 0.7700% | L61: 9.8502 | M61: 9.8866 | N61: 沪深300 | O61: 2026-08-31 | P61: 2026-09-15
A62: 方普安享二号 | B62: SXY895 | C62: 套利策略 | D62: 基金套利 | E62: 珠海横琴方普 | F62: 2022-12-16 | G62: 3.8100% | J62: 53.8500% | M62: 1.5339 | N62: 沪深300 | O62: 2026-08-31 | P62: 2026-09-15
A63: 佳泽信享5号 | B63: SZC395 | C63: 套利策略 | D63: 期货套利 | E63: 海南佳泽 | F63: 2023-01-10 | G63: 6.2900% | H63: 4.7800% | I63: 70.2700% | J63: 84.6200% | K63: 2.4800% | L63: 1.9252 | M63: 6.6879 | N63: 沪深300 | O63: 2026-08-31 | P63: 2026-09-15
A64: 衍舟弄潮2号 | B64: SZG044 | C64: 套利策略 | D64: 混合套利 | E64: 海南衍舟 | F64: 2023-02-02 | G64: -5.2400% | H64: 2.4200% | I64: 62.1600% | J64: 30.7700% | K64: 9.4200% | L64: 0.2572 | M64: -0.6306 | N64: 沪深300 | O64: 2026-08-31 | P64: 2026-09-15
